{"e":"depthUpdate","E":1787612486435,"s":"BTCUSDT","U":3297892529,"u":3297892530,"b":[["78701.88000000","0.01260000"]],"a":[["78725.92000000","0.01261000"]]}
{"e":"depthUpdate","E":1787612486535,"s":"BTCUSDT","U":3297892531,"u":3297892531,"b":[["78688.87000000","0.04030000"]],"a":[]}
{"e":"depthUpdate","E":1787612486635,"s":"BTCUSDT","U":3297892532,"u":3297892534,"b":[["78712.76000000","0.00000000"],["78704.88000000","0.03176000"]],"a":[["78757.02000000","0.04030000"]]}
{"e":"depthUpdate","E":1787612486836,"s":"BTCUSDT","U":3297892535,"u":3297892535,"b":[["78689.99000000","0.02686000"],["78672.92000000","0.00000000"]],"a":[]}
{"e":"depthUpdate","E":1787612487536,"s":"BTCUSDT","U":3297892536,"u":3297892537,"b":[["78689.99000000","0.00000000"]],"a":[["85028.44000000","0.00045000"]]}
{"e":"depthUpdate","E":1787612487636,"s":"BTCUSDT","U":3297892538,"u":3297892539,"b":[["78688.87000000","0.00000000"],["78657.04000000","0.04030000"]],"a":[]}
{"e":"depthUpdate","E":1787612487736,"s":"BTCUSDT","U":3297892540,"u":3297892540,"b":[["78675.67000000","0.00007000"]],"a":[]}
{"e":"depthUpdate","E":1787612487936,"s":"BTCUSDT","U":3297892541,"u":3297892541,"b":[["78688.81000000","0.04030000"],["78657.04000000","0.00000000"]],"a":[]}
{"e":"depthUpdate","E":1787612488136,"s":"BTCUSDT","U":3297892542,"u":3297892542,"b":[],"a":[["85028.44000000","0.00060000"]]}
{"e":"depthUpdate","E":1787612489537,"s":"BTCUSDT","U":3297892543,"u":3297892543,"b":[["78694.79000000","0.02686000"]],"a":[]}
{"e":"depthUpdate","E":1787612490438,"s":"BTCUSDT","U":3297892544,"u":3297892550,"b":[["78686.08000000","0.05082000"],["78678.62000000","0.00000000"],["78665.70000000","0.07623000"],["78657.52000000","0.00000000"],["78645.31000000","0.15246000"],["78636.43000000","0.00000000"],["78604.54000000","0.35574000"],["78594.25000000","0.00000000"]],"a":[["78781.28000000","0.00000000"],["78786.63000000","0.07623000"],["78802.37000000","0.00000000"],["78807.02000000","0.15246000"],["78844.55000000","0.00000000"],["78847.79000000","0.35574000"]]}
{"e":"depthUpdate","E":1787612491138,"s":"BTCUSDT","U":3297892551,"u":3297892570,"b":[["78725.91000000","0.00282000"],["78722.30000000","0.00000000"],["78719.88000000","0.00000000"],["78713.74000000","0.02803000"],["78711.61000000","0.00000000"],["78710.19000000","0.00000000"],["78705.46000000","0.00330000"],["78704.88000000","0.00000000"],["78703.46000000","0.00000000"],["78692.11000000","0.03507000"],["78688.13000000","0.00000000"],["78658.95000000","0.13434000"],["78474.98000000","0.00000000"]],"a":[["78728.36000000","0.00000000"],["78728.89000000","0.00000000"],["78729.61000000","0.00276000"],["78731.02000000","0.00000000"],["78732.28000000","0.00330000"],["78733.83000000","0.00000000"],["78737.37000000","0.02734000"],["78769.16000000","0.00000000"]]}
{"e":"depthUpdate","E":1787612491238,"s":"BTCUSDT","U":3297892571,"u":3297892591,"b":[["78719.75000000","0.02791000"],["78713.74000000","0.00000000"],["78705.93000000","0.04030000"],["78701.88000000","0.00000000"],["78674.43000000","0.00000000"],["78325.25000000","0.01090000"],["78317.09000000","0.00000000"]],"a":[["78729.61000000","0.00000000"],["78732.28000000","0.00000000"],["78733.02000000","0.00000000"],["78735.02000000","0.00330000"],["78735.70000000","0.00262000"],["78737.37000000","0.00000000"],["78737.94000000","0.00000000"],["78739.63000000","0.00000000"],["78740.88000000","0.10141000"],["78743.39000000","0.02814000"],["78743.61000000","0.00000000"],["78744.44000000","0.03175000"],["78745.62000000","0.00000000"],["78747.62000000","0.03504000"],["78794.74000000","0.00000000"],["78821.40000000","0.12688000"],["79032.42000000","0.00000000"]]}
{"e":"depthUpdate","E":1787612491339,"s":"BTCUSDT","U":3297892592,"u":3297892598,"b":[["78728.57000000","0.00266000"],["78725.91000000","0.00000000"],["78707.46000000","0.00330000"],["78705.46000000","0.00000000"],["78696.11000000","0.03507000"],["78692.11000000","0.00000000"]],"a":[["78725.92000000","0.00000000"],["78735.02000000","0.00000000"],["78736.28000000","0.00330000"],["78740.88000000","0.00000000"]]}
{"e":"depthUpdate","E":1787612491439,"s":"BTCUSDT","U":3297892599,"u":3297892600,"b":[["78706.60000000","0.01264000"]],"a":[["78731.72000000","0.01268000"]]}
{"e":"depthUpdate","E":1787612491539,"s":"BTCUSDT","U":3297892601,"u":3297892604,"b":[["78697.64000000","0.09999000"],["78488.32000000","0.00000000"]],"a":[["78744.88000000","0.10080000"],["78940.53000000","0.13434000"]]}
{"e":"depthUpdate","E":1787612491639,"s":"BTCUSDT","U":3297892605,"u":3297892605,"b":[],"a":[["79032.86000000","0.27697000"]]}
{"e":"depthUpdate","E":1787612491739,"s":"BTCUSDT","U":3297892606,"u":3297892607,"b":[["78723.17000000","0.03176000"]],"a":[["85028.44000000","0.00045000"]]}
{"e":"depthUpdate","E":1787612492139,"s":"BTCUSDT","U":3297892608,"u":3297892608,"b":[],"a":[["85028.44000000","0.00030000"]]}
{"e":"depthUpdate","E":1787612493240,"s":"BTCUSDT","U":3297892609,"u":3297892610,"b":[["78723.17000000","0.00000000"],["78716.86000000","0.03176000"]],"a":[]}
{"e":"depthUpdate","E":1787612493640,"s":"BTCUSDT","U":3297892611,"u":3297892611,"b":[],"a":[["78728.58000000","0.87652000"]]}
{"e":"depthUpdate","E":1787612494341,"s":"BTCUSDT","U":3297892612,"u":3297892612,"b":[],"a":[["85028.44000000","0.00045000"]]}
{"e":"depthUpdate","E":1787612495341,"s":"BTCUSDT","U":3297892613,"u":3297892628,"b":[["78728.57000000","0.00000000"],["78724.03000000","0.00277000"],["78719.75000000","0.00000000"],["78717.11000000","0.02696000"],["78716.86000000","0.00000000"],["78708.72000000","0.00330000"],["78707.48000000","0.04030000"],["78707.46000000","0.00000000"],["78705.93000000","0.00000000"],["78704.71000000","0.03176000"]],"a":[["78731.67000000","0.00000000"],["78732.89000000","0.00260000"],["78733.32000000","0.03175000"],["78735.70000000","0.00000000"],["78740.75000000","0.02658000"],["78743.39000000","0.00000000"],["78744.44000000","0.00000000"]]}
{"e":"depthUpdate","E":1787612495441,"s":"BTCUSDT","U":3297892629,"u":3297892629,"b":[["78704.71000000","0.00000000"]],"a":[]}
{"e":"depthUpdate","E":1787612495541,"s":"BTCUSDT","U":3297892630,"u":3297892634,"b":[["78717.11000000","0.00000000"],["78710.69000000","0.02598000"],["78705.14000000","0.03176000"]],"a":[["78734.34000000","0.02730000"],["78740.75000000","0.00000000"]]}
