{"data":{"id":2043024879235074,"id_str":"2043024879235074","order_type":1,"order_subtype":5,"datetime":"1787620346","microtimestamp":"1787620345565000","amount":0.06549561,"amount_str":"0.06549561","amount_traded":"0","amount_at_create":"0.06549561","price":79646.04,"price_str":"79646.04","is_liquidation":false},"channel":"live_orders_btcusd","event":"order_created","event_id":"000659d4-cbb0-cf48-0000-000101000020","pre_event_id":"000659d4-cbb0-c390-0000-000100000020","order_source":"orderbook"}
{"data":{"id":2043024879239168,"id_str":"2043024879239168","order_type":1,"order_subtype":5,"datetime":"1787620346","microtimestamp":"1787620345565000","amount":0.02456085,"amount_str":"0.02456085","amount_traded":"0","amount_at_create":"0.02456085","price":79642.06,"price_str":"79642.06","is_liquidation":false},"channel":"live_orders_btcusd","event":"order_created","event_id":"000659d4-cbb0-cf48-0001-000102000020","pre_event_id":"000659d4-cbb0-cf48-0000-000101000020","order_source":"orderbook"}
{"data":{"id":2043024879247363,"id_str":"2043024879247363","order_type":1,"order_subtype":5,"datetime":"1787620346","microtimestamp":"1787620345568000","amount":0.08186951,"amount_str":"0.08186951","amount_traded":"0","amount_at_create":"0.08186951","price":79644.05,"price_str":"79644.05","is_liquidation":false},"channel":"live_orders_btcusd","event":"order_created","event_id":"000659d4-cbb0-db00-0000-000103000020","pre_event_id":"000659d4-cbb0-cf48-0001-000102000020","order_source":"orderbook"}
{"data":{"id":2043024878317572,"id_str":"2043024878317572","order_type":0,"order_subtype":5,"datetime":"1787620346","microtimestamp":"1787620345578000","amount":0.62794599,"amount_str":"0.62794599","amount_traded":"0","amount_at_create":"0.62794599","price":79602.72,"price_str":"79602.72","is_liquidation":false},"channel":"live_orders_btcusd","event":"order_deleted","event_id":"000659d4-cbb1-0210-0000-000100000020","pre_event_id":"000659d4-cbb0-db00-0000-000103000020","order_source":"orderbook"}
{"data":{"id":2043024879321088,"id_str":"2043024879321088","order_type":0,"order_subtype":0,"datetime":"1787620346","microtimestamp":"1787620345586000","amount":0.00049029,"amount_str":"0.00049029","amount_traded":"0","amount_at_create":"0.00049029","price":78775.17,"price_str":"78775.17","is_liquidation":false},"channel":"live_orders_btcusd","event":"order_created","event_id":"000659d4-cbb1-2150-0000-000101000020","pre_event_id":"000659d4-cbb1-0210-0000-000100000020","order_source":"orderbook"}
{"data":{"id":2043024879321089,"id_str":"2043024879321089","order_type":1,"order_subtype":5,"datetime":"1787620346","microtimestamp":"1787620345586000","amount":0.5,"amount_str":"0.50000000","amount_traded":"0","amount_at_create":"0.50000000","price":79627.8,"price_str":"79627.80","is_liquidation":false},"channel":"live_orders_btcusd","event":"order_created","event_id":"000659d4-cbb1-2150-0001-000102000020","pre_event_id":"000659d4-cbb1-2150-0000-000101000020","order_source":"orderbook"}
{"data":{"id":2043024879329282,"id_str":"2043024879329282","order_type":0,"order_subtype":5,"datetime":"1787620346","microtimestamp":"1787620345588000","amount":0.62797427,"amount_str":"0.62797427","amount_traded":"0","amount_at_create":"0.62797427","price":79604.76,"price_str":"79604.76","is_liquidation":false},"channel":"live_orders_btcusd","event":"order_created","event_id":"000659d4-cbb1-2920-0000-000103000020","pre_event_id":"000659d4-cbb1-2150-0001-000102000020","order_source":"orderbook"}
{"data":{"id":2043024878321681,"id_str":"2043024878321681","order_type":0,"order_subtype":5,"datetime":"1787620346","microtimestamp":"1787620345591000","amount":0.50235679,"amount_str":"0.50235679","amount_traded":"0","amount_at_create":"0.50235679","price":79600.73,"price_str":"79600.73","is_liquidation":false},"channel":"live_orders_btcusd","event":"order_deleted","event_id":"000659d4-cbb1-34d8-0000-000100000020","pre_event_id":"000659d4-cbb1-2920-0000-000103000020","order_source":"orderbook"}
{"data":{"id":2043024879239168,"id_str":"2043024879239168","order_type":1,"order_subtype":5,"datetime":"1787620346","microtimestamp":"1787620345592000","amount":0.02456085,"amount_str":"0.02456085","amount_traded":"0","amount_at_create":"0.02456085","price":79642.06,"price_str":"79642.06","is_liquidation":false},"channel":"live_orders_btcusd","event":"order_deleted","event_id":"000659d4-cbb1-38c0-0000-000101000020","pre_event_id":"000659d4-cbb1-34d8-0000-000100000020","order_source":"orderbook"}
{"data":{"id":2043024878514186,"id_str":"2043024878514186","order_type":0,"order_subtype":5,"datetime":"1787620346","microtimestamp":"1787620345592000","amount":0.81593385,"amount_str":"0.81593385","amount_traded":"0","amount_at_create":"0.81593385","price":79581.58,"price_str":"79581.58","is_liquidation":false},"channel":"live_orders_btcusd","event":"order_deleted","event_id":"000659d4-cbb1-38c0-0001-000102000020","pre_event_id":"000659d4-cbb1-38c0-0000-000101000020","order_source":"orderbook"}
{"data":{"id":2043024879247363,"id_str":"2043024879247363","order_type":1,"order_subtype":5,"datetime":"1787620346","microtimestamp":"1787620345596000","amount":0.08186951,"amount_str":"0.08186951","amount_traded":"0","amount_at_create":"0.08186951","price":79644.05,"price_str":"79644.05","is_liquidation":false},"channel":"live_orders_btcusd","event":"order_deleted","event_id":"000659d4-cbb1-4860-0000-000103000020","pre_event_id":"000659d4-cbb1-38c0-0001-000102000020","order_source":"orderbook"}
{"data":{"id":2043024879235074,"id_str":"2043024879235074","order_type":1,"order_subtype":5,"datetime":"1787620346","microtimestamp":"1787620345600000","amount":0.06549561,"amount_str":"0.06549561","amount_traded":"0","amount_at_create":"0.06549561","price":79646.04,"price_str":"79646.04","is_liquidation":false},"channel":"live_orders_btcusd","event":"order_deleted","event_id":"000659d4-cbb1-5800-0000-000100000020","pre_event_id":"000659d4-cbb1-4860-0000-000103000020","order_source":"orderbook"}
{"data":{"id":2043024879390720,"id_str":"2043024879390720","order_type":0,"order_subtype":5,"datetime":"1787620346","microtimestamp":"1787620345602000","amount":0.50236423,"amount_str":"0.50236423","amount_traded":"0","amount_at_create":"0.50236423","price":79603.34,"price_str":"79603.34","is_liquidation":false},"channel":"live_orders_btcusd","event":"order_created","event_id":"000659d4-cbb1-5fd0-0000-000101000020","pre_event_id":"000659d4-cbb1-5800-0000-000100000020","order_source":"orderbook"}
{"data":{"id":2043024879390722,"id_str":"2043024879390722","order_type":1,"order_subtype":5,"datetime":"1787620346","microtimestamp":"1787620345603000","amount":0.02456085,"amount_str":"0.02456085","amount_traded":"0","amount_at_create":"0.02456085","price":79642.87,"price_str":"79642.87","is_liquidation":false},"channel":"live_orders_btcusd","event":"order_created","event_id":"000659d4-cbb1-63b8-0000-000102000020","pre_event_id":"000659d4-cbb1-5fd0-0000-000101000020","order_source":"orderbook"}
{"data":{"id":2043024879403008,"id_str":"2043024879403008","order_type":1,"order_subtype":5,"datetime":"1787620346","microtimestamp":"1787620345605000","amount":0.08186951,"amount_str":"0.08186951","amount_traded":"0","amount_at_create":"0.08186951","price":79644.98,"price_str":"79644.98","is_liquidation":false},"channel":"live_orders_btcusd","event":"order_created","event_id":"000659d4-cbb1-6b88-0000-000103000020","pre_event_id":"000659d4-cbb1-63b8-0000-000102000020","order_source":"orderbook"}
{"data":{"id":2043024879419394,"id_str":"2043024879419394","order_type":0,"order_subtype":5,"datetime":"1787620346","microtimestamp":"1787620345609000","amount":0.25124871,"amount_str":"0.25124871","amount_traded":"0","amount_at_create":"0.25124871","price":79602.39,"price_str":"79602.39","is_liquidation":false},"channel":"live_orders_btcusd","event":"order_created","event_id":"000659d4-cbb1-7b28-0000-000100000020","pre_event_id":"000659d4-cbb1-6b88-0000-000103000020","order_source":"orderbook"}
{"data":{"id":2043024879419410,"id_str":"2043024879419410","order_type":0,"order_subtype":5,"datetime":"1787620346","microtimestamp":"1787620345610000","amount":0.25126995,"amount_str":"0.25126995","amount_traded":"0","amount_at_create":"0.25126995","price":79595.66,"price_str":"79595.66","is_liquidation":false},"channel":"live_orders_btcusd","event":"order_created","event_id":"000659d4-cbb1-7f10-0000-000101000020","pre_event_id":"000659d4-cbb1-7b28-0000-000100000020","order_source":"orderbook"}
{"data":{"id":2043024879419411,"id_str":"2043024879419411","order_type":0,"order_subtype":5,"datetime":"1787620346","microtimestamp":"1787620345610000","amount":1.25760936,"amount_str":"1.25760936","amount_traded":"0","amount_at_create":"1.25760936","price":79515.94,"price_str":"79515.94","is_liquidation":false},"channel":"live_orders_btcusd","event":"order_created","event_id":"000659d4-cbb1-7f10-0001-000102000020","pre_event_id":"000659d4-cbb1-7f10-0000-000101000020","order_source":"orderbook"}
{"data":{"id":2043024879423502,"id_str":"2043024879423502","order_type":1,"order_subtype":5,"datetime":"1787620346","microtimestamp":"1787620345611000","amount":0.06549561,"amount_str":"0.06549561","amount_traded":"0","amount_at_create":"0.06549561","price":79647.04,"price_str":"79647.04","is_liquidation":false},"channel":"live_orders_btcusd","event":"order_created","event_id":"000659d4-cbb1-82f8-0000-000103000020","pre_event_id":"000659d4-cbb1-7f10-0001-000102000020","order_source":"orderbook"}
{"data":{"id":2043024879439876,"id_str":"2043024879439876","order_type":0,"order_subtype":5,"datetime":"1787620346","microtimestamp":"1787620345614000","amount":0.06280381,"amount_str":"0.06280381","amount_traded":"0","amount_at_create":"0.06280381","price":79612.99,"price_str":"79612.99","is_liquidation":false},"channel":"live_orders_btcusd","event":"order_created","event_id":"000659d4-cbb1-8eb0-0000-000100000020","pre_event_id":"000659d4-cbb1-82f8-0000-000103000020","order_source":"orderbook"}
{"data":{"id":2043024879460376,"id_str":"2043024879460376","order_type":0,"order_subtype":5,"datetime":"1787620346","microtimestamp":"1787620345620000","amount":0.48956031,"amount_str":"0.48956031","amount_traded":"0","amount_at_create":"0.48956031","price":79588.42,"price_str":"79588.42","is_liquidation":false},"channel":"live_orders_btcusd","event":"order_created","event_id":"000659d4-cbb1-a620-0000-000101000020","pre_event_id":"000659d4-cbb1-8eb0-0000-000100000020","order_source":"orderbook"}
{"data":{"id":2043024879472646,"id_str":"2043024879472646","order_type":0,"order_subtype":5,"datetime":"1787620346","microtimestamp":"1787620345623000","amount":0.81593385,"amount_str":"0.81593385","amount_traded":"0","amount_at_create":"0.81593385","price":79581.53,"price_str":"79581.53","is_liquidation":false},"channel":"live_orders_btcusd","event":"order_created","event_id":"000659d4-cbb1-b1d8-0000-000102000020","pre_event_id":"000659d4-cbb1-a620-0000-000101000020","order_source":"orderbook"}
{"data":{"id":2043024879489030,"id_str":"2043024879489030","order_type":1,"order_subtype":4,"datetime":"1787620346","microtimestamp":"1787620345627000","amount":6.158e-05,"amount_str":"0.00006158","amount_traded":"0","amount_at_create":"0.00006158","price":82015.73,"price_str":"82015.73","is_liquidation":false},"channel":"live_orders_btcusd","event":"order_created","event_id":"000659d4-cbb1-c178-0000-000103000020","pre_event_id":"000659d4-cbb1-b1d8-0000-000102000020","order_source":"orderbook"}
{"data":{"id":2043024879489030,"id_str":"2043024879489030","order_type":1,"order_subtype":4,"datetime":"1787620346","microtimestamp":"1787620345627000","amount":6.158e-05,"amount_str":"0.00006158","amount_traded":"0","amount_at_create":"0.00006158","price":82015.73,"price_str":"82015.73","is_liquidation":false},"channel":"live_orders_btcusd","event":"order_deleted","event_id":"000659d4-cbb1-c178-0001-000100000020","pre_event_id":"000659d4-cbb1-c178-0000-000103000020","order_source":"orderbook"}
{"data":{"id":2043024879546374,"id_str":"2043024879546374","order_type":0,"order_subtype":5,"datetime":"1787620346","microtimestamp":"1787620345641000","amount":0.00143636,"amount_str":"0.00143636","amount_traded":"0","amount_at_create":"0.00143636","price":71664.23,"price_str":"71664.23","is_liquidation":false},"channel":"live_orders_btcusd","event":"order_created","event_id":"000659d4-cbb1-f828-0000-000101000020","pre_event_id":"000659d4-cbb1-c178-0001-000100000020","order_source":"orderbook"}
{"data":{"id":2043024878231560,"id_str":"2043024878231560","order_type":1,"order_subtype":5,"datetime":"1787620346","microtimestamp":"1787620345641000","amount":0.0860472,"amount_str":"0.08604720","amount_traded":"0","amount_at_create":"0.08604720","price":79626.93,"price_str":"79626.93","is_liquidation":false},"channel":"live_orders_btcusd","event":"order_deleted","event_id":"000659d4-cbb1-f828-0001-000102000020","pre_event_id":"000659d4-cbb1-f828-0000-000101000020","order_source":"orderbook"}
{"data":{"id":2043024879550466,"id_str":"2043024879550466","order_type":1,"order_subtype":5,"datetime":"1787620346","microtimestamp":"1787620345641000","amount":0.0860472,"amount_str":"0.08604720","amount_traded":"0","amount_at_create":"0.08604720","price":79626.93,"price_str":"79626.93","is_liquidation":false},"channel":"live_orders_btcusd","event":"order_created","event_id":"000659d4-cbb1-f828-0002-000103000020","pre_event_id":"000659d4-cbb1-f828-0001-000102000020","order_source":"orderbook"}
{"data":{"id":2043024878256128,"id_str":"2043024878256128","order_type":0,"order_subtype":5,"datetime":"1787620346","microtimestamp":"1787620345649000","amount":0.26349748,"amount_str":"0.26349748","amount_traded":"0","amount_at_create":"0.26349748","price":79607.82,"price_str":"79607.82","is_liquidation":false},"channel":"live_orders_btcusd","event":"order_deleted","event_id":"000659d4-cbb2-1768-0000-000100000020","pre_event_id":"000659d4-cbb1-f828-0002-000103000020","order_source":"orderbook"}
{"data":{"id":2043024879583238,"id_str":"2043024879583238","order_type":0,"order_subtype":5,"datetime":"1787620346","microtimestamp":"1787620345649000","amount":0.26349748,"amount_str":"0.26349748","amount_traded":"0","amount_at_create":"0.26349748","price":79607.82,"price_str":"79607.82","is_liquidation":false},"channel":"live_orders_btcusd","event":"order_created","event_id":"000659d4-cbb2-1768-0001-000101000020","pre_event_id":"000659d4-cbb2-1768-0000-000100000020","order_source":"orderbook"}
{"data":{"id":2043024879583252,"id_str":"2043024879583252","order_type":0,"order_subtype":5,"datetime":"1787620346","microtimestamp":"1787620345650000","amount":0.26349748,"amount_str":"0.26349748","amount_traded":"0","amount_at_create":"0.26349748","price":79579.17,"price_str":"79579.17","is_liquidation":false},"channel":"live_orders_btcusd","event":"order_created","event_id":"000659d4-cbb2-1b50-0000-000102000020","pre_event_id":"000659d4-cbb2-1768-0001-000101000020","order_source":"orderbook"}
{"data":{"id":2043024878891017,"id_str":"2043024878891017","order_type":0,"order_subtype":5,"datetime":"1787620346","microtimestamp":"1787620345654000","amount":0.00143636,"amount_str":"0.00143636","amount_traded":"0","amount_at_create":"0.00143636","price":71664.23,"price_str":"71664.23","is_liquidation":false},"channel":"live_orders_btcusd","event":"order_deleted","event_id":"000659d4-cbb2-2af0-0000-000103000020","pre_event_id":"000659d4-cbb2-1b50-0000-000102000020","order_source":"orderbook"}
{"data":{"id":2043024879632385,"id_str":"2043024879632385","order_type":0,"order_subtype":5,"datetime":"1787620346","microtimestamp":"1787620345661000","amount":0.19,"amount_str":"0.19000000","amount_traded":"0","amount_at_create":"0.19000000","price":79626.92,"price_str":"79626.92","is_liquidation":false},"channel":"live_orders_btcusd","event":"order_created","event_id":"000659d4-cbb2-4648-0000-000100000020","pre_event_id":"000659d4-cbb2-2af0-0000-000103000020","order_source":"orderbook"}
{"data":{"id":2043024879390722,"id_str":"2043024879390722","order_type":1,"order_subtype":5,"datetime":"1787620346","microtimestamp":"1787620345662000","amount":0.02456085,"amount_str":"0.02456085","amount_traded":"0","amount_at_create":"0.02456085","price":79642.87,"price_str":"79642.87","is_liquidation":false},"channel":"live_orders_btcusd","event":"order_deleted","event_id":"000659d4-cbb2-4a30-0000-000101000020","pre_event_id":"000659d4-cbb2-4648-0000-000100000020","order_source":"orderbook"}
{"data":{"id":2043024879403008,"id_str":"2043024879403008","order_type":1,"order_subtype":5,"datetime":"1787620346","microtimestamp":"1787620345663000","amount":0.08186951,"amount_str":"0.08186951","amount_traded":"0","amount_at_create":"0.08186951","price":79644.98,"price_str":"79644.98","is_liquidation":false},"channel":"live_orders_btcusd","event":"order_deleted","event_id":"000659d4-cbb2-4e18-0000-000102000020","pre_event_id":"000659d4-cbb2-4a30-0000-000101000020","order_source":"orderbook"}
{"data":{"id":2043024879079440,"id_str":"2043024879079440","order_type":0,"order_subtype":5,"datetime":"1787620346","microtimestamp":"1787620345663000","amount":0.18839112,"amount_str":"0.18839112","amount_traded":"0","amount_at_create":"0.18839112","price":79606.12,"price_str":"79606.12","is_liquidation":false},"channel":"live_orders_btcusd","event":"order_deleted","event_id":"000659d4-cbb2-4e18-0001-000103000020","pre_event_id":"000659d4-cbb2-4e18-0000-000102000020","order_source":"orderbook"}
{"data":{"id":2043024879423502,"id_str":"2043024879423502","order_type":1,"order_subtype":5,"datetime":"1787620346","microtimestamp":"1787620345664000","amount":0.06549561,"amount_str":"0.06549561","amount_traded":"0","amount_at_create":"0.06549561","price":79647.04,"price_str":"79647.04","is_liquidation":false},"channel":"live_orders_btcusd","event":"order_deleted","event_id":"000659d4-cbb2-5200-0000-000100000020","pre_event_id":"000659d4-cbb2-4e18-0001-000103000020","order_source":"orderbook"}
{"data":{"id":2043024879321089,"id_str":"2043024879321089","order_type":1,"order_subtype":5,"datetime":"1787620346","microtimestamp":"1787620345666000","amount":0.5,"amount_str":"0.50000000","amount_traded":"0","amount_at_create":"0.50000000","price":79627.8,"price_str":"79627.80","is_liquidation":false},"channel":"live_orders_btcusd","event":"order_deleted","event_id":"000659d4-cbb2-59d0-0000-000101000020","pre_event_id":"000659d4-cbb2-5200-0000-000100000020","order_source":"orderbook"}
{"data":{"id":2043024879321088,"id_str":"2043024879321088","order_type":0,"order_subtype":0,"datetime":"1787620346","microtimestamp":"1787620345669000","amount":0.00049029,"amount_str":"0.00049029","amount_traded":"0","amount_at_create":"0.00049029","price":78775.17,"price_str":"78775.17","is_liquidation":false},"channel":"live_orders_btcusd","event":"order_deleted","event_id":"000659d4-cbb2-6588-0000-000102000020","pre_event_id":"000659d4-cbb2-59d0-0000-000101000020","order_source":"orderbook"}
{"data":{"id":2043024879677442,"id_str":"2043024879677442","order_type":0,"order_subtype":5,"datetime":"1787620346","microtimestamp":"1787620345673000","amount":0.00251249,"amount_str":"0.00251249","amount_traded":"0","amount_at_create":"0.00251249","price":79602.26,"price_str":"79602.26","is_liquidation":false},"channel":"live_orders_btcusd","event":"order_created","event_id":"000659d4-cbb2-7528-0000-000103000020","pre_event_id":"000659d4-cbb2-6588-0000-000102000020","order_source":"orderbook"}
{"data":{"id":2043024879685637,"id_str":"2043024879685637","order_type":1,"order_subtype":5,"datetime":"1787620346","microtimestamp":"1787620345674000","amount":0.02456085,"amount_str":"0.02456085","amount_traded":"0","amount_at_create":"0.02456085","price":79644.14,"price_str":"79644.14","is_liquidation":false},"channel":"live_orders_btcusd","event":"order_created","event_id":"000659d4-cbb2-7910-0000-000100000020","pre_event_id":"000659d4-cbb2-7528-0000-000103000020","order_source":"orderbook"}
{"data":{"id":2043024879689728,"id_str":"2043024879689728","order_type":0,"order_subtype":5,"datetime":"1787620346","microtimestamp":"1787620345675000","amount":0.18838707,"amount_str":"0.18838707","amount_traded":"0","amount_at_create":"0.18838707","price":79608.58,"price_str":"79608.58","is_liquidation":false},"channel":"live_orders_btcusd","event":"order_created","event_id":"000659d4-cbb2-7cf8-0000-000101000020","pre_event_id":"000659d4-cbb2-7910-0000-000100000020","order_source":"orderbook"}
{"data":{"id":2043024879689730,"id_str":"2043024879689730","order_type":1,"order_subtype":5,"datetime":"1787620346","microtimestamp":"1787620345675000","amount":0.06549561,"amount_str":"0.06549561","amount_traded":"0","amount_at_create":"0.06549561","price":79648.12,"price_str":"79648.12","is_liquidation":false},"channel":"live_orders_btcusd","event":"order_created","event_id":"000659d4-cbb2-7cf8-0001-000102000020","pre_event_id":"000659d4-cbb2-7cf8-0000-000101000020","order_source":"orderbook"}
{"data":{"id":2043024879689733,"id_str":"2043024879689733","order_type":1,"order_subtype":5,"datetime":"1787620346","microtimestamp":"1787620345675000","amount":0.08186951,"amount_str":"0.08186951","amount_traded":"0","amount_at_create":"0.08186951","price":79646.13,"price_str":"79646.13","is_liquidation":false},"channel":"live_orders_btcusd","event":"order_created","event_id":"000659d4-cbb2-7cf8-0002-000103000020","pre_event_id":"000659d4-cbb2-7cf8-0001-000102000020","order_source":"orderbook"}
{"data":{"id":2043024846766081,"id_str":"2043024846766081","order_type":0,"order_subtype":5,"datetime":"1787620346","microtimestamp":"1787620345699000","amount":7.281869,"amount_str":"7.28186900","amount_traded":"0","amount_at_create":"7.28186900","price":79510.66,"price_str":"79510.66","is_liquidation":false},"channel":"live_orders_btcusd","event":"order_deleted","event_id":"000659d4-cbb2-dab8-0000-000100000020","pre_event_id":"000659d4-cbb2-7cf8-0002-000103000020","order_source":"orderbook"}
{"data":{"id":2043024879816704,"id_str":"2043024879816704","order_type":1,"order_subtype":5,"datetime":"1787620346","microtimestamp":"1787620345706000","amount":0.5,"amount_str":"0.50000000","amount_traded":"0","amount_at_create":"0.50000000","price":79627.81,"price_str":"79627.81","is_liquidation":false},"channel":"live_orders_btcusd","event":"order_created","event_id":"000659d4-cbb2-f610-0000-000101000020","pre_event_id":"000659d4-cbb2-dab8-0000-000100000020","order_source":"orderbook"}
{"data":{"id":2043024879853572,"id_str":"2043024879853572","order_type":0,"order_subtype":5,"datetime":"1787620346","microtimestamp":"1787620345715000","amount":6.285699,"amount_str":"6.28569900","amount_traded":"0","amount_at_create":"6.28569900","price":79470.42,"price_str":"79470.42","is_liquidation":false},"channel":"live_orders_btcusd","event":"order_created","event_id":"000659d4-cbb3-1938-0000-000102000020","pre_event_id":"000659d4-cbb2-f610-0000-000101000020","order_source":"orderbook"}
{"data":{"id":2043024879886336,"id_str":"2043024879886336","order_type":0,"order_subtype":5,"datetime":"1787620346","microtimestamp":"1787620345723000","amount":0.00143636,"amount_str":"0.00143636","amount_traded":"0","amount_at_create":"0.00143636","price":71664.23,"price_str":"71664.23","is_liquidation":false},"channel":"live_orders_btcusd","event":"order_created","event_id":"000659d4-cbb3-3878-0000-000103000020","pre_event_id":"000659d4-cbb3-1938-0000-000102000020","order_source":"orderbook"}
{"data":{"id":2043024879222788,"id_str":"2043024879222788","order_type":0,"order_subtype":5,"datetime":"1787620346","microtimestamp":"1787620345734000","amount":0.00143636,"amount_str":"0.00143636","amount_traded":"0","amount_at_create":"0.00143636","price":71664.23,"price_str":"71664.23","is_liquidation":false},"channel":"live_orders_btcusd","event":"order_deleted","event_id":"000659d4-cbb3-6370-0000-000100000020","pre_event_id":"000659d4-cbb3-3878-0000-000103000020","order_source":"orderbook"}
{"data":{"id":2043024879964168,"id_str":"2043024879964168","order_type":1,"order_subtype":5,"datetime":"1787620346","microtimestamp":"1787620345743000","amount":0.13,"amount_str":"0.13000000","amount_traded":"0","amount_at_create":"0.13000000","price":79655.57,"price_str":"79655.57","is_liquidation":false},"channel":"live_orders_btcusd","event":"order_created","event_id":"000659d4-cbb3-8698-0000-000101000020","pre_event_id":"000659d4-cbb3-6370-0000-000100000020","order_source":"orderbook"}
{"data":{"id":2043024861155339,"id_str":"2043024861155339","order_type":1,"order_subtype":5,"datetime":"1787620346","microtimestamp":"1787620345744000","amount":0.13,"amount_str":"0.13000000","amount_traded":"0","amount_at_create":"0.13000000","price":79681.17,"price_str":"79681.17","is_liquidation":false},"channel":"live_orders_btcusd","event":"order_deleted","event_id":"000659d4-cbb3-8a80-0000-000102000020","pre_event_id":"000659d4-cbb3-8698-0000-000101000020","order_source":"orderbook"}
{"data":{"id":2043024880013312,"id_str":"2043024880013312","order_type":0,"order_subtype":5,"datetime":"1787620346","microtimestamp":"1787620345754000","amount":0.12506966,"amount_str":"0.12506966","amount_traded":"0","amount_at_create":"0.12506966","price":79575.63,"price_str":"79575.63","is_liquidation":false},"channel":"live_orders_btcusd","event":"order_created","event_id":"000659d4-cbb3-b190-0000-000103000020","pre_event_id":"000659d4-cbb3-8a80-0000-000102000020","order_source":"orderbook"}
{"data":{"id":2043024879419410,"id_str":"2043024879419410","order_type":0,"order_subtype":5,"datetime":"1787620346","microtimestamp":"1787620345776000","amount":0.25126995,"amount_str":"0.25126995","amount_traded":"0","amount_at_create":"0.25126995","price":79595.66,"price_str":"79595.66","is_liquidation":false},"channel":"live_orders_btcusd","event":"order_deleted","event_id":"000659d4-cbb4-0780-0000-000100000020","pre_event_id":"000659d4-cbb3-b190-0000-000103000020","order_source":"orderbook"}
{"data":{"id":2043024879816704,"id_str":"2043024879816704","order_type":1,"order_subtype":5,"datetime":"1787620346","microtimestamp":"1787620345779000","amount":0.5,"amount_str":"0.50000000","amount_traded":"0","amount_at_create":"0.50000000","price":79627.81,"price_str":"79627.81","is_liquidation":false},"channel":"live_orders_btcusd","event":"order_deleted","event_id":"000659d4-cbb4-1338-0000-000101000020","pre_event_id":"000659d4-cbb4-0780-0000-000100000020","order_source":"orderbook"}
{"data":{"id":2043024880197636,"id_str":"2043024880197636","order_type":0,"order_subtype":5,"datetime":"1787620346","microtimestamp":"1787620345799000","amount":0.00143636,"amount_str":"0.00143636","amount_traded":"0","amount_at_create":"0.00143636","price":71664.23,"price_str":"71664.23","is_liquidation":false},"channel":"live_orders_btcusd","event":"order_created","event_id":"000659d4-cbb4-6158-0000-000102000020","pre_event_id":"000659d4-cbb4-1338-0000-000101000020","order_source":"orderbook"}
{"data":{"id":2043024880205828,"id_str":"2043024880205828","order_type":0,"order_subtype":5,"datetime":"1787620346","microtimestamp":"1787620345802000","amount":0.13,"amount_str":"0.13000000","amount_traded":"0","amount_at_create":"0.13000000","price":79616.38,"price_str":"79616.38","is_liquidation":false},"channel":"live_orders_btcusd","event":"order_created","event_id":"000659d4-cbb4-6d10-0000-000103000020","pre_event_id":"000659d4-cbb4-6158-0000-000102000020","order_source":"orderbook"}
{"data":{"id":2043024879546374,"id_str":"2043024879546374","order_type":0,"order_subtype":5,"datetime":"1787620346","microtimestamp":"1787620345814000","amount":0.00143636,"amount_str":"0.00143636","amount_traded":"0","amount_at_create":"0.00143636","price":71664.23,"price_str":"71664.23","is_liquidation":false},"channel":"live_orders_btcusd","event":"order_deleted","event_id":"000659d4-cbb4-9bf0-0000-000100000020","pre_event_id":"000659d4-cbb4-6d10-0000-000103000020","order_source":"orderbook"}
{"data":{"id":2043024880267266,"id_str":"2043024880267266","order_type":1,"order_subtype":5,"datetime":"1787620346","microtimestamp":"1787620345817000","amount":0.5,"amount_str":"0.50000000","amount_traded":"0","amount_at_create":"0.50000000","price":79627.82,"price_str":"79627.82","is_liquidation":false},"channel":"live_orders_btcusd","event":"order_created","event_id":"000659d4-cbb4-a7a8-0000-000101000020","pre_event_id":"000659d4-cbb4-9bf0-0000-000100000020","order_source":"orderbook"}
{"data":{"id":2043024880271360,"id_str":"2043024880271360","order_type":0,"order_subtype":5,"datetime":"1787620346","microtimestamp":"1787620345817000","amount":1.2,"amount_str":"1.20000000","amount_traded":"0","amount_at_create":"1.20000000","price":79600,"price_str":"79600.00","is_liquidation":false},"channel":"live_orders_btcusd","event":"order_created","event_id":"000659d4-cbb4-a7a8-0001-000102000020","pre_event_id":"000659d4-cbb4-a7a8-0000-000101000020","order_source":"orderbook"}
{"data":{"id":2043024880205828,"id_str":"2043024880205828","order_type":0,"order_subtype":5,"datetime":"1787620346","microtimestamp":"1787620345844000","amount":0.13,"amount_str":"0.13000000","amount_traded":"0","amount_at_create":"0.13000000","price":79616.38,"price_str":"79616.38","is_liquidation":false},"channel":"live_orders_btcusd","event":"order_deleted","event_id":"000659d4-cbb5-1120-0000-000103000020","pre_event_id":"000659d4-cbb4-a7a8-0001-000102000020","order_source":"orderbook"}
{"data":{"id":2043024880398344,"id_str":"2043024880398344","order_type":0,"order_subtype":0,"datetime":"1787620346","microtimestamp":"1787620345849000","amount":0.00049029,"amount_str":"0.00049029","amount_traded":"0","amount_at_create":"0.00049029","price":78775.17,"price_str":"78775.17","is_liquidation":false},"channel":"live_orders_btcusd","event":"order_created","event_id":"000659d4-cbb5-24a8-0000-000100000020","pre_event_id":"000659d4-cbb5-1120-0000-000103000020","order_source":"orderbook"}
{"data":{"id":2043024879632385,"id_str":"2043024879632385","order_type":0,"order_subtype":5,"datetime":"1787620346","microtimestamp":"1787620345856000","amount":0.19,"amount_str":"0.19000000","amount_traded":"0","amount_at_create":"0.19000000","price":79626.92,"price_str":"79626.92","is_liquidation":false},"channel":"live_orders_btcusd","event":"order_deleted","event_id":"000659d4-cbb5-4000-0000-000101000020","pre_event_id":"000659d4-cbb5-24a8-0000-000100000020","order_source":"orderbook"}
{"data":{"id":2043024880533504,"id_str":"2043024880533504","order_type":0,"order_subtype":5,"datetime":"1787620346","microtimestamp":"1787620345881000","amount":0.00143636,"amount_str":"0.00143636","amount_traded":"0","amount_at_create":"0.00143636","price":71664.23,"price_str":"71664.23","is_liquidation":false},"channel":"live_orders_btcusd","event":"order_created","event_id":"000659d4-cbb5-a1a8-0000-000102000020","pre_event_id":"000659d4-cbb5-4000-0000-000101000020","order_source":"orderbook"}
{"data":{"id":2043024880574475,"id_str":"2043024880574475","order_type":1,"order_subtype":5,"datetime":"1787620346","microtimestamp":"1787620345892000","amount":1.2,"amount_str":"1.20000000","amount_traded":"0","amount_at_create":"1.20000000","price":79643,"price_str":"79643.00","is_liquidation":false},"channel":"live_orders_btcusd","event":"order_created","event_id":"000659d4-cbb5-cca0-0000-000103000020","pre_event_id":"000659d4-cbb5-a1a8-0000-000102000020","order_source":"orderbook"}
{"data":{"id":2043024879886336,"id_str":"2043024879886336","order_type":0,"order_subtype":5,"datetime":"1787620346","microtimestamp":"1787620345893000","amount":0.00143636,"amount_str":"0.00143636","amount_traded":"0","amount_at_create":"0.00143636","price":71664.23,"price_str":"71664.23","is_liquidation":false},"channel":"live_orders_btcusd","event":"order_deleted","event_id":"000659d4-cbb5-d088-0000-000100000020","pre_event_id":"000659d4-cbb5-cca0-0000-000103000020","order_source":"orderbook"}
{"data":{"id":2043024880267266,"id_str":"2043024880267266","order_type":1,"order_subtype":5,"datetime":"1787620346","microtimestamp":"1787620345905000","amount":0.5,"amount_str":"0.50000000","amount_traded":"0","amount_at_create":"0.50000000","price":79627.82,"price_str":"79627.82","is_liquidation":false},"channel":"live_orders_btcusd","event":"order_deleted","event_id":"000659d4-cbb5-ff68-0000-000101000020","pre_event_id":"000659d4-cbb5-d088-0000-000100000020","order_source":"orderbook"}
{"data":{"id":2043024880398344,"id_str":"2043024880398344","order_type":0,"order_subtype":0,"datetime":"1787620346","microtimestamp":"1787620345934000","amount":0.00049029,"amount_str":"0.00049029","amount_traded":"0","amount_at_create":"0.00049029","price":78775.17,"price_str":"78775.17","is_liquidation":false},"channel":"live_orders_btcusd","event":"order_deleted","event_id":"000659d4-cbb6-70b0-0000-000102000020","pre_event_id":"000659d4-cbb5-ff68-0000-000101000020","order_source":"orderbook"}
{"data":{"id":2043024880791552,"id_str":"2043024880791552","order_type":1,"order_subtype":5,"datetime":"1787620346","microtimestamp":"1787620345944000","amount":0.5,"amount_str":"0.50000000","amount_traded":"0","amount_at_create":"0.50000000","price":79627.83,"price_str":"79627.83","is_liquidation":false},"channel":"live_orders_btcusd","event":"order_created","event_id":"000659d4-cbb6-97c0-0000-000103000020","pre_event_id":"000659d4-cbb6-70b0-0000-000102000020","order_source":"orderbook"}
{"data":{"id":2043024880791553,"id_str":"2043024880791553","order_type":0,"order_subtype":5,"datetime":"1787620346","microtimestamp":"1787620345944000","amount":0.06279938,"amount_str":"0.06279938","amount_traded":"0","amount_at_create":"0.06279938","price":79618.61,"price_str":"79618.61","is_liquidation":false},"channel":"live_orders_btcusd","event":"order_created","event_id":"000659d4-cbb6-97c0-0001-000100000020","pre_event_id":"000659d4-cbb6-97c0-0000-000103000020","order_source":"orderbook"}
{"data":{"id":2043024880820225,"id_str":"2043024880820225","order_type":0,"order_subtype":5,"datetime":"1787620346","microtimestamp":"1787620345952000","amount":0.25126781,"amount_str":"0.25126781","amount_traded":"0","amount_at_create":"0.25126781","price":79596.34,"price_str":"79596.34","is_liquidation":false},"channel":"live_orders_btcusd","event":"order_created","event_id":"000659d4-cbb6-b700-0000-000101000020","pre_event_id":"000659d4-cbb6-97c0-0001-000100000020","order_source":"orderbook"}
{"data":{"id":2043024880873476,"id_str":"2043024880873476","order_type":0,"order_subtype":5,"datetime":"1787620346","microtimestamp":"1787620345966000","amount":0.00143636,"amount_str":"0.00143636","amount_traded":"0","amount_at_create":"0.00143636","price":71664.23,"price_str":"71664.23","is_liquidation":false},"channel":"live_orders_btcusd","event":"order_created","event_id":"000659d4-cbb6-edb0-0000-000102000020","pre_event_id":"000659d4-cbb6-b700-0000-000101000020","order_source":"orderbook"}
{"data":{"id":2043024880197636,"id_str":"2043024880197636","order_type":0,"order_subtype":5,"datetime":"1787620346","microtimestamp":"1787620345974000","amount":0.00143636,"amount_str":"0.00143636","amount_traded":"0","amount_at_create":"0.00143636","price":71664.23,"price_str":"71664.23","is_liquidation":false},"channel":"live_orders_btcusd","event":"order_deleted","event_id":"000659d4-cbb7-0cf0-0000-000103000020","pre_event_id":"000659d4-cbb6-edb0-0000-000102000020","order_source":"orderbook"}
{"data":{"id":2043024879583238,"id_str":"2043024879583238","order_type":0,"order_subtype":5,"datetime":"1787620346","microtimestamp":"1787620345974000","amount":0.26349748,"amount_str":"0.26349748","amount_traded":"0","amount_at_create":"0.26349748","price":79608.59,"price_str":"79608.59","is_liquidation":false},"channel":"live_orders_btcusd","event":"order_deleted","event_id":"000659d4-cbb7-0cf0-0001-000100000020","pre_event_id":"000659d4-cbb7-0cf0-0000-000103000020","order_source":"orderbook"}
{"data":{"id":2043024880914432,"id_str":"2043024880914432","order_type":0,"order_subtype":5,"datetime":"1787620346","microtimestamp":"1787620345974000","amount":0.12559138,"amount_str":"0.12559138","amount_traded":"0","amount_at_create":"0.12559138","price":79608.59,"price_str":"79608.59","is_liquidation":false},"channel":"live_orders_btcusd","event":"order_created","event_id":"000659d4-cbb7-0cf0-0002-000101000020","pre_event_id":"000659d4-cbb7-0cf0-0001-000100000020","order_source":"orderbook"}
{"data":{"id":2043024880947200,"id_str":"2043024880947200","order_type":1,"order_subtype":5,"datetime":"1787620346","microtimestamp":"1787620345982000","amount":0.13,"amount_str":"0.13000000","amount_traded":"0","amount_at_create":"0.13000000","price":79652.79,"price_str":"79652.79","is_liquidation":false},"channel":"live_orders_btcusd","event":"order_created","event_id":"000659d4-cbb7-2c30-0000-000102000020","pre_event_id":"000659d4-cbb7-0cf0-0002-000101000020","order_source":"orderbook"}
{"data":{"id":2043024876793857,"id_str":"2043024876793857","order_type":1,"order_subtype":5,"datetime":"1787620346","microtimestamp":"1787620345984000","amount":0.13,"amount_str":"0.13000000","amount_traded":"0","amount_at_create":"0.13000000","price":79671.37,"price_str":"79671.37","is_liquidation":false},"channel":"live_orders_btcusd","event":"order_deleted","event_id":"000659d4-cbb7-3400-0000-000103000020","pre_event_id":"000659d4-cbb7-2c30-0000-000102000020","order_source":"orderbook"}
{"data":{"id":2043024880791553,"id_str":"2043024880791553","order_type":0,"order_subtype":5,"datetime":"1787620346","microtimestamp":"1787620345987000","amount":0.06279938,"amount_str":"0.06279938","amount_traded":"0","amount_at_create":"0.06279938","price":79618.61,"price_str":"79618.61","is_liquidation":false},"channel":"live_orders_btcusd","event":"order_deleted","event_id":"000659d4-cbb7-3fb8-0000-000100000020","pre_event_id":"000659d4-cbb7-3400-0000-000103000020","order_source":"orderbook"}
{"data":{"id":2043024880947200,"id_str":"2043024880947200","order_type":1,"order_subtype":5,"datetime":"1787620346","microtimestamp":"1787620345988000","amount":0.13,"amount_str":"0.13000000","amount_traded":"0","amount_at_create":"0.13000000","price":79652.79,"price_str":"79652.79","is_liquidation":false},"channel":"live_orders_btcusd","event":"order_deleted","event_id":"000659d4-cbb7-43a0-0000-000101000020","pre_event_id":"000659d4-cbb7-3fb8-0000-000100000020","order_source":"orderbook"}
{"data":{"id":2043024881029121,"id_str":"2043024881029121","order_type":0,"order_subtype":5,"datetime":"1787620346","microtimestamp":"1787620346002000","amount":0.06280086,"amount_str":"0.06280086","amount_traded":"0","amount_at_create":"0.06280086","price":79616.73,"price_str":"79616.73","is_liquidation":false},"channel":"live_orders_btcusd","event":"order_created","event_id":"000659d4-cbb7-7a50-0000-000102000020","pre_event_id":"000659d4-cbb7-43a0-0000-000101000020","order_source":"orderbook"}
{"data":{"id":2043024881065995,"id_str":"2043024881065995","order_type":1,"order_subtype":5,"datetime":"1787620346","microtimestamp":"1787620346012000","amount":0.00132259,"amount_str":"0.00132259","amount_traded":"0","amount_at_create":"0.00132259","price":79626.93,"price_str":"79626.93","is_liquidation":false},"channel":"live_orders_btcusd","event":"order_created","event_id":"000659d4-cbb7-a160-0000-000103000020","pre_event_id":"000659d4-cbb7-7a50-0000-000102000020","order_source":"orderbook"}
{"data":{"id":2043024880791552,"id_str":"2043024880791552","order_type":1,"order_subtype":5,"datetime":"1787620346","microtimestamp":"1787620346031000","amount":0.5,"amount_str":"0.50000000","amount_traded":"0","amount_at_create":"0.50000000","price":79627.83,"price_str":"79627.83","is_liquidation":false},"channel":"live_orders_btcusd","event":"order_deleted","event_id":"000659d4-cbb7-eb98-0000-000100000020","pre_event_id":"000659d4-cbb7-a160-0000-000103000020","order_source":"orderbook"}
{"data":{"id":2043024881180673,"id_str":"2043024881180673","order_type":0,"order_subtype":0,"datetime":"1787620346","microtimestamp":"1787620346039000","amount":0.00049029,"amount_str":"0.00049029","amount_traded":"0","amount_at_create":"0.00049029","price":78775.17,"price_str":"78775.17","is_liquidation":false},"channel":"live_orders_btcusd","event":"order_created","event_id":"000659d4-cbb8-0ad8-0000-000101000020","pre_event_id":"000659d4-cbb7-eb98-0000-000100000020","order_source":"orderbook"}
{"data":{"id":2043024881192963,"id_str":"2043024881192963","order_type":0,"order_subtype":5,"datetime":"1787620346","microtimestamp":"1787620346042000","amount":0.00143636,"amount_str":"0.00143636","amount_traded":"0","amount_at_create":"0.00143636","price":71664.23,"price_str":"71664.23","is_liquidation":false},"channel":"live_orders_btcusd","event":"order_created","event_id":"000659d4-cbb8-1690-0000-000102000020","pre_event_id":"000659d4-cbb8-0ad8-0000-000101000020","order_source":"orderbook"}
{"data":{"id":2043024880533504,"id_str":"2043024880533504","order_type":0,"order_subtype":5,"datetime":"1787620346","microtimestamp":"1787620346045000","amount":0.00143636,"amount_str":"0.00143636","amount_traded":"0","amount_at_create":"0.00143636","price":71664.23,"price_str":"71664.23","is_liquidation":false},"channel":"live_orders_btcusd","event":"order_deleted","event_id":"000659d4-cbb8-2248-0000-000103000020","pre_event_id":"000659d4-cbb8-1690-0000-000102000020","order_source":"orderbook"}
{"data":{"id":2043024881307651,"id_str":"2043024881307651","order_type":1,"order_subtype":5,"datetime":"1787620346","microtimestamp":"1787620346070000","amount":0.5,"amount_str":"0.50000000","amount_traded":"0","amount_at_create":"0.50000000","price":79627.84,"price_str":"79627.84","is_liquidation":false},"channel":"live_orders_btcusd","event":"order_created","event_id":"000659d4-cbb8-83f0-0000-000100000020","pre_event_id":"000659d4-cbb8-2248-0000-000103000020","order_source":"orderbook"}
{"data":{"id":2043024881508352,"id_str":"2043024881508352","order_type":0,"order_subtype":5,"datetime":"1787620346","microtimestamp":"1787620346120000","amount":0.00143636,"amount_str":"0.00143636","amount_traded":"0","amount_at_create":"0.00143636","price":71664.23,"price_str":"71664.23","is_liquidation":false},"channel":"live_orders_btcusd","event":"order_created","event_id":"000659d4-cbb9-4740-0000-000101000020","pre_event_id":"000659d4-cbb8-83f0-0000-000100000020","order_source":"orderbook"}
{"data":{"id":2043024881528835,"id_str":"2043024881528835","order_type":1,"order_subtype":4,"datetime":"1787620346","microtimestamp":"1787620346125000","amount":6.158e-05,"amount_str":"0.00006158","amount_traded":"0","amount_at_create":"0.00006158","price":82016,"price_str":"82016.00","is_liquidation":false},"channel":"live_orders_btcusd","event":"order_created","event_id":"000659d4-cbb9-5ac8-0000-000102000020","pre_event_id":"000659d4-cbb9-4740-0000-000101000020","order_source":"orderbook"}
{"data":{"id":2043024881528835,"id_str":"2043024881528835","order_type":1,"order_subtype":4,"datetime":"1787620346","microtimestamp":"1787620346125000","amount":6.158e-05,"amount_str":"0.00006158","amount_traded":"0","amount_at_create":"0.00006158","price":82016,"price_str":"82016.00","is_liquidation":false},"channel":"live_orders_btcusd","event":"order_deleted","event_id":"000659d4-cbb9-5ac8-0001-000103000020","pre_event_id":"000659d4-cbb9-5ac8-0000-000102000020","order_source":"orderbook"}
{"data":{"id":2043024881180673,"id_str":"2043024881180673","order_type":0,"order_subtype":0,"datetime":"1787620346","microtimestamp":"1787620346130000","amount":0.00049029,"amount_str":"0.00049029","amount_traded":"0","amount_at_create":"0.00049029","price":78775.17,"price_str":"78775.17","is_liquidation":false},"channel":"live_orders_btcusd","event":"order_deleted","event_id":"000659d4-cbb9-6e50-0000-000100000020","pre_event_id":"000659d4-cbb9-5ac8-0001-000103000020","order_source":"orderbook"}
{"data":{"id":2043024880873476,"id_str":"2043024880873476","order_type":0,"order_subtype":5,"datetime":"1787620346","microtimestamp":"1787620346134000","amount":0.00143636,"amount_str":"0.00143636","amount_traded":"0","amount_at_create":"0.00143636","price":71664.23,"price_str":"71664.23","is_liquidation":false},"channel":"live_orders_btcusd","event":"order_deleted","event_id":"000659d4-cbb9-7df0-0000-000101000020","pre_event_id":"000659d4-cbb9-6e50-0000-000100000020","order_source":"orderbook"}
{"data":{"id":2043024881655810,"id_str":"2043024881655810","order_type":1,"order_subtype":5,"datetime":"1787620346","microtimestamp":"1787620346155000","amount":0.13,"amount_str":"0.13000000","amount_traded":"0","amount_at_create":"0.13000000","price":79653.7,"price_str":"79653.70","is_liquidation":false},"channel":"live_orders_btcusd","event":"order_created","event_id":"000659d4-cbb9-cff8-0000-000102000020","pre_event_id":"000659d4-cbb9-7df0-0000-000101000020","order_source":"orderbook"}
{"data":{"id":2043024881307651,"id_str":"2043024881307651","order_type":1,"order_subtype":5,"datetime":"1787620346","microtimestamp":"1787620346164000","amount":0.5,"amount_str":"0.50000000","amount_traded":"0","amount_at_create":"0.50000000","price":79627.84,"price_str":"79627.84","is_liquidation":false},"channel":"live_orders_btcusd","event":"order_deleted","event_id":"000659d4-cbb9-f320-0000-000103000020","pre_event_id":"000659d4-cbb9-cff8-0000-000102000020","order_source":"orderbook"}
{"data":{"id":2043024881655810,"id_str":"2043024881655810","order_type":1,"order_subtype":5,"datetime":"1787620346","microtimestamp":"1787620346200000","amount":0.13,"amount_str":"0.13000000","amount_traded":"0","amount_at_create":"0.13000000","price":79653.7,"price_str":"79653.70","is_liquidation":false},"channel":"live_orders_btcusd","event":"order_deleted","event_id":"000659d4-cbba-7fc0-0000-000100000020","pre_event_id":"000659d4-cbb9-f320-0000-000103000020","order_source":"orderbook"}
{"data":{"id":2043024881844229,"id_str":"2043024881844229","order_type":0,"order_subtype":5,"datetime":"1787620346","microtimestamp":"1787620346202000","amount":0.00143636,"amount_str":"0.00143636","amount_traded":"0","amount_at_create":"0.00143636","price":71664.23,"price_str":"71664.23","is_liquidation":false},"channel":"live_orders_btcusd","event":"order_created","event_id":"000659d4-cbba-8790-0000-000101000020","pre_event_id":"000659d4-cbba-7fc0-0000-000100000020","order_source":"orderbook"}
{"data":{"id":2043024881852421,"id_str":"2043024881852421","order_type":1,"order_subtype":5,"datetime":"1787620346","microtimestamp":"1787620346204000","amount":0.5,"amount_str":"0.50000000","amount_traded":"0","amount_at_create":"0.50000000","price":79627.85,"price_str":"79627.85","is_liquidation":false},"channel":"live_orders_btcusd","event":"order_created","event_id":"000659d4-cbba-8f60-0000-000102000020","pre_event_id":"000659d4-cbba-8790-0000-000101000020","order_source":"orderbook"}
{"data":{"id":2043024881192963,"id_str":"2043024881192963","order_type":0,"order_subtype":5,"datetime":"1787620346","microtimestamp":"1787620346214000","amount":0.00143636,"amount_str":"0.00143636","amount_traded":"0","amount_at_create":"0.00143636","price":71664.23,"price_str":"71664.23","is_liquidation":false},"channel":"live_orders_btcusd","event":"order_deleted","event_id":"000659d4-cbba-b670-0000-000103000020","pre_event_id":"000659d4-cbba-8f60-0000-000102000020","order_source":"orderbook"}
{"data":{"id":2043024881893379,"id_str":"2043024881893379","order_type":0,"order_subtype":0,"datetime":"1787620346","microtimestamp":"1787620346214000","amount":0.00049029,"amount_str":"0.00049029","amount_traded":"0","amount_at_create":"0.00049029","price":78775.17,"price_str":"78775.17","is_liquidation":false},"channel":"live_orders_btcusd","event":"order_created","event_id":"000659d4-cbba-b670-0001-000100000020","pre_event_id":"000659d4-cbba-b670-0000-000103000020","order_source":"orderbook"}
{"data":{"id":2043024882008064,"id_str":"2043024882008064","order_type":1,"order_subtype":4,"datetime":"1787620346","microtimestamp":"1787620346241000","amount":6.158e-05,"amount_str":"0.00006158","amount_traded":"0","amount_at_create":"0.00006158","price":82016,"price_str":"82016.00","is_liquidation":false},"channel":"live_orders_btcusd","event":"order_created","event_id":"000659d4-cbbb-1fe8-0000-000101000020","pre_event_id":"000659d4-cbba-b670-0001-000100000020","order_source":"orderbook"}
{"data":{"id":2043024882008064,"id_str":"2043024882008064","order_type":1,"order_subtype":4,"datetime":"1787620346","microtimestamp":"1787620346241000","amount":6.158e-05,"amount_str":"0.00006158","amount_traded":"0","amount_at_create":"0.00006158","price":82016,"price_str":"82016.00","is_liquidation":false},"channel":"live_orders_btcusd","event":"order_deleted","event_id":"000659d4-cbbb-1fe8-0001-000102000020","pre_event_id":"000659d4-cbbb-1fe8-0000-000101000020","order_source":"orderbook"}
{"data":{"id":2043024879329282,"id_str":"2043024879329282","order_type":0,"order_subtype":5,"datetime":"1787620346","microtimestamp":"1787620346247000","amount":0.62797427,"amount_str":"0.62797427","amount_traded":"0","amount_at_create":"0.62797427","price":79604.76,"price_str":"79604.76","is_liquidation":false},"channel":"live_orders_btcusd","event":"order_deleted","event_id":"000659d4-cbbb-3758-0000-000103000020","pre_event_id":"000659d4-cbbb-1fe8-0001-000102000020","order_source":"orderbook"}
{"data":{"id":2043024882073602,"id_str":"2043024882073602","order_type":0,"order_subtype":5,"datetime":"1787620346","microtimestamp":"1787620346257000","amount":0.62795328,"amount_str":"0.62795328","amount_traded":"0","amount_at_create":"0.62795328","price":79606.83,"price_str":"79606.83","is_liquidation":false},"channel":"live_orders_btcusd","event":"order_created","event_id":"000659d4-cbbb-5e68-0000-000100000020","pre_event_id":"000659d4-cbbb-3758-0000-000103000020","order_source":"orderbook"}
