{"event":"bts:subscription_succeeded","channel":"live_orders_btcusd","data":{}}
{"data":{"id":2043024875446273,"id_str":"2043024875446273","order_type":0,"order_subtype":5,"datetime":"1787620345","microtimestamp":"1787620344640000","amount":0.25,"amount_str":"0.25000000","amount_traded":"0","amount_at_create":"0.25000000","price":79640.78,"price_str":"79640.78","is_liquidation":false},"channel":"live_orders_btcusd","event":"order_created","event_id":"000659d4-cba2-b200-0000-000101000020","pre_event_id":"000659d4-cba2-7768-0000-000100000020","order_source":"orderbook"}
{"data":{"id":2043024875212801,"id_str":"2043024875212801","order_type":0,"order_subtype":0,"datetime":"1787620345","microtimestamp":"1787620344675000","amount":0.00049029,"amount_str":"0.00049029","amount_traded":"0","amount_at_create":"0.00049029","price":78775.17,"price_str":"78775.17","is_liquidation":false},"channel":"live_orders_btcusd","event":"order_deleted","event_id":"000659d4-cba3-3ab8-0000-000102000020","pre_event_id":"000659d4-cba2-b200-0000-000101000020","order_source":"orderbook"}
{"data":{"id":2043024875610114,"id_str":"2043024875610114","order_type":0,"order_subtype":5,"datetime":"1787620345","microtimestamp":"1787620344680000","amount":0.00143636,"amount_str":"0.00143636","amount_traded":"0","amount_at_create":"0.00143636","price":71676.81,"price_str":"71676.81","is_liquidation":false},"channel":"live_orders_btcusd","event":"order_created","event_id":"000659d4-cba3-4e40-0000-000103000020","pre_event_id":"000659d4-cba3-3ab8-0000-000102000020","order_source":"orderbook"}
{"data":{"id":2043024874967040,"id_str":"2043024874967040","order_type":0,"order_subtype":5,"datetime":"1787620345","microtimestamp":"1787620344693000","amount":0.00143636,"amount_str":"0.00143636","amount_traded":"0","amount_at_create":"0.00143636","price":71676.81,"price_str":"71676.81","is_liquidation":false},"channel":"live_orders_btcusd","event":"order_deleted","event_id":"000659d4-cba3-8108-0000-000100000020","pre_event_id":"000659d4-cba3-4e40-0000-000103000020","order_source":"orderbook"}
{"data":{"id":2043024875712512,"id_str":"2043024875712512","order_type":0,"order_subtype":4,"datetime":"1787620345","microtimestamp":"1787620344704000","amount":0.001,"amount_str":"0.00100000","amount_traded":"0","amount_at_create":"0.00100000","price":79644.33,"price_str":"79644.33","is_liquidation":false},"channel":"live_orders_btcusd","event":"order_created","event_id":"000659d4-cba3-ac00-0000-000101000020","pre_event_id":"000659d4-cba3-8108-0000-000100000020","order_source":"orderbook"}
{"data":{"id":2043024875712512,"id_str":"2043024875712512","order_type":0,"order_subtype":4,"datetime":"1787620345","microtimestamp":"1787620344704000","amount":0,"amount_str":"0","amount_traded":"0.00100000","amount_at_create":"0.00100000","price":79640.91,"price_str":"79640.91","is_liquidation":false},"channel":"live_orders_btcusd","event":"order_deleted","event_id":"000659d4-cba3-ac00-0001-000102000020","pre_event_id":"000659d4-cba3-ac00-0000-000101000020","order_source":"orderbook"}
{"data":{"id":2043024863952899,"id_str":"2043024863952899","order_type":1,"order_subtype":5,"datetime":"1787620345","microtimestamp":"1787620344704000","amount":0.0217818,"amount_str":"0.02178180","amount_traded":"0.00100000","amount_at_create":"0.06278180","price":79640.91,"price_str":"79640.91","is_liquidation":false},"channel":"live_orders_btcusd","event":"order_changed","event_id":"000659d4-cba3-ac00-0002-000103000020","pre_event_id":"000659d4-cba3-ac00-0001-000102000020","order_source":"orderbook"}
{"data":{"id":2043024875765760,"id_str":"2043024875765760","order_type":1,"order_subtype":5,"datetime":"1787620345","microtimestamp":"1787620344717000","amount":0.06549561,"amount_str":"0.06549561","amount_traded":"0","amount_at_create":"0.06549561","price":79661.99,"price_str":"79661.99","is_liquidation":false},"channel":"live_orders_btcusd","event":"order_created","event_id":"000659d4-cba3-dec8-0000-000100000020","pre_event_id":"000659d4-cba3-ac00-0002-000103000020","order_source":"orderbook"}
{"data":{"id":2043024875765766,"id_str":"2043024875765766","order_type":1,"order_subtype":5,"datetime":"1787620345","microtimestamp":"1787620344717000","amount":0.02456085,"amount_str":"0.02456085","amount_traded":"0","amount_at_create":"0.02456085","price":79658,"price_str":"79658.00","is_liquidation":false},"channel":"live_orders_btcusd","event":"order_created","event_id":"000659d4-cba3-dec8-0001-000101000020","pre_event_id":"000659d4-cba3-dec8-0000-000100000020","order_source":"orderbook"}
{"data":{"id":2043024875773954,"id_str":"2043024875773954","order_type":1,"order_subtype":5,"datetime":"1787620345","microtimestamp":"1787620344719000","amount":0.08186951,"amount_str":"0.08186951","amount_traded":"0","amount_at_create":"0.08186951","price":79660,"price_str":"79660.00","is_liquidation":false},"channel":"live_orders_btcusd","event":"order_created","event_id":"000659d4-cba3-e698-0000-000102000020","pre_event_id":"000659d4-cba3-dec8-0001-000101000020","order_source":"orderbook"}
{"data":{"id":2043024875823106,"id_str":"2043024875823106","order_type":1,"order_subtype":4,"datetime":"1787620345","microtimestamp":"1787620344731000","amount":6.157e-05,"amount_str":"0.00006157","amount_traded":"0","amount_at_create":"0.00006157","price":82030.13,"price_str":"82030.13","is_liquidation":false},"channel":"live_orders_btcusd","event":"order_created","event_id":"000659d4-cba4-1578-0000-000103000020","pre_event_id":"000659d4-cba3-e698-0000-000102000020","order_source":"orderbook"}
{"data":{"id":2043024875823106,"id_str":"2043024875823106","order_type":1,"order_subtype":4,"datetime":"1787620345","microtimestamp":"1787620344731000","amount":6.157e-05,"amount_str":"0.00006157","amount_traded":"0","amount_at_create":"0.00006157","price":82030.13,"price_str":"82030.13","is_liquidation":false},"channel":"live_orders_btcusd","event":"order_deleted","event_id":"000659d4-cba4-1578-0001-000100000020","pre_event_id":"000659d4-cba4-1578-0000-000103000020","order_source":"orderbook"}
{"data":{"id":2043024875872260,"id_str":"2043024875872260","order_type":0,"order_subtype":5,"datetime":"1787620345","microtimestamp":"1787620344744000","amount":0.13,"amount_str":"0.13000000","amount_traded":"0","amount_at_create":"0.13000000","price":79633.21,"price_str":"79633.21","is_liquidation":false},"channel":"live_orders_btcusd","event":"order_created","event_id":"000659d4-cba4-4840-0000-000101000020","pre_event_id":"000659d4-cba4-1578-0001-000100000020","order_source":"orderbook"}
{"data":{"id":2043024874471426,"id_str":"2043024874471426","order_type":0,"order_subtype":5,"datetime":"1787620345","microtimestamp":"1787620344753000","amount":0.13,"amount_str":"0.13000000","amount_traded":"0","amount_at_create":"0.13000000","price":79631.87,"price_str":"79631.87","is_liquidation":false},"channel":"live_orders_btcusd","event":"order_deleted","event_id":"000659d4-cba4-6b68-0000-000102000020","pre_event_id":"000659d4-cba4-4840-0000-000101000020","order_source":"orderbook"}
{"data":{"id":2043024875261953,"id_str":"2043024875261953","order_type":0,"order_subtype":5,"datetime":"1787620345","microtimestamp":"1787620344754000","amount":0.5,"amount_str":"0.50000000","amount_traded":"0","amount_at_create":"0.50000000","price":79636.8,"price_str":"79636.80","is_liquidation":false},"channel":"live_orders_btcusd","event":"order_deleted","event_id":"000659d4-cba4-6f50-0000-000103000020","pre_event_id":"000659d4-cba4-6b68-0000-000102000020","order_source":"orderbook"}
{"data":{"id":2043024875941888,"id_str":"2043024875941888","order_type":0,"order_subtype":5,"datetime":"1787620345","microtimestamp":"1787620344760000","amount":0.00143636,"amount_str":"0.00143636","amount_traded":"0","amount_at_create":"0.00143636","price":71676.81,"price_str":"71676.81","is_liquidation":false},"channel":"live_orders_btcusd","event":"order_created","event_id":"000659d4-cba4-86c0-0000-000100000020","pre_event_id":"000659d4-cba4-6f50-0000-000103000020","order_source":"orderbook"}
{"data":{"id":2043024875941889,"id_str":"2043024875941889","order_type":0,"order_subtype":0,"datetime":"1787620345","microtimestamp":"1787620344763000","amount":0.00049029,"amount_str":"0.00049029","amount_traded":"0","amount_at_create":"0.00049029","price":78775.17,"price_str":"78775.17","is_liquidation":false},"channel":"live_orders_btcusd","event":"order_created","event_id":"000659d4-cba4-9278-0000-000101000020","pre_event_id":"000659d4-cba4-86c0-0000-000100000020","order_source":"orderbook"}
{"data":{"id":2043024874049536,"id_str":"2043024874049536","order_type":0,"order_subtype":5,"datetime":"1787620345","microtimestamp":"1787620344768000","amount":0.18835401,"amount_str":"0.18835401","amount_traded":"0","amount_at_create":"0.18835401","price":79621.35,"price_str":"79621.35","is_liquidation":false},"channel":"live_orders_btcusd","event":"order_deleted","event_id":"000659d4-cba4-a600-0000-000102000020","pre_event_id":"000659d4-cba4-9278-0000-000101000020","order_source":"orderbook"}
{"data":{"id":2043024875446273,"id_str":"2043024875446273","order_type":0,"order_subtype":5,"datetime":"1787620345","microtimestamp":"1787620344771000","amount":0.25,"amount_str":"0.25000000","amount_traded":"0","amount_at_create":"0.25000000","price":79640.78,"price_str":"79640.78","is_liquidation":false},"channel":"live_orders_btcusd","event":"order_deleted","event_id":"000659d4-cba4-b1b8-0000-000103000020","pre_event_id":"000659d4-cba4-a600-0000-000102000020","order_source":"orderbook"}
{"data":{"id":2043024875286529,"id_str":"2043024875286529","order_type":0,"order_subtype":5,"datetime":"1787620345","microtimestamp":"1787620344774000","amount":0.00143636,"amount_str":"0.00143636","amount_traded":"0","amount_at_create":"0.00143636","price":71676.81,"price_str":"71676.81","is_liquidation":false},"channel":"live_orders_btcusd","event":"order_deleted","event_id":"000659d4-cba4-bd70-0000-000100000020","pre_event_id":"000659d4-cba4-b1b8-0000-000103000020","order_source":"orderbook"}
{"data":{"id":2043024876015616,"id_str":"2043024876015616","order_type":0,"order_subtype":5,"datetime":"1787620345","microtimestamp":"1787620344778000","amount":0.18835267,"amount_str":"0.18835267","amount_traded":"0","amount_at_create":"0.18835267","price":79622.58,"price_str":"79622.58","is_liquidation":false},"channel":"live_orders_btcusd","event":"order_created","event_id":"000659d4-cba4-cd10-0000-000101000020","pre_event_id":"000659d4-cba4-bd70-0000-000100000020","order_source":"orderbook"}
{"data":{"id":2043024873324555,"id_str":"2043024873324555","order_type":1,"order_subtype":5,"datetime":"1787620345","microtimestamp":"1787620344789000","amount":0.81593385,"amount_str":"0.81593385","amount_traded":"0","amount_at_create":"0.81593385","price":79672.55,"price_str":"79672.55","is_liquidation":false},"channel":"live_orders_btcusd","event":"order_deleted","event_id":"000659d4-cba4-f808-0000-000102000020","pre_event_id":"000659d4-cba4-cd10-0000-000101000020","order_source":"orderbook"}
{"data":{"id":2043024860094477,"id_str":"2043024860094477","order_type":1,"order_subtype":5,"datetime":"1787620345","microtimestamp":"1787620344797000","amount":0.48956031,"amount_str":"0.48956031","amount_traded":"0","amount_at_create":"0.48956031","price":79653.42,"price_str":"79653.42","is_liquidation":false},"channel":"live_orders_btcusd","event":"order_deleted","event_id":"000659d4-cba5-1748-0000-000103000020","pre_event_id":"000659d4-cba4-f808-0000-000102000020","order_source":"orderbook"}
{"data":{"id":2043024876146693,"id_str":"2043024876146693","order_type":0,"order_subtype":5,"datetime":"1787620345","microtimestamp":"1787620344811000","amount":0.25,"amount_str":"0.25000000","amount_traded":"0","amount_at_create":"0.25000000","price":79640.77,"price_str":"79640.77","is_liquidation":false},"channel":"live_orders_btcusd","event":"order_created","event_id":"000659d4-cba5-4df8-0000-000100000020","pre_event_id":"000659d4-cba5-1748-0000-000103000020","order_source":"orderbook"}
{"data":{"id":2043024876150784,"id_str":"2043024876150784","order_type":0,"order_subtype":5,"datetime":"1787620345","microtimestamp":"1787620344811000","amount":0.5,"amount_str":"0.50000000","amount_traded":"0","amount_at_create":"0.50000000","price":79636.79,"price_str":"79636.79","is_liquidation":false},"channel":"live_orders_btcusd","event":"order_created","event_id":"000659d4-cba5-4df8-0001-000101000020","pre_event_id":"000659d4-cba5-4df8-0000-000100000020","order_source":"orderbook"}
{"data":{"id":2043024876158978,"id_str":"2043024876158978","order_type":1,"order_subtype":5,"datetime":"1787620345","microtimestamp":"1787620344814000","amount":0.48956031,"amount_str":"0.48956031","amount_traded":"0","amount_at_create":"0.48956031","price":79668.12,"price_str":"79668.12","is_liquidation":false},"channel":"live_orders_btcusd","event":"order_created","event_id":"000659d4-cba5-59b0-0000-000102000020","pre_event_id":"000659d4-cba5-4df8-0001-000101000020","order_source":"orderbook"}
{"data":{"id":2043024874045446,"id_str":"2043024874045446","order_type":0,"order_subtype":5,"datetime":"1787620345","microtimestamp":"1787620344820000","amount":0.62784672,"amount_str":"0.62784672","amount_traded":"0","amount_at_create":"0.62784672","price":79619.36,"price_str":"79619.36","is_liquidation":false},"channel":"live_orders_btcusd","event":"order_deleted","event_id":"000659d4-cba5-7120-0000-000103000020","pre_event_id":"000659d4-cba5-59b0-0000-000102000020","order_source":"orderbook"}
{"data":{"id":2043024876216320,"id_str":"2043024876216320","order_type":1,"order_subtype":5,"datetime":"1787620345","microtimestamp":"1787620344827000","amount":0.81593385,"amount_str":"0.81593385","amount_traded":"0","amount_at_create":"0.81593385","price":79672.63,"price_str":"79672.63","is_liquidation":false},"channel":"live_orders_btcusd","event":"order_created","event_id":"000659d4-cba5-8c78-0000-000100000020","pre_event_id":"000659d4-cba5-7120-0000-000103000020","order_source":"orderbook"}
{"data":{"id":2043024876228616,"id_str":"2043024876228616","order_type":0,"order_subtype":5,"datetime":"1787620345","microtimestamp":"1787620344830000","amount":0.62784324,"amount_str":"0.62784324","amount_traded":"0","amount_at_create":"0.62784324","price":79620.64,"price_str":"79620.64","is_liquidation":false},"channel":"live_orders_btcusd","event":"order_created","event_id":"000659d4-cba5-9830-0000-000101000020","pre_event_id":"000659d4-cba5-8c78-0000-000100000020","order_source":"orderbook"}
{"data":{"id":2043024876265475,"id_str":"2043024876265475","order_type":0,"order_subtype":5,"datetime":"1787620345","microtimestamp":"1787620344840000","amount":0.00143636,"amount_str":"0.00143636","amount_traded":"0","amount_at_create":"0.00143636","price":71676.81,"price_str":"71676.81","is_liquidation":false},"channel":"live_orders_btcusd","event":"order_created","event_id":"000659d4-cba5-bf40-0000-000102000020","pre_event_id":"000659d4-cba5-9830-0000-000101000020","order_source":"orderbook"}
{"data":{"id":2043024875610114,"id_str":"2043024875610114","order_type":0,"order_subtype":5,"datetime":"1787620345","microtimestamp":"1787620344854000","amount":0.00143636,"amount_str":"0.00143636","amount_traded":"0","amount_at_create":"0.00143636","price":71676.81,"price_str":"71676.81","is_liquidation":false},"channel":"live_orders_btcusd","event":"order_deleted","event_id":"000659d4-cba5-f5f0-0000-000103000020","pre_event_id":"000659d4-cba5-bf40-0000-000102000020","order_source":"orderbook"}
{"data":{"id":2043024875941889,"id_str":"2043024875941889","order_type":0,"order_subtype":0,"datetime":"1787620345","microtimestamp":"1787620344855000","amount":0.00049029,"amount_str":"0.00049029","amount_traded":"0","amount_at_create":"0.00049029","price":78775.17,"price_str":"78775.17","is_liquidation":false},"channel":"live_orders_btcusd","event":"order_deleted","event_id":"000659d4-cba5-f9d8-0000-000100000020","pre_event_id":"000659d4-cba5-f5f0-0000-000103000020","order_source":"orderbook"}
{"data":{"id":2043024874057729,"id_str":"2043024874057729","order_type":0,"order_subtype":5,"datetime":"1787620345","microtimestamp":"1787620344868000","amount":0.50227736,"amount_str":"0.50227736","amount_traded":"0","amount_at_create":"0.50227736","price":79617.37,"price_str":"79617.37","is_liquidation":false},"channel":"live_orders_btcusd","event":"order_deleted","event_id":"000659d4-cba6-2ca0-0000-000101000020","pre_event_id":"000659d4-cba5-f9d8-0000-000100000020","order_source":"orderbook"}
{"data":{"id":2043024876421120,"id_str":"2043024876421120","order_type":0,"order_subtype":5,"datetime":"1787620345","microtimestamp":"1787620344878000","amount":0.50227536,"amount_str":"0.50227536","amount_traded":"0","amount_at_create":"0.50227536","price":79618.69,"price_str":"79618.69","is_liquidation":false},"channel":"live_orders_btcusd","event":"order_created","event_id":"000659d4-cba6-53b0-0000-000102000020","pre_event_id":"000659d4-cba6-2ca0-0000-000101000020","order_source":"orderbook"}
{"data":{"id":2043024875319298,"id_str":"2043024875319298","order_type":0,"order_subtype":5,"datetime":"1787620345","microtimestamp":"1787620344901000","amount":0.06278858,"amount_str":"0.06278858","amount_traded":"0","amount_at_create":"0.06278858","price":79632.31,"price_str":"79632.31","is_liquidation":false},"channel":"live_orders_btcusd","event":"order_deleted","event_id":"000659d4-cba6-ad88-0000-000103000020","pre_event_id":"000659d4-cba6-53b0-0000-000102000020","order_source":"orderbook"}
{"data":{"id":2043024875872260,"id_str":"2043024875872260","order_type":0,"order_subtype":5,"datetime":"1787620345","microtimestamp":"1787620344908000","amount":0.13,"amount_str":"0.13000000","amount_traded":"0","amount_at_create":"0.13000000","price":79633.21,"price_str":"79633.21","is_liquidation":false},"channel":"live_orders_btcusd","event":"order_deleted","event_id":"000659d4-cba6-c8e0-0000-000100000020","pre_event_id":"000659d4-cba6-ad88-0000-000103000020","order_source":"orderbook"}
{"data":{"id":2043024876150784,"id_str":"2043024876150784","order_type":0,"order_subtype":5,"datetime":"1787620345","microtimestamp":"1787620344913000","amount":0.5,"amount_str":"0.50000000","amount_traded":"0","amount_at_create":"0.50000000","price":79636.79,"price_str":"79636.79","is_liquidation":false},"channel":"live_orders_btcusd","event":"order_deleted","event_id":"000659d4-cba6-dc68-0000-000101000020","pre_event_id":"000659d4-cba6-c8e0-0000-000100000020","order_source":"orderbook"}
{"data":{"id":2043024876584967,"id_str":"2043024876584967","order_type":0,"order_subtype":5,"datetime":"1787620345","microtimestamp":"1787620344918000","amount":0.06279536,"amount_str":"0.06279536","amount_traded":"0","amount_at_create":"0.06279536","price":79623.71,"price_str":"79623.71","is_liquidation":false},"channel":"live_orders_btcusd","event":"order_created","event_id":"000659d4-cba6-eff0-0000-000102000020","pre_event_id":"000659d4-cba6-dc68-0000-000101000020","order_source":"orderbook"}
{"data":{"id":2043024876601346,"id_str":"2043024876601346","order_type":0,"order_subtype":5,"datetime":"1787620345","microtimestamp":"1787620344921000","amount":0.00143636,"amount_str":"0.00143636","amount_traded":"0","amount_at_create":"0.00143636","price":71676.81,"price_str":"71676.81","is_liquidation":false},"channel":"live_orders_btcusd","event":"order_created","event_id":"000659d4-cba6-fba8-0000-000103000020","pre_event_id":"000659d4-cba6-eff0-0000-000102000020","order_source":"orderbook"}
{"data":{"id":2043024875941888,"id_str":"2043024875941888","order_type":0,"order_subtype":5,"datetime":"1787620345","microtimestamp":"1787620344934000","amount":0.00143636,"amount_str":"0.00143636","amount_traded":"0","amount_at_create":"0.00143636","price":71676.81,"price_str":"71676.81","is_liquidation":false},"channel":"live_orders_btcusd","event":"order_deleted","event_id":"000659d4-cba7-2e70-0000-000100000020","pre_event_id":"000659d4-cba6-fba8-0000-000103000020","order_source":"orderbook"}
{"data":{"id":2043024876707842,"id_str":"2043024876707842","order_type":0,"order_subtype":0,"datetime":"1787620345","microtimestamp":"1787620344947000","amount":0.00049029,"amount_str":"0.00049029","amount_traded":"0","amount_at_create":"0.00049029","price":78775.17,"price_str":"78775.17","is_liquidation":false},"channel":"live_orders_btcusd","event":"order_created","event_id":"000659d4-cba7-6138-0000-000101000020","pre_event_id":"000659d4-cba7-2e70-0000-000100000020","order_source":"orderbook"}
{"data":{"id":2043024876740615,"id_str":"2043024876740615","order_type":0,"order_subtype":5,"datetime":"1787620345","microtimestamp":"1787620344956000","amount":0.5,"amount_str":"0.50000000","amount_traded":"0","amount_at_create":"0.50000000","price":79636.78,"price_str":"79636.78","is_liquidation":false},"channel":"live_orders_btcusd","event":"order_created","event_id":"000659d4-cba7-8460-0000-000102000020","pre_event_id":"000659d4-cba7-6138-0000-000101000020","order_source":"orderbook"}
{"data":{"id":2043024876146693,"id_str":"2043024876146693","order_type":0,"order_subtype":5,"datetime":"1787620345","microtimestamp":"1787620344957000","amount":0.25,"amount_str":"0.25000000","amount_traded":"0","amount_at_create":"0.25000000","price":79640.77,"price_str":"79640.77","is_liquidation":false},"channel":"live_orders_btcusd","event":"order_deleted","event_id":"000659d4-cba7-8848-0000-000103000020","pre_event_id":"000659d4-cba7-8460-0000-000102000020","order_source":"orderbook"}
{"data":{"id":2043024876793857,"id_str":"2043024876793857","order_type":1,"order_subtype":5,"datetime":"1787620345","microtimestamp":"1787620344968000","amount":0.13,"amount_str":"0.13000000","amount_traded":"0","amount_at_create":"0.13000000","price":79671.37,"price_str":"79671.37","is_liquidation":false},"channel":"live_orders_btcusd","event":"order_created","event_id":"000659d4-cba7-b340-0000-000100000020","pre_event_id":"000659d4-cba7-8848-0000-000103000020","order_source":"orderbook"}
{"data":{"id":2043024870576128,"id_str":"2043024870576128","order_type":1,"order_subtype":5,"datetime":"1787620345","microtimestamp":"1787620344970000","amount":0.13,"amount_str":"0.13000000","amount_traded":"0","amount_at_create":"0.13000000","price":79672.25,"price_str":"79672.25","is_liquidation":false},"channel":"live_orders_btcusd","event":"order_deleted","event_id":"000659d4-cba7-bb10-0000-000101000020","pre_event_id":"000659d4-cba7-b340-0000-000100000020","order_source":"orderbook"}
{"data":{"id":2043024876863489,"id_str":"2043024876863489","order_type":0,"order_subtype":5,"datetime":"1787620345","microtimestamp":"1787620344985000","amount":0.25,"amount_str":"0.25000000","amount_traded":"0","amount_at_create":"0.25000000","price":79640.76,"price_str":"79640.76","is_liquidation":false},"channel":"live_orders_btcusd","event":"order_created","event_id":"000659d4-cba7-f5a8-0000-000102000020","pre_event_id":"000659d4-cba7-bb10-0000-000101000020","order_source":"orderbook"}
{"data":{"id":2043024876933120,"id_str":"2043024876933120","order_type":0,"order_subtype":5,"datetime":"1787620345","microtimestamp":"1787620345002000","amount":0.00143636,"amount_str":"0.00143636","amount_traded":"0","amount_at_create":"0.00143636","price":71676.81,"price_str":"71676.81","is_liquidation":false},"channel":"live_orders_btcusd","event":"order_created","event_id":"000659d4-cba8-3810-0000-000103000020","pre_event_id":"000659d4-cba7-f5a8-0000-000102000020","order_source":"orderbook"}
{"data":{"id":2043024874627073,"id_str":"2043024874627073","order_type":0,"order_subtype":5,"datetime":"1787620345","microtimestamp":"1787620345014000","amount":0.00143636,"amount_str":"0.00143636","amount_traded":"0","amount_at_create":"0.00143636","price":71676.81,"price_str":"71676.81","is_liquidation":false},"channel":"live_orders_btcusd","event":"order_deleted","event_id":"000659d4-cba8-66f0-0000-000100000020","pre_event_id":"000659d4-cba8-3810-0000-000103000020","order_source":"orderbook"}
{"data":{"id":2043024876265475,"id_str":"2043024876265475","order_type":0,"order_subtype":5,"datetime":"1787620345","microtimestamp":"1787620345014000","amount":0.00143636,"amount_str":"0.00143636","amount_traded":"0","amount_at_create":"0.00143636","price":71676.81,"price_str":"71676.81","is_liquidation":false},"channel":"live_orders_btcusd","event":"order_deleted","event_id":"000659d4-cba8-66f0-0001-000101000020","pre_event_id":"000659d4-cba8-66f0-0000-000100000020","order_source":"orderbook"}
{"data":{"id":2043024876584967,"id_str":"2043024876584967","order_type":0,"order_subtype":5,"datetime":"1787620345","microtimestamp":"1787620345024000","amount":0.06279536,"amount_str":"0.06279536","amount_traded":"0","amount_at_create":"0.06279536","price":79623.71,"price_str":"79623.71","is_liquidation":false},"channel":"live_orders_btcusd","event":"order_deleted","event_id":"000659d4-cba8-8e00-0000-000102000020","pre_event_id":"000659d4-cba8-66f0-0001-000101000020","order_source":"orderbook"}
{"data":{"id":2043024876707842,"id_str":"2043024876707842","order_type":0,"order_subtype":0,"datetime":"1787620345","microtimestamp":"1787620345039000","amount":0.00049029,"amount_str":"0.00049029","amount_traded":"0","amount_at_create":"0.00049029","price":78775.17,"price_str":"78775.17","is_liquidation":false},"channel":"live_orders_btcusd","event":"order_deleted","event_id":"000659d4-cba8-c898-0000-000103000020","pre_event_id":"000659d4-cba8-8e00-0000-000102000020","order_source":"orderbook"}
{"data":{"id":2043024877088768,"id_str":"2043024877088768","order_type":0,"order_subtype":5,"datetime":"1787620345","microtimestamp":"1787620345040000","amount":0.06278884,"amount_str":"0.06278884","amount_traded":"0","amount_at_create":"0.06278884","price":79631.98,"price_str":"79631.98","is_liquidation":false},"channel":"live_orders_btcusd","event":"order_created","event_id":"000659d4-cba8-cc80-0000-000100000020","pre_event_id":"000659d4-cba8-c898-0000-000103000020","order_source":"orderbook"}
{"data":{"id":2043024875765766,"id_str":"2043024875765766","order_type":1,"order_subtype":5,"datetime":"1787620345","microtimestamp":"1787620345068000","amount":0.02456085,"amount_str":"0.02456085","amount_traded":"0","amount_at_create":"0.02456085","price":79658,"price_str":"79658.00","is_liquidation":false},"channel":"live_orders_btcusd","event":"order_deleted","event_id":"000659d4-cba9-39e0-0000-000101000020","pre_event_id":"000659d4-cba8-cc80-0000-000100000020","order_source":"orderbook"}
{"data":{"id":2043024877240320,"id_str":"2043024877240320","order_type":1,"order_subtype":5,"datetime":"1787620345","microtimestamp":"1787620345077000","amount":0.02456085,"amount_str":"0.02456085","amount_traded":"0","amount_at_create":"0.02456085","price":79658.3,"price_str":"79658.30","is_liquidation":false},"channel":"live_orders_btcusd","event":"order_created","event_id":"000659d4-cba9-5d08-0000-000102000020","pre_event_id":"000659d4-cba9-39e0-0000-000101000020","order_source":"orderbook"}
{"data":{"id":2043024877256707,"id_str":"2043024877256707","order_type":0,"order_subtype":5,"datetime":"1787620345","microtimestamp":"1787620345081000","amount":0.13,"amount_str":"0.13000000","amount_traded":"0","amount_at_create":"0.13000000","price":79633.41,"price_str":"79633.41","is_liquidation":false},"channel":"live_orders_btcusd","event":"order_created","event_id":"000659d4-cba9-6ca8-0000-000103000020","pre_event_id":"000659d4-cba9-5d08-0000-000102000020","order_source":"orderbook"}
{"data":{"id":2043024877256706,"id_str":"2043024877256706","order_type":0,"order_subtype":5,"datetime":"1787620345","microtimestamp":"1787620345081000","amount":0.00143636,"amount_str":"0.00143636","amount_traded":"0","amount_at_create":"0.00143636","price":71676.81,"price_str":"71676.81","is_liquidation":false},"channel":"live_orders_btcusd","event":"order_created","event_id":"000659d4-cba9-6ca8-0001-000100000020","pre_event_id":"000659d4-cba9-6ca8-0000-000103000020","order_source":"orderbook"}
{"data":{"id":2043024876601346,"id_str":"2043024876601346","order_type":0,"order_subtype":5,"datetime":"1787620345","microtimestamp":"1787620345094000","amount":0.00143636,"amount_str":"0.00143636","amount_traded":"0","amount_at_create":"0.00143636","price":71676.81,"price_str":"71676.81","is_liquidation":false},"channel":"live_orders_btcusd","event":"order_deleted","event_id":"000659d4-cba9-9f70-0000-000101000020","pre_event_id":"000659d4-cba9-6ca8-0001-000100000020","order_source":"orderbook"}
{"data":{"id":2043024876740615,"id_str":"2043024876740615","order_type":0,"order_subtype":5,"datetime":"1787620345","microtimestamp":"1787620345100000","amount":0.5,"amount_str":"0.50000000","amount_traded":"0","amount_at_create":"0.50000000","price":79636.78,"price_str":"79636.78","is_liquidation":false},"channel":"live_orders_btcusd","event":"order_deleted","event_id":"000659d4-cba9-b6e0-0000-000102000020","pre_event_id":"000659d4-cba9-9f70-0000-000101000020","order_source":"orderbook"}
{"data":{"id":2043024877457408,"id_str":"2043024877457408","order_type":1,"order_subtype":4,"datetime":"1787620345","microtimestamp":"1787620345131000","amount":6.157e-05,"amount_str":"0.00006157","amount_traded":"0","amount_at_create":"0.00006157","price":82030,"price_str":"82030.00","is_liquidation":false},"channel":"live_orders_btcusd","event":"order_created","event_id":"000659d4-cbaa-2ff8-0000-000103000020","pre_event_id":"000659d4-cba9-b6e0-0000-000102000020","order_source":"orderbook"}
{"data":{"id":2043024877457408,"id_str":"2043024877457408","order_type":1,"order_subtype":4,"datetime":"1787620345","microtimestamp":"1787620345131000","amount":6.157e-05,"amount_str":"0.00006157","amount_traded":"0","amount_at_create":"0.00006157","price":82030,"price_str":"82030.00","is_liquidation":false},"channel":"live_orders_btcusd","event":"order_deleted","event_id":"000659d4-cbaa-2ff8-0001-000100000020","pre_event_id":"000659d4-cbaa-2ff8-0000-000103000020","order_source":"orderbook"}
{"data":{"id":2043024877465602,"id_str":"2043024877465602","order_type":1,"order_subtype":5,"datetime":"1787620345","microtimestamp":"1787620345132000","amount":0.13,"amount_str":"0.13000000","amount_traded":"0","amount_at_create":"0.13000000","price":79668.79,"price_str":"79668.79","is_liquidation":false},"channel":"live_orders_btcusd","event":"order_created","event_id":"000659d4-cbaa-33e0-0000-000101000020","pre_event_id":"000659d4-cbaa-2ff8-0001-000100000020","order_source":"orderbook"}
{"data":{"id":2043024877465603,"id_str":"2043024877465603","order_type":0,"order_subtype":5,"datetime":"1787620345","microtimestamp":"1787620345133000","amount":0.5,"amount_str":"0.50000000","amount_traded":"0","amount_at_create":"0.50000000","price":79636.77,"price_str":"79636.77","is_liquidation":false},"channel":"live_orders_btcusd","event":"order_created","event_id":"000659d4-cbaa-37c8-0000-000102000020","pre_event_id":"000659d4-cbaa-33e0-0000-000101000020","order_source":"orderbook"}
{"data":{"id":2043024876863489,"id_str":"2043024876863489","order_type":0,"order_subtype":5,"datetime":"1787620345","microtimestamp":"1787620345133000","amount":0.25,"amount_str":"0.25000000","amount_traded":"0","amount_at_create":"0.25000000","price":79640.76,"price_str":"79640.76","is_liquidation":false},"channel":"live_orders_btcusd","event":"order_deleted","event_id":"000659d4-cbaa-37c8-0001-000103000020","pre_event_id":"000659d4-cbaa-37c8-0000-000102000020","order_source":"orderbook"}
{"data":{"id":2043024877486080,"id_str":"2043024877486080","order_type":0,"order_subtype":0,"datetime":"1787620345","microtimestamp":"1787620345138000","amount":0.00049029,"amount_str":"0.00049029","amount_traded":"0","amount_at_create":"0.00049029","price":78775.17,"price_str":"78775.17","is_liquidation":false},"channel":"live_orders_btcusd","event":"order_created","event_id":"000659d4-cbaa-4b50-0000-000100000020","pre_event_id":"000659d4-cbaa-37c8-0001-000103000020","order_source":"orderbook"}
{"data":{"id":2043024877256707,"id_str":"2043024877256707","order_type":0,"order_subtype":5,"datetime":"1787620345","microtimestamp":"1787620345141000","amount":0.13,"amount_str":"0.13000000","amount_traded":"0","amount_at_create":"0.13000000","price":79633.41,"price_str":"79633.41","is_liquidation":false},"channel":"live_orders_btcusd","event":"order_deleted","event_id":"000659d4-cbaa-5708-0000-000101000020","pre_event_id":"000659d4-cbaa-4b50-0000-000100000020","order_source":"orderbook"}
{"data":{"id":2043024877580290,"id_str":"2043024877580290","order_type":0,"order_subtype":5,"datetime":"1787620345","microtimestamp":"1787620345160000","amount":0.00143636,"amount_str":"0.00143636","amount_traded":"0","amount_at_create":"0.00143636","price":71676.81,"price_str":"71676.81","is_liquidation":false},"channel":"live_orders_btcusd","event":"order_created","event_id":"000659d4-cbaa-a140-0000-000102000020","pre_event_id":"000659d4-cbaa-5708-0000-000101000020","order_source":"orderbook"}
{"data":{"id":2043024877588481,"id_str":"2043024877588481","order_type":0,"order_subtype":5,"datetime":"1787620345","microtimestamp":"1787620345163000","amount":0.25,"amount_str":"0.25000000","amount_traded":"0","amount_at_create":"0.25000000","price":79640.75,"price_str":"79640.75","is_liquidation":false},"channel":"live_orders_btcusd","event":"order_created","event_id":"000659d4-cbaa-acf8-0000-000103000020","pre_event_id":"000659d4-cbaa-a140-0000-000102000020","order_source":"orderbook"}
{"data":{"id":2043024876933120,"id_str":"2043024876933120","order_type":0,"order_subtype":5,"datetime":"1787620345","microtimestamp":"1787620345174000","amount":0.00143636,"amount_str":"0.00143636","amount_traded":"0","amount_at_create":"0.00143636","price":71676.81,"price_str":"71676.81","is_liquidation":false},"channel":"live_orders_btcusd","event":"order_deleted","event_id":"000659d4-cbaa-d7f0-0000-000100000020","pre_event_id":"000659d4-cbaa-acf8-0000-000103000020","order_source":"orderbook"}
{"data":{"id":2043024875773954,"id_str":"2043024875773954","order_type":1,"order_subtype":5,"datetime":"1787620345","microtimestamp":"1787620345175000","amount":0.08186951,"amount_str":"0.08186951","amount_traded":"0","amount_at_create":"0.08186951","price":79660,"price_str":"79660.00","is_liquidation":false},"channel":"live_orders_btcusd","event":"order_deleted","event_id":"000659d4-cbaa-dbd8-0000-000101000020","pre_event_id":"000659d4-cbaa-d7f0-0000-000100000020","order_source":"orderbook"}
{"data":{"id":2043024872943618,"id_str":"2043024872943618","order_type":0,"order_subtype":5,"datetime":"1787620345","microtimestamp":"1787620345185000","amount":0.26349748,"amount_str":"0.26349748","amount_traded":"0","amount_at_create":"0.26349748","price":79634.86,"price_str":"79634.86","is_liquidation":false},"channel":"live_orders_btcusd","event":"order_deleted","event_id":"000659d4-cbab-02e8-0000-000102000020","pre_event_id":"000659d4-cbaa-dbd8-0000-000101000020","order_source":"orderbook"}
{"data":{"id":2043024857731075,"id_str":"2043024857731075","order_type":1,"order_subtype":0,"datetime":"1787620345","microtimestamp":"1787620345193000","amount":0.02222515,"amount_str":"0.02222515","amount_traded":"0","amount_at_create":"0.02222515","price":79699.73,"price_str":"79699.73","is_liquidation":false},"channel":"live_orders_btcusd","event":"order_deleted","event_id":"000659d4-cbab-2228-0000-000103000020","pre_event_id":"000659d4-cbab-02e8-0000-000102000020","order_source":"orderbook"}
{"data":{"id":2043024857751556,"id_str":"2043024857751556","order_type":0,"order_subtype":0,"datetime":"1787620345","microtimestamp":"1787620345194000","amount":0.024359,"amount_str":"0.02435900","amount_traded":"0","amount_at_create":"0.02435900","price":79604.13,"price_str":"79604.13","is_liquidation":false},"channel":"live_orders_btcusd","event":"order_deleted","event_id":"000659d4-cbab-2610-0000-000100000020","pre_event_id":"000659d4-cbab-2228-0000-000103000020","order_source":"orderbook"}
{"data":{"id":2043024860246018,"id_str":"2043024860246018","order_type":0,"order_subtype":5,"datetime":"1787620345","microtimestamp":"1787620345198000","amount":0.0255447,"amount_str":"0.02554470","amount_traded":"0","amount_at_create":"0.02554470","price":79564.84,"price_str":"79564.84","is_liquidation":false},"channel":"live_orders_btcusd","event":"order_deleted","event_id":"000659d4-cbab-35b0-0000-000101000020","pre_event_id":"000659d4-cbab-2610-0000-000100000020","order_source":"orderbook"}
{"data":{"id":2043024870653953,"id_str":"2043024870653953","order_type":1,"order_subtype":5,"datetime":"1787620345","microtimestamp":"1787620345199000","amount":0.01255617,"amount_str":"0.01255617","amount_traded":"0","amount_at_create":"0.01255617","price":79651.08,"price_str":"79651.08","is_liquidation":false},"channel":"live_orders_btcusd","event":"order_deleted","event_id":"000659d4-cbab-3998-0000-000102000020","pre_event_id":"000659d4-cbab-35b0-0000-000101000020","order_source":"orderbook"}
{"data":{"id":2043024870313984,"id_str":"2043024870313984","order_type":1,"order_subtype":5,"datetime":"1787620345","microtimestamp":"1787620345199000","amount":0.01255617,"amount_str":"0.01255617","amount_traded":"0","amount_at_create":"0.01255617","price":79649.5,"price_str":"79649.50","is_liquidation":false},"channel":"live_orders_btcusd","event":"order_deleted","event_id":"000659d4-cbab-3998-0001-000103000020","pre_event_id":"000659d4-cbab-3998-0000-000102000020","order_source":"orderbook"}
{"data":{"id":2043024877748225,"id_str":"2043024877748225","order_type":0,"order_subtype":0,"datetime":"1787620345","microtimestamp":"1787620345201000","amount":0.024359,"amount_str":"0.02435900","amount_traded":"0","amount_at_create":"0.02435900","price":79586.35,"price_str":"79586.35","is_liquidation":false},"channel":"live_orders_btcusd","event":"order_created","event_id":"000659d4-cbab-4168-0000-000100000020","pre_event_id":"000659d4-cbab-3998-0001-000103000020","order_source":"orderbook"}
{"data":{"id":2043024877752321,"id_str":"2043024877752321","order_type":1,"order_subtype":0,"datetime":"1787620345","microtimestamp":"1787620345203000","amount":0.02222515,"amount_str":"0.02222515","amount_traded":"0","amount_at_create":"0.02222515","price":79681.93,"price_str":"79681.93","is_liquidation":false},"channel":"live_orders_btcusd","event":"order_created","event_id":"000659d4-cbab-4938-0000-000101000020","pre_event_id":"000659d4-cbab-4168-0000-000100000020","order_source":"orderbook"}
{"data":{"id":2043024862638087,"id_str":"2043024862638087","order_type":0,"order_subtype":0,"datetime":"1787620345","microtimestamp":"1787620345207000","amount":0.06275933,"amount_str":"0.06275933","amount_traded":"0","amount_at_create":"0.06275933","price":79622.87,"price_str":"79622.87","is_liquidation":false},"channel":"live_orders_btcusd","event":"order_deleted","event_id":"000659d4-cbab-58d8-0000-000102000020","pre_event_id":"000659d4-cbab-4938-0000-000101000020","order_source":"orderbook"}
{"data":{"id":2043024862986242,"id_str":"2043024862986242","order_type":0,"order_subtype":5,"datetime":"1787620345","microtimestamp":"1787620345208000","amount":0.48956031,"amount_str":"0.48956031","amount_traded":"0","amount_at_create":"0.48956031","price":79634.85,"price_str":"79634.85","is_liquidation":false},"channel":"live_orders_btcusd","event":"order_deleted","event_id":"000659d4-cbab-5cc0-0000-000103000020","pre_event_id":"000659d4-cbab-58d8-0000-000102000020","order_source":"orderbook"}
{"data":{"id":2043024862875652,"id_str":"2043024862875652","order_type":1,"order_subtype":5,"datetime":"1787620345","microtimestamp":"1787620345208000","amount":0.1,"amount_str":"0.10000000","amount_traded":"0","amount_at_create":"0.10000000","price":79647.54,"price_str":"79647.54","is_liquidation":false},"channel":"live_orders_btcusd","event":"order_deleted","event_id":"000659d4-cbab-5cc0-0001-000100000020","pre_event_id":"000659d4-cbab-5cc0-0000-000103000020","order_source":"orderbook"}
{"data":{"id":2043024877088768,"id_str":"2043024877088768","order_type":0,"order_subtype":5,"datetime":"1787620345","microtimestamp":"1787620345209000","amount":0.06278884,"amount_str":"0.06278884","amount_traded":"0","amount_at_create":"0.06278884","price":79631.98,"price_str":"79631.98","is_liquidation":false},"channel":"live_orders_btcusd","event":"order_deleted","event_id":"000659d4-cbab-60a8-0000-000101000020","pre_event_id":"000659d4-cbab-5cc0-0001-000100000020","order_source":"orderbook"}
{"data":{"id":2043024863662085,"id_str":"2043024863662085","order_type":0,"order_subtype":5,"datetime":"1787620345","microtimestamp":"1787620345210000","amount":0.19,"amount_str":"0.19000000","amount_traded":"0","amount_at_create":"0.19000000","price":79640.9,"price_str":"79640.90","is_liquidation":false},"channel":"live_orders_btcusd","event":"order_deleted","event_id":"000659d4-cbab-6490-0000-000102000020","pre_event_id":"000659d4-cbab-60a8-0000-000101000020","order_source":"orderbook"}
{"data":{"id":2043024877588481,"id_str":"2043024877588481","order_type":0,"order_subtype":5,"datetime":"1787620345","microtimestamp":"1787620345210000","amount":0.25,"amount_str":"0.25000000","amount_traded":"0","amount_at_create":"0.25000000","price":79640.75,"price_str":"79640.75","is_liquidation":false},"channel":"live_orders_btcusd","event":"order_deleted","event_id":"000659d4-cbab-6490-0001-000103000020","pre_event_id":"000659d4-cbab-6490-0000-000102000020","order_source":"orderbook"}
{"data":{"id":2043024866664451,"id_str":"2043024866664451","order_type":0,"order_subtype":5,"datetime":"1787620345","microtimestamp":"1787620345210000","amount":0.0255447,"amount_str":"0.02554470","amount_traded":"0","amount_at_create":"0.02554470","price":79563.78,"price_str":"79563.78","is_liquidation":false},"channel":"live_orders_btcusd","event":"order_deleted","event_id":"000659d4-cbab-6490-0002-000100000020","pre_event_id":"000659d4-cbab-6490-0001-000103000020","order_source":"orderbook"}
{"data":{"id":2043024863047683,"id_str":"2043024863047683","order_type":1,"order_subtype":5,"datetime":"1787620345","microtimestamp":"1787620345210000","amount":0.1,"amount_str":"0.10000000","amount_traded":"0","amount_at_create":"0.10000000","price":79647.5,"price_str":"79647.50","is_liquidation":false},"channel":"live_orders_btcusd","event":"order_deleted","event_id":"000659d4-cbab-6490-0003-000101000020","pre_event_id":"000659d4-cbab-6490-0002-000100000020","order_source":"orderbook"}
{"data":{"id":2043024861229072,"id_str":"2043024861229072","order_type":0,"order_subtype":5,"datetime":"1787620345","microtimestamp":"1787620345211000","amount":0.25544707,"amount_str":"0.25544707","amount_traded":"0","amount_at_create":"0.25544707","price":79520.42,"price_str":"79520.42","is_liquidation":false},"channel":"live_orders_btcusd","event":"order_deleted","event_id":"000659d4-cbab-6878-0000-000102000020","pre_event_id":"000659d4-cbab-6490-0003-000101000020","order_source":"orderbook"}
{"data":{"id":2043024867971084,"id_str":"2043024867971084","order_type":1,"order_subtype":5,"datetime":"1787620345","microtimestamp":"1787620345211000","amount":0.25106799,"amount_str":"0.25106799","amount_traded":"0","amount_at_create":"0.25106799","price":79659.7,"price_str":"79659.70","is_liquidation":false},"channel":"live_orders_btcusd","event":"order_deleted","event_id":"000659d4-cbab-6878-0001-000103000020","pre_event_id":"000659d4-cbab-6878-0000-000102000020","order_source":"orderbook"}
{"data":{"id":2043024877465603,"id_str":"2043024877465603","order_type":0,"order_subtype":5,"datetime":"1787620345","microtimestamp":"1787620345211000","amount":0.5,"amount_str":"0.50000000","amount_traded":"0","amount_at_create":"0.50000000","price":79636.77,"price_str":"79636.77","is_liquidation":false},"channel":"live_orders_btcusd","event":"order_deleted","event_id":"000659d4-cbab-6878-0002-000100000020","pre_event_id":"000659d4-cbab-6878-0001-000103000020","order_source":"orderbook"}
{"data":{"id":2043024870514688,"id_str":"2043024870514688","order_type":1,"order_subtype":5,"datetime":"1787620345","microtimestamp":"1787620345211000","amount":0.5,"amount_str":"0.50000000","amount_traded":"0","amount_at_create":"0.50000000","price":79644.84,"price_str":"79644.84","is_liquidation":false},"channel":"live_orders_btcusd","event":"order_deleted","event_id":"000659d4-cbab-6878-0003-000101000020","pre_event_id":"000659d4-cbab-6878-0002-000100000020","order_source":"orderbook"}
{"data":{"id":2043024862990341,"id_str":"2043024862990341","order_type":0,"order_subtype":5,"datetime":"1787620345","microtimestamp":"1787620345211000","amount":0.48956031,"amount_str":"0.48956031","amount_traded":"0","amount_at_create":"0.48956031","price":79628.27,"price_str":"79628.27","is_liquidation":false},"channel":"live_orders_btcusd","event":"order_deleted","event_id":"000659d4-cbab-6878-0004-000102000020","pre_event_id":"000659d4-cbab-6878-0003-000101000020","order_source":"orderbook"}
{"data":{"id":2043024877789233,"id_str":"2043024877789233","order_type":0,"order_subtype":5,"datetime":"1787620345","microtimestamp":"1787620345212000","amount":0.0255447,"amount_str":"0.02554470","amount_traded":"0","amount_at_create":"0.02554470","price":79551.17,"price_str":"79551.17","is_liquidation":false},"channel":"live_orders_btcusd","event":"order_created","event_id":"000659d4-cbab-6c60-0000-000103000020","pre_event_id":"000659d4-cbab-6878-0004-000102000020","order_source":"orderbook"}
{"data":{"id":2043024862588930,"id_str":"2043024862588930","order_type":0,"order_subtype":0,"datetime":"1787620345","microtimestamp":"1787620345213000","amount":0.06275933,"amount_str":"0.06275933","amount_traded":"0","amount_at_create":"0.06275933","price":79620.48,"price_str":"79620.48","is_liquidation":false},"channel":"live_orders_btcusd","event":"order_deleted","event_id":"000659d4-cbab-7048-0000-000100000020","pre_event_id":"000659d4-cbab-6c60-0000-000103000020","order_source":"orderbook"}
{"data":{"id":2043024876015616,"id_str":"2043024876015616","order_type":0,"order_subtype":5,"datetime":"1787620345","microtimestamp":"1787620345215000","amount":0.18835267,"amount_str":"0.18835267","amount_traded":"0","amount_at_create":"0.18835267","price":79622.58,"price_str":"79622.58","is_liquidation":false},"channel":"live_orders_btcusd","event":"order_deleted","event_id":"000659d4-cbab-7818-0000-000101000020","pre_event_id":"000659d4-cbab-7048-0000-000100000020","order_source":"orderbook"}
{"data":{"id":2043024875388929,"id_str":"2043024875388929","order_type":0,"order_subtype":5,"datetime":"1787620345","microtimestamp":"1787620345215000","amount":0.06279199,"amount_str":"0.06279199","amount_traded":"0","amount_at_create":"0.06279199","price":79627.98,"price_str":"79627.98","is_liquidation":false},"channel":"live_orders_btcusd","event":"order_deleted","event_id":"000659d4-cbab-7818-0001-000102000020","pre_event_id":"000659d4-cbab-7818-0000-000101000020","order_source":"orderbook"}
{"data":{"id":2043024876228616,"id_str":"2043024876228616","order_type":0,"order_subtype":5,"datetime":"1787620345","microtimestamp":"1787620345216000","amount":0.62784324,"amount_str":"0.62784324","amount_traded":"0","amount_at_create":"0.62784324","price":79620.64,"price_str":"79620.64","is_liquidation":false},"channel":"live_orders_btcusd","event":"order_deleted","event_id":"000659d4-cbab-7c00-0000-000103000020","pre_event_id":"000659d4-cbab-7818-0001-000102000020","order_source":"orderbook"}
{"data":{"id":2043024861954050,"id_str":"2043024861954050","order_type":0,"order_subtype":5,"datetime":"1787620345","microtimestamp":"1787620345216000","amount":0.03958976,"amount_str":"0.03958976","amount_traded":"0","amount_at_create":"0.03958976","price":79601.31,"price_str":"79601.31","is_liquidation":false},"channel":"live_orders_btcusd","event":"order_deleted","event_id":"000659d4-cbab-7c00-0001-000100000020","pre_event_id":"000659d4-cbab-7c00-0000-000103000020","order_source":"orderbook"}
{"data":{"id":2043024845389832,"id_str":"2043024845389832","order_type":0,"order_subtype":0,"datetime":"1787620345","microtimestamp":"1787620345216000","amount":0.06275933,"amount_str":"0.06275933","amount_traded":"0","amount_at_create":"0.06275933","price":79615.68,"price_str":"79615.68","is_liquidation":false},"channel":"live_orders_btcusd","event":"order_deleted","event_id":"000659d4-cbab-7c00-0002-000101000020","pre_event_id":"000659d4-cbab-7c00-0001-000100000020","order_source":"orderbook"}
{"data":{"id":2043024875319300,"id_str":"2043024875319300","order_type":0,"order_subtype":5,"datetime":"1787620345","microtimestamp":"1787620345216000","amount":0.25119676,"amount_str":"0.25119676","amount_traded":"0","amount_at_create":"0.25119676","price":79618.85,"price_str":"79618.85","is_liquidation":false},"channel":"live_orders_btcusd","event":"order_deleted","event_id":"000659d4-cbab-7c00-0003-000102000020","pre_event_id":"000659d4-cbab-7c00-0002-000101000020","order_source":"orderbook"}
{"data":{"id":2043024876421120,"id_str":"2043024876421120","order_type":0,"order_subtype":5,"datetime":"1787620345","microtimestamp":"1787620345220000","amount":0.50227536,"amount_str":"0.50227536","amount_traded":"0","amount_at_create":"0.50227536","price":79618.69,"price_str":"79618.69","is_liquidation":false},"channel":"live_orders_btcusd","event":"order_deleted","event_id":"000659d4-cbab-8ba0-0000-000103000020","pre_event_id":"000659d4-cbab-7c00-0003-000102000020","order_source":"orderbook"}
{"data":{"id":2043024845455382,"id_str":"2043024845455382","order_type":0,"order_subtype":0,"datetime":"1787620345","microtimestamp":"1787620345220000","amount":0.06275933,"amount_str":"0.06275933","amount_traded":"0","amount_at_create":"0.06275933","price":79610.89,"price_str":"79610.89","is_liquidation":false},"channel":"live_orders_btcusd","event":"order_deleted","event_id":"000659d4-cbab-8ba0-0001-000100000020","pre_event_id":"000659d4-cbab-8ba0-0000-000103000020","order_source":"orderbook"}
{"data":{"id":2043024877240320,"id_str":"2043024877240320","order_type":1,"order_subtype":5,"datetime":"1787620345","microtimestamp":"1787620345220000","amount":0.02456085,"amount_str":"0.02456085","amount_traded":"0","amount_at_create":"0.02456085","price":79658.3,"price_str":"79658.30","is_liquidation":false},"channel":"live_orders_btcusd","event":"order_deleted","event_id":"000659d4-cbab-8ba0-0002-000101000020","pre_event_id":"000659d4-cbab-8ba0-0001-000100000020","order_source":"orderbook"}
{"data":{"id":2043024850120709,"id_str":"2043024850120709","order_type":0,"order_subtype":0,"datetime":"1787620345","microtimestamp":"1787620345221000","amount":0.06275933,"amount_str":"0.06275933","amount_traded":"0","amount_at_create":"0.06275933","price":79606.11,"price_str":"79606.11","is_liquidation":false},"channel":"live_orders_btcusd","event":"order_deleted","event_id":"000659d4-cbab-8f88-0000-000102000020","pre_event_id":"000659d4-cbab-8ba0-0002-000101000020","order_source":"orderbook"}
{"data":{"id":2043024877813771,"id_str":"2043024877813771","order_type":1,"order_subtype":5,"datetime":"1787620345","microtimestamp":"1787620345221000","amount":0.1,"amount_str":"0.10000000","amount_traded":"0","amount_at_create":"0.10000000","price":79643.71,"price_str":"79643.71","is_liquidation":false},"channel":"live_orders_btcusd","event":"order_created","event_id":"000659d4-cbab-8f88-0001-000103000020","pre_event_id":"000659d4-cbab-8f88-0000-000102000020","order_source":"orderbook"}
{"data":{"id":2043024877817870,"id_str":"2043024877817870","order_type":1,"order_subtype":5,"datetime":"1787620345","microtimestamp":"1787620345221000","amount":0.1,"amount_str":"0.10000000","amount_traded":"0","amount_at_create":"0.10000000","price":79640.89,"price_str":"79640.89","is_liquidation":false},"channel":"live_orders_btcusd","event":"order_created","event_id":"000659d4-cbab-8f88-0002-000100000020","pre_event_id":"000659d4-cbab-8f88-0001-000103000020","order_source":"orderbook"}
{"data":{"id":2043024877817872,"id_str":"2043024877817872","order_type":1,"order_subtype":5,"datetime":"1787620345","microtimestamp":"1787620345222000","amount":0.1,"amount_str":"0.10000000","amount_traded":"0","amount_at_create":"0.10000000","price":79640.9,"price_str":"79640.90","is_liquidation":false},"channel":"live_orders_btcusd","event":"order_created","event_id":"000659d4-cbab-9370-0000-000101000020","pre_event_id":"000659d4-cbab-8f88-0002-000100000020","order_source":"orderbook"}
{"data":{"id":2043024877789233,"id_str":"2043024877789233","order_type":0,"order_subtype":5,"datetime":"1787620345","microtimestamp":"1787620345222000","amount":0.0255447,"amount_str":"0.02554470","amount_traded":"0","amount_at_create":"0.02554470","price":79551.17,"price_str":"79551.17","is_liquidation":false},"channel":"live_orders_btcusd","event":"order_deleted","event_id":"000659d4-cbab-9370-0001-000102000020","pre_event_id":"000659d4-cbab-9370-0000-000101000020","order_source":"orderbook"}
{"data":{"id":2043024858644507,"id_str":"2043024858644507","order_type":0,"order_subtype":5,"datetime":"1787620345","microtimestamp":"1787620345222000","amount":0.024359,"amount_str":"0.02435900","amount_traded":"0","amount_at_create":"0.02435900","price":79587.93,"price_str":"79587.93","is_liquidation":false},"channel":"live_orders_btcusd","event":"order_deleted","event_id":"000659d4-cbab-9370-0002-000103000020","pre_event_id":"000659d4-cbab-9370-0001-000102000020","order_source":"orderbook"}
{"data":{"id":2043024875765760,"id_str":"2043024875765760","order_type":1,"order_subtype":5,"datetime":"1787620345","microtimestamp":"1787620345222000","amount":0.06549561,"amount_str":"0.06549561","amount_traded":"0","amount_at_create":"0.06549561","price":79661.99,"price_str":"79661.99","is_liquidation":false},"channel":"live_orders_btcusd","event":"order_deleted","event_id":"000659d4-cbab-9370-0003-000100000020","pre_event_id":"000659d4-cbab-9370-0002-000103000020","order_source":"orderbook"}
{"data":{"id":2043024845410353,"id_str":"2043024845410353","order_type":1,"order_subtype":5,"datetime":"1787620345","microtimestamp":"1787620345223000","amount":12.52128758,"amount_str":"12.52128758","amount_traded":"0","amount_at_create":"12.52128758","price":79864,"price_str":"79864.00","is_liquidation":false},"channel":"live_orders_btcusd","event":"order_deleted","event_id":"000659d4-cbab-9758-0000-000101000020","pre_event_id":"000659d4-cbab-9370-0003-000100000020","order_source":"orderbook"}
{"data":{"id":2043024678535254,"id_str":"2043024678535254","order_type":0,"order_subtype":5,"datetime":"1787620345","microtimestamp":"1787620345223000","amount":0.0646,"amount_str":"0.06460000","amount_traded":"0","amount_at_create":"0.06460000","price":79595.04,"price_str":"79595.04","is_liquidation":false},"channel":"live_orders_btcusd","event":"order_deleted","event_id":"000659d4-cbab-9758-0001-000102000020","pre_event_id":"000659d4-cbab-9758-0000-000101000020","order_source":"orderbook"}
{"data":{"id":2043024860614657,"id_str":"2043024860614657","order_type":1,"order_subtype":5,"datetime":"1787620345","microtimestamp":"1787620345225000","amount":0.48956031,"amount_str":"0.48956031","amount_traded":"0","amount_at_create":"0.48956031","price":79668.12,"price_str":"79668.12","is_liquidation":false},"channel":"live_orders_btcusd","event":"order_deleted","event_id":"000659d4-cbab-9f28-0000-000103000020","pre_event_id":"000659d4-cbab-9758-0001-000102000020","order_source":"orderbook"}
{"data":{"id":2043024858628098,"id_str":"2043024858628098","order_type":0,"order_subtype":5,"datetime":"1787620345","microtimestamp":"1787620345225000","amount":0.0255447,"amount_str":"0.02554470","amount_traded":"0","amount_at_create":"0.02554470","price":79550.7,"price_str":"79550.70","is_liquidation":false},"channel":"live_orders_btcusd","event":"order_deleted","event_id":"000659d4-cbab-9f28-0001-000100000020","pre_event_id":"000659d4-cbab-9f28-0000-000103000020","order_source":"orderbook"}
{"data":{"id":2043024860344322,"id_str":"2043024860344322","order_type":0,"order_subtype":5,"datetime":"1787620345","microtimestamp":"1787620345226000","amount":0.64019425,"amount_str":"0.64019425","amount_traded":"0","amount_at_create":"0.64019425","price":79521.78,"price_str":"79521.78","is_liquidation":false},"channel":"live_orders_btcusd","event":"order_deleted","event_id":"000659d4-cbab-a310-0000-000101000020","pre_event_id":"000659d4-cbab-9f28-0001-000100000020","order_source":"orderbook"}
{"data":{"id":2043024860123145,"id_str":"2043024860123145","order_type":1,"order_subtype":5,"datetime":"1787620345","microtimestamp":"1787620345226000","amount":0.64019425,"amount_str":"0.64019425","amount_traded":"0","amount_at_create":"0.64019425","price":79771.45,"price_str":"79771.45","is_liquidation":false},"channel":"live_orders_btcusd","event":"order_deleted","event_id":"000659d4-cbab-a310-0001-000102000020","pre_event_id":"000659d4-cbab-a310-0000-000101000020","order_source":"orderbook"}
{"data":{"id":2043024872828928,"id_str":"2043024872828928","order_type":0,"order_subtype":5,"datetime":"1787620345","microtimestamp":"1787620345226000","amount":1.2,"amount_str":"1.20000000","amount_traded":"0","amount_at_create":"1.20000000","price":79617,"price_str":"79617.00","is_liquidation":false},"channel":"live_orders_btcusd","event":"order_deleted","event_id":"000659d4-cbab-a310-0002-000103000020","pre_event_id":"000659d4-cbab-a310-0001-000102000020","order_source":"orderbook"}
{"data":{"id":2043024868196352,"id_str":"2043024868196352","order_type":1,"order_subtype":5,"datetime":"1787620345","microtimestamp":"1787620345227000","amount":0.06275933,"amount_str":"0.06275933","amount_traded":"0","amount_at_create":"0.06275933","price":79644.57,"price_str":"79644.57","is_liquidation":false},"channel":"live_orders_btcusd","event":"order_deleted","event_id":"000659d4-cbab-a6f8-0000-000100000020","pre_event_id":"000659d4-cbab-a310-0002-000103000020","order_source":"orderbook"}
{"data":{"id":2043024877846602,"id_str":"2043024877846602","order_type":1,"order_subtype":5,"datetime":"1787620345","microtimestamp":"1787620345227000","amount":0.01255663,"amount_str":"0.01255663","amount_traded":"0","amount_at_create":"0.01255663","price":79646.51,"price_str":"79646.51","is_liquidation":false},"channel":"live_orders_btcusd","event":"order_created","event_id":"000659d4-cbab-a6f8-0001-000101000020","pre_event_id":"000659d4-cbab-a6f8-0000-000100000020","order_source":"orderbook"}
{"data":{"id":2043024876216320,"id_str":"2043024876216320","order_type":1,"order_subtype":5,"datetime":"1787620345","microtimestamp":"1787620345229000","amount":0.81593385,"amount_str":"0.81593385","amount_traded":"0","amount_at_create":"0.81593385","price":79672.63,"price_str":"79672.63","is_liquidation":false},"channel":"live_orders_btcusd","event":"order_deleted","event_id":"000659d4-cbab-aec8-0000-000102000020","pre_event_id":"000659d4-cbab-a6f8-0001-000101000020","order_source":"orderbook"}
{"data":{"id":2043024850444288,"id_str":"2043024850444288","order_type":0,"order_subtype":5,"datetime":"1787620345","microtimestamp":"1787620345229000","amount":0.351387,"amount_str":"0.35138700","amount_traded":"0","amount_at_create":"0.35138700","price":79590.37,"price_str":"79590.37","is_liquidation":false},"channel":"live_orders_btcusd","event":"order_deleted","event_id":"000659d4-cbab-aec8-0001-000103000020","pre_event_id":"000659d4-cbab-aec8-0000-000102000020","order_source":"orderbook"}
{"data":{"id":2043024877854722,"id_str":"2043024877854722","order_type":0,"order_subtype":5,"datetime":"1787620345","microtimestamp":"1787620345229000","amount":0.18836695,"amount_str":"0.18836695","amount_traded":"0","amount_at_create":"0.18836695","price":79617.53,"price_str":"79617.53","is_liquidation":false},"channel":"live_orders_btcusd","event":"order_created","event_id":"000659d4-cbab-aec8-0002-000100000020","pre_event_id":"000659d4-cbab-aec8-0001-000103000020","order_source":"orderbook"}
{"data":{"id":2043024877854728,"id_str":"2043024877854728","order_type":0,"order_subtype":5,"datetime":"1787620345","microtimestamp":"1787620345231000","amount":0.0255447,"amount_str":"0.02554470","amount_traded":"0","amount_at_create":"0.02554470","price":79518.76,"price_str":"79518.76","is_liquidation":false},"channel":"live_orders_btcusd","event":"order_created","event_id":"000659d4-cbab-b698-0000-000101000020","pre_event_id":"000659d4-cbab-aec8-0002-000100000020","order_source":"orderbook"}
{"data":{"id":2043024877854813,"id_str":"2043024877854813","order_type":0,"order_subtype":5,"datetime":"1787620345","microtimestamp":"1787620345231000","amount":0.024359,"amount_str":"0.02435900","amount_traded":"0","amount_at_create":"0.02435900","price":79575.02,"price_str":"79575.02","is_liquidation":false},"channel":"live_orders_btcusd","event":"order_created","event_id":"000659d4-cbab-b698-0001-000102000020","pre_event_id":"000659d4-cbab-b698-0000-000101000020","order_source":"orderbook"}
{"data":{"id":2043024862814214,"id_str":"2043024862814214","order_type":1,"order_subtype":5,"datetime":"1787620345","microtimestamp":"1787620345231000","amount":0.1,"amount_str":"0.10000000","amount_traded":"0","amount_at_create":"0.10000000","price":79649.34,"price_str":"79649.34","is_liquidation":false},"channel":"live_orders_btcusd","event":"order_deleted","event_id":"000659d4-cbab-b698-0002-000103000020","pre_event_id":"000659d4-cbab-b698-0001-000102000020","order_source":"orderbook"}
{"data":{"id":2043024877858826,"id_str":"2043024877858826","order_type":0,"order_subtype":5,"datetime":"1787620345","microtimestamp":"1787620345232000","amount":0.48956031,"amount_str":"0.48956031","amount_traded":"0","amount_at_create":"0.48956031","price":79612.33,"price_str":"79612.33","is_liquidation":false},"channel":"live_orders_btcusd","event":"order_created","event_id":"000659d4-cbab-ba80-0000-000100000020","pre_event_id":"000659d4-cbab-b698-0002-000103000020","order_source":"orderbook"}
{"data":{"id":2043024877867021,"id_str":"2043024877867021","order_type":0,"order_subtype":5,"datetime":"1787620345","microtimestamp":"1787620345232000","amount":0.62788986,"amount_str":"0.62788986","amount_traded":"0","amount_at_create":"0.62788986","price":79615.54,"price_str":"79615.54","is_liquidation":false},"channel":"live_orders_btcusd","event":"order_created","event_id":"000659d4-cbab-ba80-0001-000101000020","pre_event_id":"000659d4-cbab-ba80-0000-000100000020","order_source":"orderbook"}
{"data":{"id":2043024877486080,"id_str":"2043024877486080","order_type":0,"order_subtype":0,"datetime":"1787620345","microtimestamp":"1787620345232000","amount":0.00049029,"amount_str":"0.00049029","amount_traded":"0","amount_at_create":"0.00049029","price":78775.17,"price_str":"78775.17","is_liquidation":false},"channel":"live_orders_btcusd","event":"order_deleted","event_id":"000659d4-cbab-ba80-0002-000102000020","pre_event_id":"000659d4-cbab-ba80-0001-000101000020","order_source":"orderbook"}
{"data":{"id":2043024877858888,"id_str":"2043024877858888","order_type":0,"order_subtype":5,"datetime":"1787620345","microtimestamp":"1787620345233000","amount":0.25544707,"amount_str":"0.25544707","amount_traded":"0","amount_at_create":"0.25544707","price":79320.64,"price_str":"79320.64","is_liquidation":false},"channel":"live_orders_btcusd","event":"order_created","event_id":"000659d4-cbab-be68-0000-000103000020","pre_event_id":"000659d4-cbab-ba80-0002-000102000020","order_source":"orderbook"}
{"data":{"id":2043024873934854,"id_str":"2043024873934854","order_type":0,"order_subtype":5,"datetime":"1787620345","microtimestamp":"1787620345233000","amount":0.00251258,"amount_str":"0.00251258","amount_traded":"0","amount_at_create":"0.00251258","price":79599.4,"price_str":"79599.40","is_liquidation":false},"channel":"live_orders_btcusd","event":"order_deleted","event_id":"000659d4-cbab-be68-0001-000100000020","pre_event_id":"000659d4-cbab-be68-0000-000103000020","order_source":"orderbook"}
{"data":{"id":2043024845807617,"id_str":"2043024845807617","order_type":0,"order_subtype":5,"datetime":"1787620345","microtimestamp":"1787620345233000","amount":0.009035,"amount_str":"0.00903500","amount_traded":"0","amount_at_create":"0.00903500","price":79562.28,"price_str":"79562.28","is_liquidation":false},"channel":"live_orders_btcusd","event":"order_deleted","event_id":"000659d4-cbab-be68-0002-000101000020","pre_event_id":"000659d4-cbab-be68-0001-000100000020","order_source":"orderbook"}
{"data":{"id":2043024872689678,"id_str":"2043024872689678","order_type":0,"order_subtype":5,"datetime":"1787620345","microtimestamp":"1787620345233000","amount":0.81593384,"amount_str":"0.81593384","amount_traded":"0","amount_at_create":"0.81593384","price":79537.35,"price_str":"79537.35","is_liquidation":false},"channel":"live_orders_btcusd","event":"order_deleted","event_id":"000659d4-cbab-be68-0003-000102000020","pre_event_id":"000659d4-cbab-be68-0002-000101000020","order_source":"orderbook"}
{"data":{"id":2043024877817872,"id_str":"2043024877817872","order_type":1,"order_subtype":5,"datetime":"1787620345","microtimestamp":"1787620345234000","amount":0.1,"amount_str":"0.10000000","amount_traded":"0","amount_at_create":"0.10000000","price":79640.9,"price_str":"79640.90","is_liquidation":false},"channel":"live_orders_btcusd","event":"order_deleted","event_id":"000659d4-cbab-c250-0000-000103000020","pre_event_id":"000659d4-cbab-be68-0003-000102000020","order_source":"orderbook"}
{"data":{"id":2043024877871123,"id_str":"2043024877871123","order_type":0,"order_subtype":5,"datetime":"1787620345","microtimestamp":"1787620345234000","amount":0.48956031,"amount_str":"0.48956031","amount_traded":"0","amount_at_create":"0.48956031","price":79604.36,"price_str":"79604.36","is_liquidation":false},"channel":"live_orders_btcusd","event":"order_created","event_id":"000659d4-cbab-c250-0001-000100000020","pre_event_id":"000659d4-cbab-c250-0000-000103000020","order_source":"orderbook"}
{"data":{"id":2043024877867029,"id_str":"2043024877867029","order_type":0,"order_subtype":5,"datetime":"1787620345","microtimestamp":"1787620345235000","amount":0.50231188,"amount_str":"0.50231188","amount_traded":"0","amount_at_create":"0.50231188","price":79613.55,"price_str":"79613.55","is_liquidation":false},"channel":"live_orders_btcusd","event":"order_created","event_id":"000659d4-cbab-c638-0000-000101000020","pre_event_id":"000659d4-cbab-c250-0001-000100000020","order_source":"orderbook"}
{"data":{"id":2043024872718342,"id_str":"2043024872718342","order_type":0,"order_subtype":5,"datetime":"1787620345","microtimestamp":"1787620345235000","amount":0.81593385,"amount_str":"0.81593385","amount_traded":"0","amount_at_create":"0.81593385","price":79595.98,"price_str":"79595.98","is_liquidation":false},"channel":"live_orders_btcusd","event":"order_deleted","event_id":"000659d4-cbab-c638-0001-000102000020","pre_event_id":"000659d4-cbab-c638-0000-000101000020","order_source":"orderbook"}
{"data":{"id":2043024870047750,"id_str":"2043024870047750","order_type":0,"order_subtype":5,"datetime":"1787620345","microtimestamp":"1787620345235000","amount":0.024359,"amount_str":"0.02435900","amount_traded":"0","amount_at_create":"0.02435900","price":79606.93,"price_str":"79606.93","is_liquidation":false},"channel":"live_orders_btcusd","event":"order_deleted","event_id":"000659d4-cbab-c638-0002-000103000020","pre_event_id":"000659d4-cbab-c638-0001-000102000020","order_source":"orderbook"}
{"data":{"id":2043024877871118,"id_str":"2043024877871118","order_type":0,"order_subtype":0,"datetime":"1787620345","microtimestamp":"1787620345235000","amount":0.06275933,"amount_str":"0.06275933","amount_traded":"0","amount_at_create":"0.06275933","price":79586.99,"price_str":"79586.99","is_liquidation":false},"channel":"live_orders_btcusd","event":"order_created","event_id":"000659d4-cbab-c638-0003-000100000020","pre_event_id":"000659d4-cbab-c638-0002-000103000020","order_source":"orderbook"}
{"data":{"id":2043024872701952,"id_str":"2043024872701952","order_type":1,"order_subtype":5,"datetime":"1787620345","microtimestamp":"1787620345235000","amount":0.81593384,"amount_str":"0.81593384","amount_traded":"0","amount_at_create":"0.81593384","price":79736.43,"price_str":"79736.43","is_liquidation":false},"channel":"live_orders_btcusd","event":"order_deleted","event_id":"000659d4-cbab-c638-0004-000101000020","pre_event_id":"000659d4-cbab-c638-0003-000100000020","order_source":"orderbook"}
{"data":{"id":2043024877875200,"id_str":"2043024877875200","order_type":0,"order_subtype":5,"datetime":"1787620345","microtimestamp":"1787620345235000","amount":0.18836864,"amount_str":"0.18836864","amount_traded":"0","amount_at_create":"0.18836864","price":79617.08,"price_str":"79617.08","is_liquidation":false},"channel":"live_orders_btcusd","event":"order_created","event_id":"000659d4-cbab-c638-0005-000102000020","pre_event_id":"000659d4-cbab-c638-0004-000101000020","order_source":"orderbook"}
{"data":{"id":2043024862994436,"id_str":"2043024862994436","order_type":0,"order_subtype":5,"datetime":"1787620345","microtimestamp":"1787620345236000","amount":0.48956031,"amount_str":"0.48956031","amount_traded":"0","amount_at_create":"0.48956031","price":79612.33,"price_str":"79612.33","is_liquidation":false},"channel":"live_orders_btcusd","event":"order_deleted","event_id":"000659d4-cbab-ca20-0000-000103000020","pre_event_id":"000659d4-cbab-c638-0005-000102000020","order_source":"orderbook"}
{"data":{"id":2043024858644488,"id_str":"2043024858644488","order_type":0,"order_subtype":0,"datetime":"1787620345","microtimestamp":"1787620345236000","amount":0.00316447,"amount_str":"0.00316447","amount_traded":"0","amount_at_create":"0.00316447","price":79602.64,"price_str":"79602.64","is_liquidation":false},"channel":"live_orders_btcusd","event":"order_deleted","event_id":"000659d4-cbab-ca20-0001-000100000020","pre_event_id":"000659d4-cbab-ca20-0000-000103000020","order_source":"orderbook"}
{"data":{"id":2043024870047744,"id_str":"2043024870047744","order_type":1,"order_subtype":5,"datetime":"1787620345","microtimestamp":"1787620345236000","amount":0.02222515,"amount_str":"0.02222515","amount_traded":"0","amount_at_create":"0.02222515","price":79670.65,"price_str":"79670.65","is_liquidation":false},"channel":"live_orders_btcusd","event":"order_deleted","event_id":"000659d4-cbab-ca20-0002-000101000020","pre_event_id":"000659d4-cbab-ca20-0001-000100000020","order_source":"orderbook"}
{"data":{"id":2043024870043648,"id_str":"2043024870043648","order_type":0,"order_subtype":5,"datetime":"1787620345","microtimestamp":"1787620345237000","amount":0.00316447,"amount_str":"0.00316447","amount_traded":"0","amount_at_create":"0.00316447","price":79616.56,"price_str":"79616.56","is_liquidation":false},"channel":"live_orders_btcusd","event":"order_deleted","event_id":"000659d4-cbab-ce08-0000-000102000020","pre_event_id":"000659d4-cbab-ca20-0002-000101000020","order_source":"orderbook"}
{"data":{"id":2043024877879352,"id_str":"2043024877879352","order_type":0,"order_subtype":5,"datetime":"1787620345","microtimestamp":"1787620345237000","amount":0.18837294,"amount_str":"0.18837294","amount_traded":"0","amount_at_create":"0.18837294","price":79613.86,"price_str":"79613.86","is_liquidation":false},"channel":"live_orders_btcusd","event":"order_created","event_id":"000659d4-cbab-ce08-0001-000103000020","pre_event_id":"000659d4-cbab-ce08-0000-000102000020","order_source":"orderbook"}
{"data":{"id":2043024877883395,"id_str":"2043024877883395","order_type":0,"order_subtype":5,"datetime":"1787620345","microtimestamp":"1787620345237000","amount":0.62789547,"amount_str":"0.62789547","amount_traded":"0","amount_at_create":"0.62789547","price":79615.08,"price_str":"79615.08","is_liquidation":false},"channel":"live_orders_btcusd","event":"order_created","event_id":"000659d4-cbab-ce08-0002-000100000020","pre_event_id":"000659d4-cbab-ce08-0001-000103000020","order_source":"orderbook"}
{"data":{"id":2043024862986245,"id_str":"2043024862986245","order_type":0,"order_subtype":5,"datetime":"1787620345","microtimestamp":"1787620345237000","amount":0.48956031,"amount_str":"0.48956031","amount_traded":"0","amount_at_create":"0.48956031","price":79620.3,"price_str":"79620.30","is_liquidation":false},"channel":"live_orders_btcusd","event":"order_deleted","event_id":"000659d4-cbab-ce08-0003-000101000020","pre_event_id":"000659d4-cbab-ce08-0002-000100000020","order_source":"orderbook"}
{"data":{"id":2043024877883404,"id_str":"2043024877883404","order_type":1,"order_subtype":5,"datetime":"1787620345","microtimestamp":"1787620345237000","amount":0.48956031,"amount_str":"0.48956031","amount_traded":"0","amount_at_create":"0.48956031","price":79640.91,"price_str":"79640.91","is_liquidation":false},"channel":"live_orders_btcusd","event":"order_created","event_id":"000659d4-cbab-ce08-0004-000102000020","pre_event_id":"000659d4-cbab-ce08-0003-000101000020","order_source":"orderbook"}
{"data":{"id":2043024872583186,"id_str":"2043024872583186","order_type":0,"order_subtype":5,"datetime":"1787620345","microtimestamp":"1787620345237000","amount":0.25122755,"amount_str":"0.25122755","amount_traded":"0","amount_at_create":"0.25122755","price":79609.1,"price_str":"79609.10","is_liquidation":false},"channel":"live_orders_btcusd","event":"order_deleted","event_id":"000659d4-cbab-ce08-0005-000103000020","pre_event_id":"000659d4-cbab-ce08-0004-000102000020","order_source":"orderbook"}
{"data":{"id":2043024860241925,"id_str":"2043024860241925","order_type":0,"order_subtype":5,"datetime":"1787620345","microtimestamp":"1787620345237000","amount":0.0255447,"amount_str":"0.02554470","amount_traded":"0","amount_at_create":"0.02554470","price":79536.64,"price_str":"79536.64","is_liquidation":false},"channel":"live_orders_btcusd","event":"order_deleted","event_id":"000659d4-cbab-ce08-0006-000100000020","pre_event_id":"000659d4-cbab-ce08-0005-000103000020","order_source":"orderbook"}
{"data":{"id":2043024877854722,"id_str":"2043024877854722","order_type":0,"order_subtype":5,"datetime":"1787620345","microtimestamp":"1787620345237000","amount":0.18836695,"amount_str":"0.18836695","amount_traded":"0","amount_at_create":"0.18836695","price":79617.53,"price_str":"79617.53","is_liquidation":false},"channel":"live_orders_btcusd","event":"order_deleted","event_id":"000659d4-cbab-ce08-0007-000101000020","pre_event_id":"000659d4-cbab-ce08-0006-000100000020","order_source":"orderbook"}
{"data":{"id":2043024877891606,"id_str":"2043024877891606","order_type":0,"order_subtype":0,"datetime":"1787620345","microtimestamp":"1787620345237000","amount":0.06275933,"amount_str":"0.06275933","amount_traded":"0","amount_at_create":"0.06275933","price":79582.21,"price_str":"79582.21","is_liquidation":false},"channel":"live_orders_btcusd","event":"order_created","event_id":"000659d4-cbab-ce08-0008-000102000020","pre_event_id":"000659d4-cbab-ce08-0007-000101000020","order_source":"orderbook"}
{"data":{"id":2043024877895688,"id_str":"2043024877895688","order_type":0,"order_subtype":0,"datetime":"1787620345","microtimestamp":"1787620345238000","amount":0.06275933,"amount_str":"0.06275933","amount_traded":"0","amount_at_create":"0.06275933","price":79577.43,"price_str":"79577.43","is_liquidation":false},"channel":"live_orders_btcusd","event":"order_created","event_id":"000659d4-cbab-d1f0-0000-000103000020","pre_event_id":"000659d4-cbab-ce08-0008-000102000020","order_source":"orderbook"}
{"data":{"id":2043024877895697,"id_str":"2043024877895697","order_type":1,"order_subtype":5,"datetime":"1787620345","microtimestamp":"1787620345238000","amount":0.01255663,"amount_str":"0.01255663","amount_traded":"0","amount_at_create":"0.01255663","price":79646.51,"price_str":"79646.51","is_liquidation":false},"channel":"live_orders_btcusd","event":"order_created","event_id":"000659d4-cbab-d1f0-0001-000100000020","pre_event_id":"000659d4-cbab-d1f0-0000-000103000020","order_source":"orderbook"}
{"data":{"id":2043024877895712,"id_str":"2043024877895712","order_type":1,"order_subtype":5,"datetime":"1787620345","microtimestamp":"1787620345238000","amount":0.02222515,"amount_str":"0.02222515","amount_traded":"0","amount_at_create":"0.02222515","price":79662,"price_str":"79662.00","is_liquidation":false},"channel":"live_orders_btcusd","event":"order_created","event_id":"000659d4-cbab-d1f0-0002-000101000020","pre_event_id":"000659d4-cbab-d1f0-0001-000100000020","order_source":"orderbook"}
{"data":{"id":2043024871567389,"id_str":"2043024871567389","order_type":0,"order_subtype":5,"datetime":"1787620345","microtimestamp":"1787620345238000","amount":0.26349748,"amount_str":"0.26349748","amount_traded":"0","amount_at_create":"0.26349748","price":79617.37,"price_str":"79617.37","is_liquidation":false},"channel":"live_orders_btcusd","event":"order_deleted","event_id":"000659d4-cbab-d1f0-0003-000102000020","pre_event_id":"000659d4-cbab-d1f0-0002-000101000020","order_source":"orderbook"}
{"data":{"id":2043024877867021,"id_str":"2043024877867021","order_type":0,"order_subtype":5,"datetime":"1787620345","microtimestamp":"1787620345238000","amount":0.62788986,"amount_str":"0.62788986","amount_traded":"0","amount_at_create":"0.62788986","price":79615.54,"price_str":"79615.54","is_liquidation":false},"channel":"live_orders_btcusd","event":"order_deleted","event_id":"000659d4-cbab-d1f0-0004-000103000020","pre_event_id":"000659d4-cbab-d1f0-0003-000102000020","order_source":"orderbook"}
{"data":{"id":2043024877899789,"id_str":"2043024877899789","order_type":0,"order_subtype":4,"datetime":"1787620345","microtimestamp":"1787620345239000","amount":6.538e-05,"amount_str":"0.00006538","amount_traded":"0","amount_at_create":"0.00006538","price":77252,"price_str":"77252.00","is_liquidation":false},"channel":"live_orders_btcusd","event":"order_created","event_id":"000659d4-cbab-d5d8-0000-000100000020","pre_event_id":"000659d4-cbab-d1f0-0004-000103000020","order_source":"orderbook"}
{"data":{"id":2043024877899789,"id_str":"2043024877899789","order_type":0,"order_subtype":4,"datetime":"1787620345","microtimestamp":"1787620345239000","amount":6.538e-05,"amount_str":"0.00006538","amount_traded":"0","amount_at_create":"0.00006538","price":77252,"price_str":"77252.00","is_liquidation":false},"channel":"live_orders_btcusd","event":"order_deleted","event_id":"000659d4-cbab-d5d8-0001-000101000020","pre_event_id":"000659d4-cbab-d5d8-0000-000100000020","order_source":"orderbook"}
{"data":{"id":2043024877899790,"id_str":"2043024877899790","order_type":0,"order_subtype":5,"datetime":"1787620345","microtimestamp":"1787620345239000","amount":0.00316447,"amount_str":"0.00316447","amount_traded":"0","amount_at_create":"0.00316447","price":79607.91,"price_str":"79607.91","is_liquidation":false},"channel":"live_orders_btcusd","event":"order_created","event_id":"000659d4-cbab-d5d8-0002-000102000020","pre_event_id":"000659d4-cbab-d5d8-0001-000101000020","order_source":"orderbook"}
{"data":{"id":2043024877813771,"id_str":"2043024877813771","order_type":1,"order_subtype":5,"datetime":"1787620345","microtimestamp":"1787620345239000","amount":0.1,"amount_str":"0.10000000","amount_traded":"0","amount_at_create":"0.10000000","price":79643.71,"price_str":"79643.71","is_liquidation":false},"channel":"live_orders_btcusd","event":"order_deleted","event_id":"000659d4-cbab-d5d8-0003-000103000020","pre_event_id":"000659d4-cbab-d5d8-0002-000102000020","order_source":"orderbook"}
{"data":{"id":2043024850399241,"id_str":"2043024850399241","order_type":1,"order_subtype":5,"datetime":"1787620345","microtimestamp":"1787620345239000","amount":0.06275933,"amount_str":"0.06275933","amount_traded":"0","amount_at_create":"0.06275933","price":79662.13,"price_str":"79662.13","is_liquidation":false},"channel":"live_orders_btcusd","event":"order_deleted","event_id":"000659d4-cbab-d5d8-0004-000100000020","pre_event_id":"000659d4-cbab-d5d8-0003-000103000020","order_source":"orderbook"}
{"data":{"id":2043024863531015,"id_str":"2043024863531015","order_type":1,"order_subtype":5,"datetime":"1787620345","microtimestamp":"1787620345239000","amount":0.1,"amount_str":"0.10000000","amount_traded":"0","amount_at_create":"0.10000000","price":79644.93,"price_str":"79644.93","is_liquidation":false},"channel":"live_orders_btcusd","event":"order_deleted","event_id":"000659d4-cbab-d5d8-0005-000101000020","pre_event_id":"000659d4-cbab-d5d8-0004-000100000020","order_source":"orderbook"}
{"data":{"id":2043024877903877,"id_str":"2043024877903877","order_type":0,"order_subtype":5,"datetime":"1787620345","microtimestamp":"1787620345239000","amount":0.024359,"amount_str":"0.02435900","amount_traded":"0","amount_at_create":"0.02435900","price":79598.28,"price_str":"79598.28","is_liquidation":false},"channel":"live_orders_btcusd","event":"order_created","event_id":"000659d4-cbab-d5d8-0006-000102000020","pre_event_id":"000659d4-cbab-d5d8-0005-000101000020","order_source":"orderbook"}
{"data":{"id":2043024850161666,"id_str":"2043024850161666","order_type":1,"order_subtype":5,"datetime":"1787620345","microtimestamp":"1787620345240000","amount":0.0255447,"amount_str":"0.02554470","amount_traded":"0","amount_at_create":"0.02554470","price":79736.74,"price_str":"79736.74","is_liquidation":false},"channel":"live_orders_btcusd","event":"order_deleted","event_id":"000659d4-cbab-d9c0-0000-000103000020","pre_event_id":"000659d4-cbab-d5d8-0006-000102000020","order_source":"orderbook"}
{"data":{"id":2043024877903878,"id_str":"2043024877903878","order_type":0,"order_subtype":0,"datetime":"1787620345","microtimestamp":"1787620345240000","amount":0.06275933,"amount_str":"0.06275933","amount_traded":"0","amount_at_create":"0.06275933","price":79572.65,"price_str":"79572.65","is_liquidation":false},"channel":"live_orders_btcusd","event":"order_created","event_id":"000659d4-cbab-d9c0-0001-000100000020","pre_event_id":"000659d4-cbab-d9c0-0000-000103000020","order_source":"orderbook"}
{"data":{"id":2043024863367173,"id_str":"2043024863367173","order_type":1,"order_subtype":5,"datetime":"1787620345","microtimestamp":"1787620345240000","amount":0.1,"amount_str":"0.10000000","amount_traded":"0","amount_at_create":"0.10000000","price":79647.39,"price_str":"79647.39","is_liquidation":false},"channel":"live_orders_btcusd","event":"order_deleted","event_id":"000659d4-cbab-d9c0-0002-000101000020","pre_event_id":"000659d4-cbab-d9c0-0001-000100000020","order_source":"orderbook"}
{"data":{"id":2043024863207424,"id_str":"2043024863207424","order_type":1,"order_subtype":5,"datetime":"1787620345","microtimestamp":"1787620345241000","amount":0.1,"amount_str":"0.10000000","amount_traded":"0","amount_at_create":"0.10000000","price":79647.46,"price_str":"79647.46","is_liquidation":false},"channel":"live_orders_btcusd","event":"order_deleted","event_id":"000659d4-cbab-dda8-0000-000102000020","pre_event_id":"000659d4-cbab-d9c0-0002-000101000020","order_source":"orderbook"}
{"data":{"id":2043024877867029,"id_str":"2043024877867029","order_type":0,"order_subtype":5,"datetime":"1787620345","microtimestamp":"1787620345241000","amount":0.50231188,"amount_str":"0.50231188","amount_traded":"0","amount_at_create":"0.50231188","price":79613.55,"price_str":"79613.55","is_liquidation":false},"channel":"live_orders_btcusd","event":"order_deleted","event_id":"000659d4-cbab-dda8-0001-000103000020","pre_event_id":"000659d4-cbab-dda8-0000-000102000020","order_source":"orderbook"}
{"data":{"id":2043024772726787,"id_str":"2043024772726787","order_type":1,"order_subtype":5,"datetime":"1787620345","microtimestamp":"1787620345241000","amount":1.2531389,"amount_str":"1.25313890","amount_traded":"0","amount_at_create":"1.25313890","price":79799.62,"price_str":"79799.62","is_liquidation":false},"channel":"live_orders_btcusd","event":"order_deleted","event_id":"000659d4-cbab-dda8-0002-000100000020","pre_event_id":"000659d4-cbab-dda8-0001-000103000020","order_source":"orderbook"}
{"data":{"id":2043024877912066,"id_str":"2043024877912066","order_type":0,"order_subtype":5,"datetime":"1787620345","microtimestamp":"1787620345241000","amount":0.0255447,"amount_str":"0.02554470","amount_traded":"0","amount_at_create":"0.02554470","price":79528.54,"price_str":"79528.54","is_liquidation":false},"channel":"live_orders_btcusd","event":"order_created","event_id":"000659d4-cbab-dda8-0003-000101000020","pre_event_id":"000659d4-cbab-dda8-0002-000100000020","order_source":"orderbook"}
{"data":{"id":2043024850137104,"id_str":"2043024850137104","order_type":0,"order_subtype":0,"datetime":"1787620345","microtimestamp":"1787620345242000","amount":0.06275933,"amount_str":"0.06275933","amount_traded":"0","amount_at_create":"0.06275933","price":79601.33,"price_str":"79601.33","is_liquidation":false},"channel":"live_orders_btcusd","event":"order_deleted","event_id":"000659d4-cbab-e190-0000-000102000020","pre_event_id":"000659d4-cbab-dda8-0003-000101000020","order_source":"orderbook"}
{"data":{"id":2043024877858826,"id_str":"2043024877858826","order_type":0,"order_subtype":5,"datetime":"1787620345","microtimestamp":"1787620345242000","amount":0.48956031,"amount_str":"0.48956031","amount_traded":"0","amount_at_create":"0.48956031","price":79612.33,"price_str":"79612.33","is_liquidation":false},"channel":"live_orders_btcusd","event":"order_deleted","event_id":"000659d4-cbab-e190-0001-000103000020","pre_event_id":"000659d4-cbab-e190-0000-000102000020","order_source":"orderbook"}
{"data":{"id":2043024877920257,"id_str":"2043024877920257","order_type":0,"order_subtype":5,"datetime":"1787620345","microtimestamp":"1787620345243000","amount":0.0255447,"amount_str":"0.02554470","amount_traded":"0","amount_at_create":"0.02554470","price":79506.2,"price_str":"79506.20","is_liquidation":false},"channel":"live_orders_btcusd","event":"order_created","event_id":"000659d4-cbab-e578-0000-000100000020","pre_event_id":"000659d4-cbab-e190-0001-000103000020","order_source":"orderbook"}
{"data":{"id":2043024861745169,"id_str":"2043024861745169","order_type":0,"order_subtype":0,"datetime":"1787620345","microtimestamp":"1787620345244000","amount":0.06275933,"amount_str":"0.06275933","amount_traded":"0","amount_at_create":"0.06275933","price":79596.55,"price_str":"79596.55","is_liquidation":false},"channel":"live_orders_btcusd","event":"order_deleted","event_id":"000659d4-cbab-e960-0000-000101000020","pre_event_id":"000659d4-cbab-e578-0000-000100000020","order_source":"orderbook"}
{"data":{"id":2043024877875200,"id_str":"2043024877875200","order_type":0,"order_subtype":5,"datetime":"1787620345","microtimestamp":"1787620345244000","amount":0.18836864,"amount_str":"0.18836864","amount_traded":"0","amount_at_create":"0.18836864","price":79617.08,"price_str":"79617.08","is_liquidation":false},"channel":"live_orders_btcusd","event":"order_deleted","event_id":"000659d4-cbab-e960-0001-000102000020","pre_event_id":"000659d4-cbab-e960-0000-000101000020","order_source":"orderbook"}
{"data":{"id":2043024877871123,"id_str":"2043024877871123","order_type":0,"order_subtype":5,"datetime":"1787620345","microtimestamp":"1787620345244000","amount":0.48956031,"amount_str":"0.48956031","amount_traded":"0","amount_at_create":"0.48956031","price":79604.36,"price_str":"79604.36","is_liquidation":false},"channel":"live_orders_btcusd","event":"order_deleted","event_id":"000659d4-cbab-e960-0002-000103000020","pre_event_id":"000659d4-cbab-e960-0001-000102000020","order_source":"orderbook"}
{"data":{"id":2043024870047746,"id_str":"2043024870047746","order_type":1,"order_subtype":0,"datetime":"1787620345","microtimestamp":"1787620345244000","amount":0.00290953,"amount_str":"0.00290953","amount_traded":"0","amount_at_create":"0.00290953","price":79700.21,"price_str":"79700.21","is_liquidation":false},"channel":"live_orders_btcusd","event":"order_deleted","event_id":"000659d4-cbab-e960-0003-000100000020","pre_event_id":"000659d4-cbab-e960-0002-000103000020","order_source":"orderbook"}
{"data":{"id":2043024877924401,"id_str":"2043024877924401","order_type":1,"order_subtype":5,"datetime":"1787620345","microtimestamp":"1787620345245000","amount":0.06275933,"amount_str":"0.06275933","amount_traded":"0","amount_at_create":"0.06275933","price":79640.91,"price_str":"79640.91","is_liquidation":false},"channel":"live_orders_btcusd","event":"order_created","event_id":"000659d4-cbab-ed48-0000-000101000020","pre_event_id":"000659d4-cbab-e960-0003-000100000020","order_source":"orderbook"}
{"data":{"id":2043024877924382,"id_str":"2043024877924382","order_type":0,"order_subtype":0,"datetime":"1787620345","microtimestamp":"1787620345245000","amount":0.00316447,"amount_str":"0.00316447","amount_traded":"0","amount_at_create":"0.00316447","price":79586.42,"price_str":"79586.42","is_liquidation":false},"channel":"live_orders_btcusd","event":"order_created","event_id":"000659d4-cbab-ed48-0001-000102000020","pre_event_id":"000659d4-cbab-ed48-0000-000101000020","order_source":"orderbook"}
{"data":{"id":2043024877846602,"id_str":"2043024877846602","order_type":1,"order_subtype":5,"datetime":"1787620345","microtimestamp":"1787620345245000","amount":0.01255663,"amount_str":"0.01255663","amount_traded":"0","amount_at_create":"0.01255663","price":79646.51,"price_str":"79646.51","is_liquidation":false},"channel":"live_orders_btcusd","event":"order_deleted","event_id":"000659d4-cbab-ed48-0002-000103000020","pre_event_id":"000659d4-cbab-ed48-0001-000102000020","order_source":"orderbook"}
{"data":{"id":2043024877928448,"id_str":"2043024877928448","order_type":0,"order_subtype":0,"datetime":"1787620345","microtimestamp":"1787620345246000","amount":0.06275933,"amount_str":"0.06275933","amount_traded":"0","amount_at_create":"0.06275933","price":79567.87,"price_str":"79567.87","is_liquidation":false},"channel":"live_orders_btcusd","event":"order_created","event_id":"000659d4-cbab-f130-0000-000100000020","pre_event_id":"000659d4-cbab-ed48-0002-000103000020","order_source":"orderbook"}
{"data":{"id":2043024877912065,"id_str":"2043024877912065","order_type":0,"order_subtype":5,"datetime":"1787620345","microtimestamp":"1787620345246000","amount":0.00143636,"amount_str":"0.00143636","amount_traded":"0","amount_at_create":"0.00143636","price":71676.81,"price_str":"71676.81","is_liquidation":false},"channel":"live_orders_btcusd","event":"order_created","event_id":"000659d4-cbab-f130-0001-000101000020","pre_event_id":"000659d4-cbab-f130-0000-000100000020","order_source":"orderbook"}
{"data":{"id":2043024870506500,"id_str":"2043024870506500","order_type":1,"order_subtype":5,"datetime":"1787620345","microtimestamp":"1787620345247000","amount":0.25,"amount_str":"0.25000000","amount_traded":"0","amount_at_create":"0.25000000","price":79640.91,"price_str":"79640.91","is_liquidation":false},"channel":"live_orders_btcusd","event":"order_deleted","event_id":"000659d4-cbab-f518-0000-000102000020","pre_event_id":"000659d4-cbab-f130-0001-000101000020","order_source":"orderbook"}
{"data":{"id":2043024877256706,"id_str":"2043024877256706","order_type":0,"order_subtype":5,"datetime":"1787620345","microtimestamp":"1787620345247000","amount":0.00143636,"amount_str":"0.00143636","amount_traded":"0","amount_at_create":"0.00143636","price":71676.81,"price_str":"71676.81","is_liquidation":false},"channel":"live_orders_btcusd","event":"order_deleted","event_id":"000659d4-cbab-f518-0001-000103000020","pre_event_id":"000659d4-cbab-f518-0000-000102000020","order_source":"orderbook"}
{"data":{"id":2043024877912066,"id_str":"2043024877912066","order_type":0,"order_subtype":5,"datetime":"1787620345","microtimestamp":"1787620345248000","amount":0.0255447,"amount_str":"0.02554470","amount_traded":"0","amount_at_create":"0.02554470","price":79528.54,"price_str":"79528.54","is_liquidation":false},"channel":"live_orders_btcusd","event":"order_deleted","event_id":"000659d4-cbab-f900-0000-000100000020","pre_event_id":"000659d4-cbab-f518-0001-000103000020","order_source":"orderbook"}
{"data":{"id":2043024877879352,"id_str":"2043024877879352","order_type":0,"order_subtype":5,"datetime":"1787620345","microtimestamp":"1787620345248000","amount":0.18837294,"amount_str":"0.18837294","amount_traded":"0","amount_at_create":"0.18837294","price":79613.86,"price_str":"79613.86","is_liquidation":false},"channel":"live_orders_btcusd","event":"order_deleted","event_id":"000659d4-cbab-f900-0001-000101000020","pre_event_id":"000659d4-cbab-f900-0000-000100000020","order_source":"orderbook"}
{"data":{"id":2043024877580290,"id_str":"2043024877580290","order_type":0,"order_subtype":5,"datetime":"1787620345","microtimestamp":"1787620345249000","amount":0.00143636,"amount_str":"0.00143636","amount_traded":"0","amount_at_create":"0.00143636","price":71676.81,"price_str":"71676.81","is_liquidation":false},"channel":"live_orders_btcusd","event":"order_deleted","event_id":"000659d4-cbab-fce8-0000-000102000020","pre_event_id":"000659d4-cbab-f900-0001-000101000020","order_source":"orderbook"}
{"data":{"id":2043024877883395,"id_str":"2043024877883395","order_type":0,"order_subtype":5,"datetime":"1787620345","microtimestamp":"1787620345249000","amount":0.62789547,"amount_str":"0.62789547","amount_traded":"0","amount_at_create":"0.62789547","price":79615.08,"price_str":"79615.08","is_liquidation":false},"channel":"live_orders_btcusd","event":"order_deleted","event_id":"000659d4-cbab-fce8-0001-000103000020","pre_event_id":"000659d4-cbab-fce8-0000-000102000020","order_source":"orderbook"}
{"data":{"id":2043024877940755,"id_str":"2043024877940755","order_type":1,"order_subtype":4,"datetime":"1787620345","microtimestamp":"1787620345249000","amount":0.491,"amount_str":"0.49100000","amount_traded":"0","amount_at_create":"0.49100000","price":79633.73,"price_str":"79633.73","is_liquidation":false},"channel":"live_orders_btcusd","event":"order_created","event_id":"000659d4-cbab-fce8-0002-000100000020","pre_event_id":"000659d4-cbab-fce8-0001-000103000020","order_source":"orderbook"}
{"data":{"id":2043024877940755,"id_str":"2043024877940755","order_type":1,"order_subtype":4,"datetime":"1787620345","microtimestamp":"1787620345249000","amount":0.491,"amount_str":"0.49100000","amount_traded":"0","amount_at_create":"0.49100000","price":79633.73,"price_str":"79633.73","is_liquidation":false},"channel":"live_orders_btcusd","event":"order_deleted","event_id":"000659d4-cbab-fce8-0003-000101000020","pre_event_id":"000659d4-cbab-fce8-0002-000100000020","order_source":"orderbook"}
{"data":{"id":2043024877940765,"id_str":"2043024877940765","order_type":1,"order_subtype":5,"datetime":"1787620345","microtimestamp":"1787620345250000","amount":0.25109124,"amount_str":"0.25109124","amount_traded":"0","amount_at_create":"0.25109124","price":79652.32,"price_str":"79652.32","is_liquidation":false},"channel":"live_orders_btcusd","event":"order_created","event_id":"000659d4-cbac-00d0-0000-000102000020","pre_event_id":"000659d4-cbab-fce8-0003-000101000020","order_source":"orderbook"}
{"data":{"id":2043024877912065,"id_str":"2043024877912065","order_type":0,"order_subtype":5,"datetime":"1787620345","microtimestamp":"1787620345250000","amount":0.00143636,"amount_str":"0.00143636","amount_traded":"0","amount_at_create":"0.00143636","price":71676.81,"price_str":"71676.81","is_liquidation":false},"channel":"live_orders_btcusd","event":"order_deleted","event_id":"000659d4-cbac-00d0-0001-000103000020","pre_event_id":"000659d4-cbac-00d0-0000-000102000020","order_source":"orderbook"}
{"data":{"id":2043024678625298,"id_str":"2043024678625298","order_type":0,"order_subtype":5,"datetime":"1787620345","microtimestamp":"1787620345250000","amount":0.0646,"amount_str":"0.06460000","amount_traded":"0","amount_at_create":"0.06460000","price":79587.07,"price_str":"79587.07","is_liquidation":false},"channel":"live_orders_btcusd","event":"order_deleted","event_id":"000659d4-cbac-00d0-0002-000100000020","pre_event_id":"000659d4-cbac-00d0-0001-000103000020","order_source":"orderbook"}
{"data":{"id":2043024877948956,"id_str":"2043024877948956","order_type":1,"order_subtype":5,"datetime":"1787620345","microtimestamp":"1787620345251000","amount":12.52784774,"amount_str":"12.52784774","amount_traded":"0","amount_at_create":"12.52784774","price":79822.18,"price_str":"79822.18","is_liquidation":false},"channel":"live_orders_btcusd","event":"order_created","event_id":"000659d4-cbac-04b8-0000-000101000020","pre_event_id":"000659d4-cbac-00d0-0002-000100000020","order_source":"orderbook"}
{"data":{"id":2043024877953037,"id_str":"2043024877953037","order_type":1,"order_subtype":0,"datetime":"1787620345","microtimestamp":"1787620345252000","amount":0.00290953,"amount_str":"0.00290953","amount_traded":"0","amount_at_create":"0.00290953","price":79685.94,"price_str":"79685.94","is_liquidation":false},"channel":"live_orders_btcusd","event":"order_created","event_id":"000659d4-cbac-08a0-0000-000102000020","pre_event_id":"000659d4-cbac-04b8-0000-000101000020","order_source":"orderbook"}
{"data":{"id":2043024877854813,"id_str":"2043024877854813","order_type":0,"order_subtype":5,"datetime":"1787620345","microtimestamp":"1787620345252000","amount":0.024359,"amount_str":"0.02435900","amount_traded":"0","amount_at_create":"0.02435900","price":79575.02,"price_str":"79575.02","is_liquidation":false},"channel":"live_orders_btcusd","event":"order_deleted","event_id":"000659d4-cbac-08a0-0001-000103000020","pre_event_id":"000659d4-cbac-08a0-0000-000102000020","order_source":"orderbook"}
{"data":{"id":2043024877895697,"id_str":"2043024877895697","order_type":1,"order_subtype":5,"datetime":"1787620345","microtimestamp":"1787620345253000","amount":0.01255663,"amount_str":"0.01255663","amount_traded":"0","amount_at_create":"0.01255663","price":79646.51,"price_str":"79646.51","is_liquidation":false},"channel":"live_orders_btcusd","event":"order_deleted","event_id":"000659d4-cbac-0c88-0000-000100000020","pre_event_id":"000659d4-cbac-08a0-0001-000103000020","order_source":"orderbook"}
{"data":{"id":2043024877899790,"id_str":"2043024877899790","order_type":0,"order_subtype":5,"datetime":"1787620345","microtimestamp":"1787620345253000","amount":0.00316447,"amount_str":"0.00316447","amount_traded":"0","amount_at_create":"0.00316447","price":79607.91,"price_str":"79607.91","is_liquidation":false},"channel":"live_orders_btcusd","event":"order_deleted","event_id":"000659d4-cbac-0c88-0001-000101000020","pre_event_id":"000659d4-cbac-0c88-0000-000100000020","order_source":"orderbook"}
{"data":{"id":2043024877748225,"id_str":"2043024877748225","order_type":0,"order_subtype":0,"datetime":"1787620345","microtimestamp":"1787620345253000","amount":0.024359,"amount_str":"0.02435900","amount_traded":"0","amount_at_create":"0.02435900","price":79586.35,"price_str":"79586.35","is_liquidation":false},"channel":"live_orders_btcusd","event":"order_deleted","event_id":"000659d4-cbac-0c88-0002-000102000020","pre_event_id":"000659d4-cbac-0c88-0001-000101000020","order_source":"orderbook"}
{"data":{"id":2043024877961252,"id_str":"2043024877961252","order_type":0,"order_subtype":5,"datetime":"1787620345","microtimestamp":"1787620345254000","amount":0.50236326,"amount_str":"0.50236326","amount_traded":"0","amount_at_create":"0.50236326","price":79603.97,"price_str":"79603.97","is_liquidation":false},"channel":"live_orders_btcusd","event":"order_created","event_id":"000659d4-cbac-1070-0000-000103000020","pre_event_id":"000659d4-cbac-0c88-0002-000102000020","order_source":"orderbook"}
{"data":{"id":2043024860131337,"id_str":"2043024860131337","order_type":0,"order_subtype":0,"datetime":"1787620345","microtimestamp":"1787620345254000","amount":0.0219231,"amount_str":"0.02192310","amount_traded":"0","amount_at_create":"0.02192310","price":79541.44,"price_str":"79541.44","is_liquidation":false},"channel":"live_orders_btcusd","event":"order_deleted","event_id":"000659d4-cbac-1070-0001-000100000020","pre_event_id":"000659d4-cbac-1070-0000-000103000020","order_source":"orderbook"}
{"data":{"id":2043024877903877,"id_str":"2043024877903877","order_type":0,"order_subtype":5,"datetime":"1787620345","microtimestamp":"1787620345255000","amount":0.024359,"amount_str":"0.02435900","amount_traded":"0","amount_at_create":"0.02435900","price":79598.28,"price_str":"79598.28","is_liquidation":false},"channel":"live_orders_btcusd","event":"order_deleted","event_id":"000659d4-cbac-1458-0000-000101000020","pre_event_id":"000659d4-cbac-1070-0001-000100000020","order_source":"orderbook"}
{"data":{"id":2043024863006730,"id_str":"2043024863006730","order_type":0,"order_subtype":5,"datetime":"1787620345","microtimestamp":"1787620345257000","amount":0.00251194,"amount_str":"0.00251194","amount_traded":"0","amount_at_create":"0.00251194","price":79619.59,"price_str":"79619.59","is_liquidation":false},"channel":"live_orders_btcusd","event":"order_deleted","event_id":"000659d4-cbac-1c28-0000-000102000020","pre_event_id":"000659d4-cbac-1458-0000-000101000020","order_source":"orderbook"}
{"data":{"id":2043024877973510,"id_str":"2043024877973510","order_type":0,"order_subtype":5,"datetime":"1787620345","microtimestamp":"1787620345257000","amount":0.0255447,"amount_str":"0.02554470","amount_traded":"0","amount_at_create":"0.02554470","price":79492.62,"price_str":"79492.62","is_liquidation":false},"channel":"live_orders_btcusd","event":"order_created","event_id":"000659d4-cbac-1c28-0001-000103000020","pre_event_id":"000659d4-cbac-1c28-0000-000102000020","order_source":"orderbook"}
{"data":{"id":2043024877973519,"id_str":"2043024877973519","order_type":1,"order_subtype":5,"datetime":"1787620345","microtimestamp":"1787620345257000","amount":0.0255447,"amount_str":"0.02554470","amount_traded":"0","amount_at_create":"0.02554470","price":79676.99,"price_str":"79676.99","is_liquidation":false},"channel":"live_orders_btcusd","event":"order_created","event_id":"000659d4-cbac-1c28-0002-000100000020","pre_event_id":"000659d4-cbac-1c28-0001-000103000020","order_source":"orderbook"}
{"data":{"id":2043024877961252,"id_str":"2043024877961252","order_type":0,"order_subtype":5,"datetime":"1787620345","microtimestamp":"1787620345257000","amount":0.50236326,"amount_str":"0.50236326","amount_traded":"0","amount_at_create":"0.50236326","price":79603.97,"price_str":"79603.97","is_liquidation":false},"channel":"live_orders_btcusd","event":"order_deleted","event_id":"000659d4-cbac-1c28-0003-000101000020","pre_event_id":"000659d4-cbac-1c28-0002-000100000020","order_source":"orderbook"}
{"data":{"id":2043024877977601,"id_str":"2043024877977601","order_type":1,"order_subtype":5,"datetime":"1787620345","microtimestamp":"1787620345257000","amount":0.64019425,"amount_str":"0.64019425","amount_traded":"0","amount_at_create":"0.64019425","price":79749.59,"price_str":"79749.59","is_liquidation":false},"channel":"live_orders_btcusd","event":"order_created","event_id":"000659d4-cbac-1c28-0004-000102000020","pre_event_id":"000659d4-cbac-1c28-0003-000101000020","order_source":"orderbook"}
{"data":{"id":2043024877977612,"id_str":"2043024877977612","order_type":1,"order_subtype":5,"datetime":"1787620345","microtimestamp":"1787620345258000","amount":0.1,"amount_str":"0.10000000","amount_traded":"0","amount_at_create":"0.10000000","price":79642.05,"price_str":"79642.05","is_liquidation":false},"channel":"live_orders_btcusd","event":"order_created","event_id":"000659d4-cbac-2010-0000-000103000020","pre_event_id":"000659d4-cbac-1c28-0004-000102000020","order_source":"orderbook"}
{"data":{"id":2043024850391049,"id_str":"2043024850391049","order_type":1,"order_subtype":5,"datetime":"1787620345","microtimestamp":"1787620345259000","amount":0.06275933,"amount_str":"0.06275933","amount_traded":"0","amount_at_create":"0.06275933","price":79659.74,"price_str":"79659.74","is_liquidation":false},"channel":"live_orders_btcusd","event":"order_deleted","event_id":"000659d4-cbac-23f8-0000-000100000020","pre_event_id":"000659d4-cbac-2010-0000-000103000020","order_source":"orderbook"}
{"data":{"id":2043024850370600,"id_str":"2043024850370600","order_type":1,"order_subtype":5,"datetime":"1787620345","microtimestamp":"1787620345264000","amount":0.06275933,"amount_str":"0.06275933","amount_traded":"0","amount_at_create":"0.06275933","price":79657.35,"price_str":"79657.35","is_liquidation":false},"channel":"live_orders_btcusd","event":"order_deleted","event_id":"000659d4-cbac-3780-0000-000101000020","pre_event_id":"000659d4-cbac-23f8-0000-000100000020","order_source":"orderbook"}
{"data":{"id":2043024877985796,"id_str":"2043024877985796","order_type":0,"order_subtype":5,"datetime":"1787620345","microtimestamp":"1787620345264000","amount":0.18838622,"amount_str":"0.18838622","amount_traded":"0","amount_at_create":"0.18838622","price":79607.95,"price_str":"79607.95","is_liquidation":false},"channel":"live_orders_btcusd","event":"order_created","event_id":"000659d4-cbac-3780-0001-000102000020","pre_event_id":"000659d4-cbac-3780-0000-000101000020","order_source":"orderbook"}
{"data":{"id":2043024850731013,"id_str":"2043024850731013","order_type":1,"order_subtype":5,"datetime":"1787620345","microtimestamp":"1787620345264000","amount":0.06275933,"amount_str":"0.06275933","amount_traded":"0","amount_at_create":"0.06275933","price":79654.83,"price_str":"79654.83","is_liquidation":false},"channel":"live_orders_btcusd","event":"order_deleted","event_id":"000659d4-cbac-3780-0002-000103000020","pre_event_id":"000659d4-cbac-3780-0001-000102000020","order_source":"orderbook"}
{"data":{"id":2043024877985798,"id_str":"2043024877985798","order_type":0,"order_subtype":5,"datetime":"1787620345","microtimestamp":"1787620345265000","amount":0.024359,"amount_str":"0.02435900","amount_traded":"0","amount_at_create":"0.02435900","price":79545.67,"price_str":"79545.67","is_liquidation":false},"channel":"live_orders_btcusd","event":"order_created","event_id":"000659d4-cbac-3b68-0000-000100000020","pre_event_id":"000659d4-cbac-3780-0002-000103000020","order_source":"orderbook"}
{"data":{"id":2043024877985799,"id_str":"2043024877985799","order_type":1,"order_subtype":4,"datetime":"1787620345","microtimestamp":"1787620345265000","amount":0.00478806,"amount_str":"0.00478806","amount_traded":"0","amount_at_create":"0.00478806","price":79640.75,"price_str":"79640.75","is_liquidation":false},"channel":"live_orders_btcusd","event":"order_created","event_id":"000659d4-cbac-3b68-0001-000101000020","pre_event_id":"000659d4-cbac-3b68-0000-000100000020","order_source":"orderbook"}
{"data":{"id":2043024877985799,"id_str":"2043024877985799","order_type":1,"order_subtype":4,"datetime":"1787620345","microtimestamp":"1787620345265000","amount":0.00478806,"amount_str":"0.00478806","amount_traded":"0","amount_at_create":"0.00478806","price":79640.75,"price_str":"79640.75","is_liquidation":false},"channel":"live_orders_btcusd","event":"order_deleted","event_id":"000659d4-cbac-3b68-0002-000102000020","pre_event_id":"000659d4-cbac-3b68-0001-000101000020","order_source":"orderbook"}
{"data":{"id":2043024877989890,"id_str":"2043024877989890","order_type":0,"order_subtype":5,"datetime":"1787620345","microtimestamp":"1787620345265000","amount":0.00316447,"amount_str":"0.00316447","amount_traded":"0","amount_at_create":"0.00316447","price":79599.56,"price_str":"79599.56","is_liquidation":false},"channel":"live_orders_btcusd","event":"order_created","event_id":"000659d4-cbac-3b68-0003-000103000020","pre_event_id":"000659d4-cbac-3b68-0002-000102000020","order_source":"orderbook"}
{"data":{"id":2043024862384143,"id_str":"2043024862384143","order_type":1,"order_subtype":5,"datetime":"1787620345","microtimestamp":"1787620345265000","amount":0.06275933,"amount_str":"0.06275933","amount_traded":"0","amount_at_create":"0.06275933","price":79651.77,"price_str":"79651.77","is_liquidation":false},"channel":"live_orders_btcusd","event":"order_deleted","event_id":"000659d4-cbac-3b68-0004-000100000020","pre_event_id":"000659d4-cbac-3b68-0003-000103000020","order_source":"orderbook"}
{"data":{"id":2043024877993988,"id_str":"2043024877993988","order_type":0,"order_subtype":0,"datetime":"1787620345","microtimestamp":"1787620345265000","amount":0.024359,"amount_str":"0.02435900","amount_traded":"0","amount_at_create":"0.02435900","price":79554.52,"price_str":"79554.52","is_liquidation":false},"channel":"live_orders_btcusd","event":"order_created","event_id":"000659d4-cbac-3b68-0005-000101000020","pre_event_id":"000659d4-cbac-3b68-0004-000100000020","order_source":"orderbook"}
{"data":{"id":2043024877993986,"id_str":"2043024877993986","order_type":0,"order_subtype":5,"datetime":"1787620345","microtimestamp":"1787620345265000","amount":0.18838428,"amount_str":"0.18838428","amount_traded":"0","amount_at_create":"0.18838428","price":79609.87,"price_str":"79609.87","is_liquidation":false},"channel":"live_orders_btcusd","event":"order_created","event_id":"000659d4-cbac-3b68-0006-000102000020","pre_event_id":"000659d4-cbac-3b68-0005-000101000020","order_source":"orderbook"}
{"data":{"id":2043024877989895,"id_str":"2043024877989895","order_type":0,"order_subtype":0,"datetime":"1787620345","microtimestamp":"1787620345269000","amount":0.0219231,"amount_str":"0.02192310","amount_traded":"0","amount_at_create":"0.02192310","price":79501.41,"price_str":"79501.41","is_liquidation":false},"channel":"live_orders_btcusd","event":"order_created","event_id":"000659d4-cbac-4b08-0000-000103000020","pre_event_id":"000659d4-cbac-3b68-0006-000102000020","order_source":"orderbook"}
{"data":{"id":2043024877993992,"id_str":"2043024877993992","order_type":0,"order_subtype":5,"datetime":"1787620345","microtimestamp":"1787620345269000","amount":0.0255447,"amount_str":"0.02554470","amount_traded":"0","amount_at_create":"0.02554470","price":79517.21,"price_str":"79517.21","is_liquidation":false},"channel":"live_orders_btcusd","event":"order_created","event_id":"000659d4-cbac-4b08-0001-000100000020","pre_event_id":"000659d4-cbac-4b08-0000-000103000020","order_source":"orderbook"}
{"data":{"id":2043024877994003,"id_str":"2043024877994003","order_type":1,"order_subtype":4,"datetime":"1787620345","microtimestamp":"1787620345269000","amount":0.33261856,"amount_str":"0.33261856","amount_traded":"0","amount_at_create":"0.33261856","price":79640.75,"price_str":"79640.75","is_liquidation":false},"channel":"live_orders_btcusd","event":"order_created","event_id":"000659d4-cbac-4b08-0002-000101000020","pre_event_id":"000659d4-cbac-4b08-0001-000100000020","order_source":"orderbook"}
{"data":{"id":2043024877994003,"id_str":"2043024877994003","order_type":1,"order_subtype":4,"datetime":"1787620345","microtimestamp":"1787620345269000","amount":0.33261856,"amount_str":"0.33261856","amount_traded":"0","amount_at_create":"0.33261856","price":79640.75,"price_str":"79640.75","is_liquidation":false},"channel":"live_orders_btcusd","event":"order_deleted","event_id":"000659d4-cbac-4b08-0003-000102000020","pre_event_id":"000659d4-cbac-4b08-0002-000101000020","order_source":"orderbook"}
{"data":{"id":2043024877993991,"id_str":"2043024877993991","order_type":0,"order_subtype":5,"datetime":"1787620345","microtimestamp":"1787620345269000","amount":0.62795407,"amount_str":"0.62795407","amount_traded":"0","amount_at_create":"0.62795407","price":79605.96,"price_str":"79605.96","is_liquidation":false},"channel":"live_orders_btcusd","event":"order_created","event_id":"000659d4-cbac-4b08-0004-000103000020","pre_event_id":"000659d4-cbac-4b08-0003-000102000020","order_source":"orderbook"}
{"data":{"id":2043024786169857,"id_str":"2043024786169857","order_type":0,"order_subtype":5,"datetime":"1787620345","microtimestamp":"1787620345269000","amount":1.25729472,"amount_str":"1.25729472","amount_traded":"0","amount_at_create":"1.25729472","price":79535.84,"price_str":"79535.84","is_liquidation":false},"channel":"live_orders_btcusd","event":"order_deleted","event_id":"000659d4-cbac-4b08-0005-000100000020","pre_event_id":"000659d4-cbac-4b08-0004-000103000020","order_source":"orderbook"}
{"data":{"id":2043024878002195,"id_str":"2043024878002195","order_type":0,"order_subtype":5,"datetime":"1787620345","microtimestamp":"1787620345269000","amount":0.50235808,"amount_str":"0.50235808","amount_traded":"0","amount_at_create":"0.50235808","price":79605.89,"price_str":"79605.89","is_liquidation":false},"channel":"live_orders_btcusd","event":"order_created","event_id":"000659d4-cbac-4b08-0006-000101000020","pre_event_id":"000659d4-cbac-4b08-0005-000100000020","order_source":"orderbook"}
{"data":{"id":2043024878002194,"id_str":"2043024878002194","order_type":0,"order_subtype":5,"datetime":"1787620345","microtimestamp":"1787620345270000","amount":0.6279476,"amount_str":"0.62794760","amount_traded":"0","amount_at_create":"0.62794760","price":79607.88,"price_str":"79607.88","is_liquidation":false},"channel":"live_orders_btcusd","event":"order_created","event_id":"000659d4-cbac-4ef0-0000-000102000020","pre_event_id":"000659d4-cbac-4b08-0006-000101000020","order_source":"orderbook"}
{"data":{"id":2043024878006276,"id_str":"2043024878006276","order_type":0,"order_subtype":5,"datetime":"1787620345","microtimestamp":"1787620345270000","amount":0.024359,"amount_str":"0.02435900","amount_traded":"0","amount_at_create":"0.02435900","price":79572.23,"price_str":"79572.23","is_liquidation":false},"channel":"live_orders_btcusd","event":"order_created","event_id":"000659d4-cbac-4ef0-0001-000103000020","pre_event_id":"000659d4-cbac-4ef0-0000-000102000020","order_source":"orderbook"}
{"data":{"id":2043024878014510,"id_str":"2043024878014510","order_type":1,"order_subtype":4,"datetime":"1787620345","microtimestamp":"1787620345270000","amount":0.0035897,"amount_str":"0.00358970","amount_traded":"0","amount_at_create":"0.00358970","price":79640.75,"price_str":"79640.75","is_liquidation":false},"channel":"live_orders_btcusd","event":"order_created","event_id":"000659d4-cbac-4ef0-0002-000100000020","pre_event_id":"000659d4-cbac-4ef0-0001-000103000020","order_source":"orderbook"}
{"data":{"id":2043024878014510,"id_str":"2043024878014510","order_type":1,"order_subtype":4,"datetime":"1787620345","microtimestamp":"1787620345270000","amount":0.0035897,"amount_str":"0.00358970","amount_traded":"0","amount_at_create":"0.00358970","price":79640.75,"price_str":"79640.75","is_liquidation":false},"channel":"live_orders_btcusd","event":"order_deleted","event_id":"000659d4-cbac-4ef0-0003-000101000020","pre_event_id":"000659d4-cbac-4ef0-0002-000100000020","order_source":"orderbook"}
{"data":{"id":2043024878014522,"id_str":"2043024878014522","order_type":1,"order_subtype":5,"datetime":"1787620345","microtimestamp":"1787620345270000","amount":0.06275933,"amount_str":"0.06275933","amount_traded":"0","amount_at_create":"0.06275933","price":79630.92,"price_str":"79630.92","is_liquidation":false},"channel":"live_orders_btcusd","event":"order_created","event_id":"000659d4-cbac-4ef0-0004-000102000020","pre_event_id":"000659d4-cbac-4ef0-0003-000101000020","order_source":"orderbook"}
{"data":{"id":2043024876158978,"id_str":"2043024876158978","order_type":1,"order_subtype":5,"datetime":"1787620345","microtimestamp":"1787620345270000","amount":0.48956031,"amount_str":"0.48956031","amount_traded":"0","amount_at_create":"0.48956031","price":79668.12,"price_str":"79668.12","is_liquidation":false},"channel":"live_orders_btcusd","event":"order_deleted","event_id":"000659d4-cbac-4ef0-0005-000103000020","pre_event_id":"000659d4-cbac-4ef0-0004-000102000020","order_source":"orderbook"}
{"data":{"id":2043024878026789,"id_str":"2043024878026789","order_type":0,"order_subtype":0,"datetime":"1787620345","microtimestamp":"1787620345270000","amount":0.06275933,"amount_str":"0.06275933","amount_traded":"0","amount_at_create":"0.06275933","price":79598.96,"price_str":"79598.96","is_liquidation":false},"channel":"live_orders_btcusd","event":"order_created","event_id":"000659d4-cbac-4ef0-0006-000100000020","pre_event_id":"000659d4-cbac-4ef0-0005-000103000020","order_source":"orderbook"}
{"data":{"id":2043024877993986,"id_str":"2043024877993986","order_type":0,"order_subtype":5,"datetime":"1787620345","microtimestamp":"1787620345270000","amount":0.18838428,"amount_str":"0.18838428","amount_traded":"0","amount_at_create":"0.18838428","price":79609.87,"price_str":"79609.87","is_liquidation":false},"channel":"live_orders_btcusd","event":"order_deleted","event_id":"000659d4-cbac-4ef0-0007-000101000020","pre_event_id":"000659d4-cbac-4ef0-0006-000100000020","order_source":"orderbook"}
{"data":{"id":2043024878030860,"id_str":"2043024878030860","order_type":0,"order_subtype":0,"datetime":"1787620345","microtimestamp":"1787620345271000","amount":0.06275933,"amount_str":"0.06275933","amount_traded":"0","amount_at_create":"0.06275933","price":79595.99,"price_str":"79595.99","is_liquidation":false},"channel":"live_orders_btcusd","event":"order_created","event_id":"000659d4-cbac-52d8-0000-000102000020","pre_event_id":"000659d4-cbac-4ef0-0007-000101000020","order_source":"orderbook"}
{"data":{"id":2043024877985796,"id_str":"2043024877985796","order_type":0,"order_subtype":5,"datetime":"1787620345","microtimestamp":"1787620345271000","amount":0.18838622,"amount_str":"0.18838622","amount_traded":"0","amount_at_create":"0.18838622","price":79607.95,"price_str":"79607.95","is_liquidation":false},"channel":"live_orders_btcusd","event":"order_deleted","event_id":"000659d4-cbac-52d8-0001-000103000020","pre_event_id":"000659d4-cbac-52d8-0000-000102000020","order_source":"orderbook"}
{"data":{"id":2043024877993991,"id_str":"2043024877993991","order_type":0,"order_subtype":5,"datetime":"1787620345","microtimestamp":"1787620345274000","amount":0.62795407,"amount_str":"0.62795407","amount_traded":"0","amount_at_create":"0.62795407","price":79605.96,"price_str":"79605.96","is_liquidation":false},"channel":"live_orders_btcusd","event":"order_deleted","event_id":"000659d4-cbac-5e90-0000-000100000020","pre_event_id":"000659d4-cbac-52d8-0001-000103000020","order_source":"orderbook"}
{"data":{"id":2043024878051341,"id_str":"2043024878051341","order_type":0,"order_subtype":5,"datetime":"1787620345","microtimestamp":"1787620345276000","amount":0.18838439,"amount_str":"0.18838439","amount_traded":"0","amount_at_create":"0.18838439","price":79607.66,"price_str":"79607.66","is_liquidation":false},"channel":"live_orders_btcusd","event":"order_created","event_id":"000659d4-cbac-6660-0000-000101000020","pre_event_id":"000659d4-cbac-5e90-0000-000100000020","order_source":"orderbook"}
{"data":{"id":2043024878002194,"id_str":"2043024878002194","order_type":0,"order_subtype":5,"datetime":"1787620345","microtimestamp":"1787620345277000","amount":0.6279476,"amount_str":"0.62794760","amount_traded":"0","amount_at_create":"0.62794760","price":79607.88,"price_str":"79607.88","is_liquidation":false},"channel":"live_orders_btcusd","event":"order_deleted","event_id":"000659d4-cbac-6a48-0000-000102000020","pre_event_id":"000659d4-cbac-6660-0000-000101000020","order_source":"orderbook"}
{"data":{"id":2043024878059534,"id_str":"2043024878059534","order_type":1,"order_subtype":4,"datetime":"1787620345","microtimestamp":"1787620345277000","amount":0.04915545,"amount_str":"0.04915545","amount_traded":"0","amount_at_create":"0.04915545","price":79640.75,"price_str":"79640.75","is_liquidation":false},"channel":"live_orders_btcusd","event":"order_created","event_id":"000659d4-cbac-6a48-0001-000103000020","pre_event_id":"000659d4-cbac-6a48-0000-000102000020","order_source":"orderbook"}
{"data":{"id":2043024878059534,"id_str":"2043024878059534","order_type":1,"order_subtype":4,"datetime":"1787620345","microtimestamp":"1787620345277000","amount":0.04915545,"amount_str":"0.04915545","amount_traded":"0","amount_at_create":"0.04915545","price":79640.75,"price_str":"79640.75","is_liquidation":false},"channel":"live_orders_btcusd","event":"order_deleted","event_id":"000659d4-cbac-6a48-0002-000100000020","pre_event_id":"000659d4-cbac-6a48-0001-000103000020","order_source":"orderbook"}
{"data":{"id":2043024878059547,"id_str":"2043024878059547","order_type":1,"order_subtype":4,"datetime":"1787620345","microtimestamp":"1787620345278000","amount":0.04984858,"amount_str":"0.04984858","amount_traded":"0","amount_at_create":"0.04984858","price":79640.75,"price_str":"79640.75","is_liquidation":false},"channel":"live_orders_btcusd","event":"order_created","event_id":"000659d4-cbac-6e30-0000-000101000020","pre_event_id":"000659d4-cbac-6a48-0002-000100000020","order_source":"orderbook"}
{"data":{"id":2043024878059547,"id_str":"2043024878059547","order_type":1,"order_subtype":4,"datetime":"1787620345","microtimestamp":"1787620345278000","amount":0.04984858,"amount_str":"0.04984858","amount_traded":"0","amount_at_create":"0.04984858","price":79640.75,"price_str":"79640.75","is_liquidation":false},"channel":"live_orders_btcusd","event":"order_deleted","event_id":"000659d4-cbac-6e30-0001-000102000020","pre_event_id":"000659d4-cbac-6e30-0000-000101000020","order_source":"orderbook"}
{"data":{"id":2043024878059560,"id_str":"2043024878059560","order_type":0,"order_subtype":5,"datetime":"1787620345","microtimestamp":"1787620345278000","amount":0.81593384,"amount_str":"0.81593384","amount_traded":"0","amount_at_create":"0.81593384","price":79521.28,"price_str":"79521.28","is_liquidation":false},"channel":"live_orders_btcusd","event":"order_created","event_id":"000659d4-cbac-6e30-0002-000103000020","pre_event_id":"000659d4-cbac-6e30-0001-000102000020","order_source":"orderbook"}
{"data":{"id":2043024878059563,"id_str":"2043024878059563","order_type":1,"order_subtype":5,"datetime":"1787620345","microtimestamp":"1787620345278000","amount":0.81593385,"amount_str":"0.81593385","amount_traded":"0","amount_at_create":"0.81593385","price":79660.6,"price_str":"79660.60","is_liquidation":false},"channel":"live_orders_btcusd","event":"order_created","event_id":"000659d4-cbac-6e30-0003-000100000020","pre_event_id":"000659d4-cbac-6e30-0002-000103000020","order_source":"orderbook"}
{"data":{"id":2043024878067724,"id_str":"2043024878067724","order_type":1,"order_subtype":5,"datetime":"1787620345","microtimestamp":"1787620345280000","amount":0.06275933,"amount_str":"0.06275933","amount_traded":"0","amount_at_create":"0.06275933","price":79633.31,"price_str":"79633.31","is_liquidation":false},"channel":"live_orders_btcusd","event":"order_created","event_id":"000659d4-cbac-7600-0000-000101000020","pre_event_id":"000659d4-cbac-6e30-0003-000100000020","order_source":"orderbook"}
{"data":{"id":2043024878071817,"id_str":"2043024878071817","order_type":1,"order_subtype":5,"datetime":"1787620345","microtimestamp":"1787620345281000","amount":0.48956031,"amount_str":"0.48956031","amount_traded":"0","amount_at_create":"0.48956031","price":79640.91,"price_str":"79640.91","is_liquidation":false},"channel":"live_orders_btcusd","event":"order_created","event_id":"000659d4-cbac-79e8-0000-000102000020","pre_event_id":"000659d4-cbac-7600-0000-000101000020","order_source":"orderbook"}
{"data":{"id":2043024878002195,"id_str":"2043024878002195","order_type":0,"order_subtype":5,"datetime":"1787620345","microtimestamp":"1787620345281000","amount":0.50235808,"amount_str":"0.50235808","amount_traded":"0","amount_at_create":"0.50235808","price":79605.89,"price_str":"79605.89","is_liquidation":false},"channel":"live_orders_btcusd","event":"order_deleted","event_id":"000659d4-cbac-79e8-0001-000103000020","pre_event_id":"000659d4-cbac-79e8-0000-000102000020","order_source":"orderbook"}
{"data":{"id":2043024878075935,"id_str":"2043024878075935","order_type":1,"order_subtype":5,"datetime":"1787620345","microtimestamp":"1787620345283000","amount":0.06275933,"amount_str":"0.06275933","amount_traded":"0","amount_at_create":"0.06275933","price":79635.7,"price_str":"79635.70","is_liquidation":false},"channel":"live_orders_btcusd","event":"order_created","event_id":"000659d4-cbac-81b8-0000-000100000020","pre_event_id":"000659d4-cbac-79e8-0001-000103000020","order_source":"orderbook"}
{"data":{"id":2043024878080021,"id_str":"2043024878080021","order_type":1,"order_subtype":5,"datetime":"1787620345","microtimestamp":"1787620345284000","amount":0.81593384,"amount_str":"0.81593384","amount_traded":"0","amount_at_create":"0.81593384","price":79715.16,"price_str":"79715.16","is_liquidation":false},"channel":"live_orders_btcusd","event":"order_created","event_id":"000659d4-cbac-85a0-0000-000101000020","pre_event_id":"000659d4-cbac-81b8-0000-000100000020","order_source":"orderbook"}
{"data":{"id":2043024878084097,"id_str":"2043024878084097","order_type":0,"order_subtype":5,"datetime":"1787620345","microtimestamp":"1787620345284000","amount":0.62793703,"amount_str":"0.62793703","amount_traded":"0","amount_at_create":"0.62793703","price":79603.88,"price_str":"79603.88","is_liquidation":false},"channel":"live_orders_btcusd","event":"order_created","event_id":"000659d4-cbac-85a0-0001-000102000020","pre_event_id":"000659d4-cbac-85a0-0000-000101000020","order_source":"orderbook"}
{"data":{"id":2043024878084104,"id_str":"2043024878084104","order_type":1,"order_subtype":5,"datetime":"1787620345","microtimestamp":"1787620345284000","amount":0.06275933,"amount_str":"0.06275933","amount_traded":"0","amount_at_create":"0.06275933","price":79638.09,"price_str":"79638.09","is_liquidation":false},"channel":"live_orders_btcusd","event":"order_created","event_id":"000659d4-cbac-85a0-0002-000103000020","pre_event_id":"000659d4-cbac-85a0-0001-000102000020","order_source":"orderbook"}
{"data":{"id":2043024878088192,"id_str":"2043024878088192","order_type":1,"order_subtype":4,"datetime":"1787620345","microtimestamp":"1787620345284000","amount":0.44,"amount_str":"0.44000000","amount_traded":"0","amount_at_create":"0.44000000","price":79638.66,"price_str":"79638.66","is_liquidation":false},"channel":"live_orders_btcusd","event":"order_created","event_id":"000659d4-cbac-85a0-0003-000100000020","pre_event_id":"000659d4-cbac-85a0-0002-000103000020","order_source":"orderbook"}
{"data":{"id":2043024878088192,"id_str":"2043024878088192","order_type":1,"order_subtype":4,"datetime":"1787620345","microtimestamp":"1787620345284000","amount":0.44,"amount_str":"0.44000000","amount_traded":"0","amount_at_create":"0.44000000","price":79638.66,"price_str":"79638.66","is_liquidation":false},"channel":"live_orders_btcusd","event":"order_deleted","event_id":"000659d4-cbac-85a0-0004-000101000020","pre_event_id":"000659d4-cbac-85a0-0003-000100000020","order_source":"orderbook"}
{"data":{"id":2043024878088202,"id_str":"2043024878088202","order_type":1,"order_subtype":0,"datetime":"1787620345","microtimestamp":"1787620345285000","amount":0.06275933,"amount_str":"0.06275933","amount_traded":"0","amount_at_create":"0.06275933","price":79643.55,"price_str":"79643.55","is_liquidation":false},"channel":"live_orders_btcusd","event":"order_created","event_id":"000659d4-cbac-8988-0000-000102000020","pre_event_id":"000659d4-cbac-85a0-0004-000101000020","order_source":"orderbook"}
{"data":{"id":2043024862326784,"id_str":"2043024862326784","order_type":0,"order_subtype":5,"datetime":"1787620345","microtimestamp":"1787620345286000","amount":0.110014,"amount_str":"0.11001400","amount_traded":"0","amount_at_create":"0.11001400","price":79591.2,"price_str":"79591.20","is_liquidation":false},"channel":"live_orders_btcusd","event":"order_deleted","event_id":"000659d4-cbac-8d70-0000-000103000020","pre_event_id":"000659d4-cbac-8988-0000-000102000020","order_source":"orderbook"}
{"data":{"id":2043024878096389,"id_str":"2043024878096389","order_type":1,"order_subtype":4,"datetime":"1787620345","microtimestamp":"1787620345287000","amount":0.44,"amount_str":"0.44000000","amount_traded":"0","amount_at_create":"0.44000000","price":79638.66,"price_str":"79638.66","is_liquidation":false},"channel":"live_orders_btcusd","event":"order_created","event_id":"000659d4-cbac-9158-0000-000100000020","pre_event_id":"000659d4-cbac-8d70-0000-000103000020","order_source":"orderbook"}
{"data":{"id":2043024878096389,"id_str":"2043024878096389","order_type":1,"order_subtype":4,"datetime":"1787620345","microtimestamp":"1787620345287000","amount":0.44,"amount_str":"0.44000000","amount_traded":"0","amount_at_create":"0.44000000","price":79638.66,"price_str":"79638.66","is_liquidation":false},"channel":"live_orders_btcusd","event":"order_deleted","event_id":"000659d4-cbac-9158-0001-000101000020","pre_event_id":"000659d4-cbac-9158-0000-000100000020","order_source":"orderbook"}
{"data":{"id":2043024878084097,"id_str":"2043024878084097","order_type":0,"order_subtype":5,"datetime":"1787620345","microtimestamp":"1787620345288000","amount":0.62793703,"amount_str":"0.62793703","amount_traded":"0","amount_at_create":"0.62793703","price":79603.88,"price_str":"79603.88","is_liquidation":false},"channel":"live_orders_btcusd","event":"order_deleted","event_id":"000659d4-cbac-9540-0000-000102000020","pre_event_id":"000659d4-cbac-9158-0001-000101000020","order_source":"orderbook"}
{"data":{"id":2043024878104577,"id_str":"2043024878104577","order_type":0,"order_subtype":5,"datetime":"1787620345","microtimestamp":"1787620345288000","amount":0.50234732,"amount_str":"0.50234732","amount_traded":"0","amount_at_create":"0.50234732","price":79604.22,"price_str":"79604.22","is_liquidation":false},"channel":"live_orders_btcusd","event":"order_created","event_id":"000659d4-cbac-9540-0001-000103000020","pre_event_id":"000659d4-cbac-9540-0000-000102000020","order_source":"orderbook"}
{"data":{"id":2043024878051341,"id_str":"2043024878051341","order_type":0,"order_subtype":5,"datetime":"1787620345","microtimestamp":"1787620345288000","amount":0.18838439,"amount_str":"0.18838439","amount_traded":"0","amount_at_create":"0.18838439","price":79607.66,"price_str":"79607.66","is_liquidation":false},"channel":"live_orders_btcusd","event":"order_deleted","event_id":"000659d4-cbac-9540-0002-000100000020","pre_event_id":"000659d4-cbac-9540-0001-000103000020","order_source":"orderbook"}
{"data":{"id":2043024878116870,"id_str":"2043024878116870","order_type":0,"order_subtype":5,"datetime":"1787620345","microtimestamp":"1787620345291000","amount":0.50234742,"amount_str":"0.50234742","amount_traded":"0","amount_at_create":"0.50234742","price":79603.48,"price_str":"79603.48","is_liquidation":false},"channel":"live_orders_btcusd","event":"order_created","event_id":"000659d4-cbac-a0f8-0000-000101000020","pre_event_id":"000659d4-cbac-9540-0002-000100000020","order_source":"orderbook"}
{"data":{"id":2043024878120976,"id_str":"2043024878120976","order_type":0,"order_subtype":5,"datetime":"1787620345","microtimestamp":"1787620345293000","amount":0.62793428,"amount_str":"0.62793428","amount_traded":"0","amount_at_create":"0.62793428","price":79605.47,"price_str":"79605.47","is_liquidation":false},"channel":"live_orders_btcusd","event":"order_created","event_id":"000659d4-cbac-a8c8-0000-000102000020","pre_event_id":"000659d4-cbac-a0f8-0000-000101000020","order_source":"orderbook"}
{"data":{"id":2043024877817870,"id_str":"2043024877817870","order_type":1,"order_subtype":5,"datetime":"1787620345","microtimestamp":"1787620345296000","amount":0.1,"amount_str":"0.10000000","amount_traded":"0","amount_at_create":"0.10000000","price":79640.89,"price_str":"79640.89","is_liquidation":false},"channel":"live_orders_btcusd","event":"order_deleted","event_id":"000659d4-cbac-b480-0000-000103000020","pre_event_id":"000659d4-cbac-a8c8-0000-000102000020","order_source":"orderbook"}
{"data":{"id":2043024878104577,"id_str":"2043024878104577","order_type":0,"order_subtype":5,"datetime":"1787620345","microtimestamp":"1787620345296000","amount":0.50234732,"amount_str":"0.50234732","amount_traded":"0","amount_at_create":"0.50234732","price":79604.22,"price_str":"79604.22","is_liquidation":false},"channel":"live_orders_btcusd","event":"order_deleted","event_id":"000659d4-cbac-b480-0001-000100000020","pre_event_id":"000659d4-cbac-b480-0000-000103000020","order_source":"orderbook"}
{"data":{"id":2043024878116870,"id_str":"2043024878116870","order_type":0,"order_subtype":5,"datetime":"1787620345","microtimestamp":"1787620345299000","amount":0.50234742,"amount_str":"0.50234742","amount_traded":"0","amount_at_create":"0.50234742","price":79603.48,"price_str":"79603.48","is_liquidation":false},"channel":"live_orders_btcusd","event":"order_deleted","event_id":"000659d4-cbac-c038-0000-000101000020","pre_event_id":"000659d4-cbac-b480-0001-000100000020","order_source":"orderbook"}
{"data":{"id":2043024878120976,"id_str":"2043024878120976","order_type":0,"order_subtype":5,"datetime":"1787620345","microtimestamp":"1787620345299000","amount":0.62793428,"amount_str":"0.62793428","amount_traded":"0","amount_at_create":"0.62793428","price":79605.47,"price_str":"79605.47","is_liquidation":false},"channel":"live_orders_btcusd","event":"order_deleted","event_id":"000659d4-cbac-c038-0001-000102000020","pre_event_id":"000659d4-cbac-c038-0000-000101000020","order_source":"orderbook"}
{"data":{"id":2043024878145543,"id_str":"2043024878145543","order_type":0,"order_subtype":5,"datetime":"1787620345","microtimestamp":"1787620345299000","amount":0.18837995,"amount_str":"0.18837995","amount_traded":"0","amount_at_create":"0.18837995","price":79606.61,"price_str":"79606.61","is_liquidation":false},"channel":"live_orders_btcusd","event":"order_created","event_id":"000659d4-cbac-c038-0002-000103000020","pre_event_id":"000659d4-cbac-c038-0001-000102000020","order_source":"orderbook"}
{"data":{"id":2043024878149633,"id_str":"2043024878149633","order_type":1,"order_subtype":5,"datetime":"1787620345","microtimestamp":"1787620345299000","amount":0.1,"amount_str":"0.10000000","amount_traded":"0","amount_at_create":"0.10000000","price":79640.87,"price_str":"79640.87","is_liquidation":false},"channel":"live_orders_btcusd","event":"order_created","event_id":"000659d4-cbac-c038-0003-000100000020","pre_event_id":"000659d4-cbac-c038-0002-000103000020","order_source":"orderbook"}
{"data":{"id":2043024877977612,"id_str":"2043024877977612","order_type":1,"order_subtype":5,"datetime":"1787620345","microtimestamp":"1787620345299000","amount":0.1,"amount_str":"0.10000000","amount_traded":"0","amount_at_create":"0.10000000","price":79642.05,"price_str":"79642.05","is_liquidation":false},"channel":"live_orders_btcusd","event":"order_deleted","event_id":"000659d4-cbac-c038-0004-000101000020","pre_event_id":"000659d4-cbac-c038-0003-000100000020","order_source":"orderbook"}
{"data":{"id":2043024878149643,"id_str":"2043024878149643","order_type":1,"order_subtype":5,"datetime":"1787620345","microtimestamp":"1787620345299000","amount":0.1,"amount_str":"0.10000000","amount_traded":"0","amount_at_create":"0.10000000","price":79641.39,"price_str":"79641.39","is_liquidation":false},"channel":"live_orders_btcusd","event":"order_created","event_id":"000659d4-cbac-c038-0005-000102000020","pre_event_id":"000659d4-cbac-c038-0004-000101000020","order_source":"orderbook"}
{"data":{"id":2043024865005597,"id_str":"2043024865005597","order_type":1,"order_subtype":5,"datetime":"1787620345","microtimestamp":"1787620345300000","amount":0.19,"amount_str":"0.19000000","amount_traded":"0","amount_at_create":"0.19000000","price":79640.91,"price_str":"79640.91","is_liquidation":false},"channel":"live_orders_btcusd","event":"order_deleted","event_id":"000659d4-cbac-c420-0000-000103000020","pre_event_id":"000659d4-cbac-c038-0005-000102000020","order_source":"orderbook"}
{"data":{"id":2043024878157831,"id_str":"2043024878157831","order_type":0,"order_subtype":5,"datetime":"1787620345","microtimestamp":"1787620345301000","amount":0.62793317,"amount_str":"0.62793317","amount_traded":"0","amount_at_create":"0.62793317","price":79604.62,"price_str":"79604.62","is_liquidation":false},"channel":"live_orders_btcusd","event":"order_created","event_id":"000659d4-cbac-c808-0000-000100000020","pre_event_id":"000659d4-cbac-c420-0000-000103000020","order_source":"orderbook"}
{"data":{"id":2043024878161924,"id_str":"2043024878161924","order_type":0,"order_subtype":5,"datetime":"1787620345","microtimestamp":"1787620345303000","amount":0.50234653,"amount_str":"0.50234653","amount_traded":"0","amount_at_create":"0.50234653","price":79602.63,"price_str":"79602.63","is_liquidation":false},"channel":"live_orders_btcusd","event":"order_created","event_id":"000659d4-cbac-cfd8-0000-000101000020","pre_event_id":"000659d4-cbac-c808-0000-000100000020","order_source":"orderbook"}
{"data":{"id":2043024878149643,"id_str":"2043024878149643","order_type":1,"order_subtype":5,"datetime":"1787620345","microtimestamp":"1787620345303000","amount":0.1,"amount_str":"0.10000000","amount_traded":"0","amount_at_create":"0.10000000","price":79641.39,"price_str":"79641.39","is_liquidation":false},"channel":"live_orders_btcusd","event":"order_deleted","event_id":"000659d4-cbac-cfd8-0001-000102000020","pre_event_id":"000659d4-cbac-cfd8-0000-000101000020","order_source":"orderbook"}
{"data":{"id":2043024878170117,"id_str":"2043024878170117","order_type":1,"order_subtype":5,"datetime":"1787620345","microtimestamp":"1787620345305000","amount":0.1,"amount_str":"0.10000000","amount_traded":"0","amount_at_create":"0.10000000","price":79640.88,"price_str":"79640.88","is_liquidation":false},"channel":"live_orders_btcusd","event":"order_created","event_id":"000659d4-cbac-d7a8-0000-000103000020","pre_event_id":"000659d4-cbac-cfd8-0001-000102000020","order_source":"orderbook"}
{"data":{"id":2043024878145543,"id_str":"2043024878145543","order_type":0,"order_subtype":5,"datetime":"1787620345","microtimestamp":"1787620345306000","amount":0.18837995,"amount_str":"0.18837995","amount_traded":"0","amount_at_create":"0.18837995","price":79606.61,"price_str":"79606.61","is_liquidation":false},"channel":"live_orders_btcusd","event":"order_deleted","event_id":"000659d4-cbac-db90-0000-000100000020","pre_event_id":"000659d4-cbac-d7a8-0000-000103000020","order_source":"orderbook"}
{"data":{"id":2043024869048320,"id_str":"2043024869048320","order_type":1,"order_subtype":5,"datetime":"1787620345","microtimestamp":"1787620345306000","amount":1.2,"amount_str":"1.20000000","amount_traded":"0","amount_at_create":"1.20000000","price":79660,"price_str":"79660.00","is_liquidation":false},"channel":"live_orders_btcusd","event":"order_deleted","event_id":"000659d4-cbac-db90-0001-000101000020","pre_event_id":"000659d4-cbac-db90-0000-000100000020","order_source":"orderbook"}
{"data":{"id":2043024863916032,"id_str":"2043024863916032","order_type":0,"order_subtype":5,"datetime":"1787620345","microtimestamp":"1787620345306000","amount":0.05,"amount_str":"0.05000000","amount_traded":"0","amount_at_create":"0.05000000","price":79630.91,"price_str":"79630.91","is_liquidation":false},"channel":"live_orders_btcusd","event":"order_deleted","event_id":"000659d4-cbac-db90-0002-000102000020","pre_event_id":"000659d4-cbac-db90-0001-000101000020","order_source":"orderbook"}
{"data":{"id":2043024863920128,"id_str":"2043024863920128","order_type":1,"order_subtype":5,"datetime":"1787620345","microtimestamp":"1787620345306000","amount":0.05,"amount_str":"0.05000000","amount_traded":"0","amount_at_create":"0.05000000","price":79650.9,"price_str":"79650.90","is_liquidation":false},"channel":"live_orders_btcusd","event":"order_deleted","event_id":"000659d4-cbac-db90-0003-000103000020","pre_event_id":"000659d4-cbac-db90-0002-000102000020","order_source":"orderbook"}
{"data":{"id":2043024878157831,"id_str":"2043024878157831","order_type":0,"order_subtype":5,"datetime":"1787620345","microtimestamp":"1787620345309000","amount":0.62793317,"amount_str":"0.62793317","amount_traded":"0","amount_at_create":"0.62793317","price":79604.62,"price_str":"79604.62","is_liquidation":false},"channel":"live_orders_btcusd","event":"order_deleted","event_id":"000659d4-cbac-e748-0000-000100000020","pre_event_id":"000659d4-cbac-db90-0003-000103000020","order_source":"orderbook"}
{"data":{"id":2043024878170117,"id_str":"2043024878170117","order_type":1,"order_subtype":5,"datetime":"1787620345","microtimestamp":"1787620345309000","amount":0.1,"amount_str":"0.10000000","amount_traded":"0","amount_at_create":"0.10000000","price":79640.88,"price_str":"79640.88","is_liquidation":false},"channel":"live_orders_btcusd","event":"order_deleted","event_id":"000659d4-cbac-e748-0001-000101000020","pre_event_id":"000659d4-cbac-e748-0000-000100000020","order_source":"orderbook"}
{"data":{"id":2043024878161924,"id_str":"2043024878161924","order_type":0,"order_subtype":5,"datetime":"1787620345","microtimestamp":"1787620345309000","amount":0.50234653,"amount_str":"0.50234653","amount_traded":"0","amount_at_create":"0.50234653","price":79602.63,"price_str":"79602.63","is_liquidation":false},"channel":"live_orders_btcusd","event":"order_deleted","event_id":"000659d4-cbac-e748-0002-000102000020","pre_event_id":"000659d4-cbac-e748-0001-000101000020","order_source":"orderbook"}
{"data":{"id":2043024878211073,"id_str":"2043024878211073","order_type":1,"order_subtype":5,"datetime":"1787620345","microtimestamp":"1787620345314000","amount":0.19,"amount_str":"0.19000000","amount_traded":"0","amount_at_create":"0.19000000","price":79640.88,"price_str":"79640.88","is_liquidation":false},"channel":"live_orders_btcusd","event":"order_created","event_id":"000659d4-cbac-fad0-0000-000103000020","pre_event_id":"000659d4-cbac-e748-0002-000102000020","order_source":"orderbook"}
{"data":{"id":2043024878211082,"id_str":"2043024878211082","order_type":0,"order_subtype":5,"datetime":"1787620345","microtimestamp":"1787620345315000","amount":0.18838361,"amount_str":"0.18838361","amount_traded":"0","amount_at_create":"0.18838361","price":79605.57,"price_str":"79605.57","is_liquidation":false},"channel":"live_orders_btcusd","event":"order_created","event_id":"000659d4-cbac-feb8-0000-000100000020","pre_event_id":"000659d4-cbac-fad0-0000-000103000020","order_source":"orderbook"}
{"data":{"id":2043024878219268,"id_str":"2043024878219268","order_type":0,"order_subtype":5,"datetime":"1787620345","microtimestamp":"1787620345316000","amount":0.62794536,"amount_str":"0.62794536","amount_traded":"0","amount_at_create":"0.62794536","price":79603.57,"price_str":"79603.57","is_liquidation":false},"channel":"live_orders_btcusd","event":"order_created","event_id":"000659d4-cbad-02a0-0000-000101000020","pre_event_id":"000659d4-cbac-feb8-0000-000100000020","order_source":"orderbook"}
{"data":{"id":2043024878223360,"id_str":"2043024878223360","order_type":0,"order_subtype":5,"datetime":"1787620345","microtimestamp":"1787620345317000","amount":0.50235629,"amount_str":"0.50235629","amount_traded":"0","amount_at_create":"0.50235629","price":79601.58,"price_str":"79601.58","is_liquidation":false},"channel":"live_orders_btcusd","event":"order_created","event_id":"000659d4-cbad-0688-0000-000102000020","pre_event_id":"000659d4-cbad-02a0-0000-000101000020","order_source":"orderbook"}
{"data":{"id":2043024878227465,"id_str":"2043024878227465","order_type":0,"order_subtype":5,"datetime":"1787620345","microtimestamp":"1787620345318000","amount":0.0646,"amount_str":"0.06460000","amount_traded":"0","amount_at_create":"0.06460000","price":79316.12,"price_str":"79316.12","is_liquidation":false},"channel":"live_orders_btcusd","event":"order_created","event_id":"000659d4-cbad-0a70-0000-000103000020","pre_event_id":"000659d4-cbad-0688-0000-000102000020","order_source":"orderbook"}
{"data":{"id":2043024878227470,"id_str":"2043024878227470","order_type":0,"order_subtype":5,"datetime":"1787620345","microtimestamp":"1787620345318000","amount":0.48956031,"amount_str":"0.48956031","amount_traded":"0","amount_at_create":"0.48956031","price":79604.36,"price_str":"79604.36","is_liquidation":false},"channel":"live_orders_btcusd","event":"order_created","event_id":"000659d4-cbad-0a70-0001-000100000020","pre_event_id":"000659d4-cbad-0a70-0000-000103000020","order_source":"orderbook"}
{"data":{"id":2043024878231553,"id_str":"2043024878231553","order_type":1,"order_subtype":5,"datetime":"1787620345","microtimestamp":"1787620345319000","amount":0.48956031,"amount_str":"0.48956031","amount_traded":"0","amount_at_create":"0.48956031","price":79630.92,"price_str":"79630.92","is_liquidation":false},"channel":"live_orders_btcusd","event":"order_created","event_id":"000659d4-cbad-0e58-0000-000101000020","pre_event_id":"000659d4-cbad-0a70-0001-000100000020","order_source":"orderbook"}
{"data":{"id":2043024866299905,"id_str":"2043024866299905","order_type":1,"order_subtype":5,"datetime":"1787620345","microtimestamp":"1787620345319000","amount":0.0860472,"amount_str":"0.08604720","amount_traded":"0","amount_at_create":"0.08604720","price":79630.92,"price_str":"79630.92","is_liquidation":false},"channel":"live_orders_btcusd","event":"order_deleted","event_id":"000659d4-cbad-0e58-0001-000102000020","pre_event_id":"000659d4-cbad-0e58-0000-000101000020","order_source":"orderbook"}
{"data":{"id":2043024878231560,"id_str":"2043024878231560","order_type":1,"order_subtype":5,"datetime":"1787620345","microtimestamp":"1787620345319000","amount":0.0860472,"amount_str":"0.08604720","amount_traded":"0","amount_at_create":"0.08604720","price":79630.92,"price_str":"79630.92","is_liquidation":false},"channel":"live_orders_btcusd","event":"order_created","event_id":"000659d4-cbad-0e58-0002-000103000020","pre_event_id":"000659d4-cbad-0e58-0001-000102000020","order_source":"orderbook"}
{"data":{"id":2043024878239747,"id_str":"2043024878239747","order_type":0,"order_subtype":5,"datetime":"1787620345","microtimestamp":"1787620345322000","amount":0.48956031,"amount_str":"0.48956031","amount_traded":"0","amount_at_create":"0.48956031","price":79596.39,"price_str":"79596.39","is_liquidation":false},"channel":"live_orders_btcusd","event":"order_created","event_id":"000659d4-cbad-1a10-0000-000100000020","pre_event_id":"000659d4-cbad-0e58-0002-000103000020","order_source":"orderbook"}
{"data":{"id":2043024878239760,"id_str":"2043024878239760","order_type":0,"order_subtype":5,"datetime":"1787620345","microtimestamp":"1787620345322000","amount":0.00143636,"amount_str":"0.00143636","amount_traded":"0","amount_at_create":"0.00143636","price":71672.31,"price_str":"71672.31","is_liquidation":false},"channel":"live_orders_btcusd","event":"order_created","event_id":"000659d4-cbad-1a10-0001-000101000020","pre_event_id":"000659d4-cbad-1a10-0000-000100000020","order_source":"orderbook"}
{"data":{"id":2043024878252038,"id_str":"2043024878252038","order_type":0,"order_subtype":5,"datetime":"1787620345","microtimestamp":"1787620345325000","amount":0.48956031,"amount_str":"0.48956031","amount_traded":"0","amount_at_create":"0.48956031","price":79588.42,"price_str":"79588.42","is_liquidation":false},"channel":"live_orders_btcusd","event":"order_created","event_id":"000659d4-cbad-25c8-0000-000102000020","pre_event_id":"000659d4-cbad-1a10-0001-000101000020","order_source":"orderbook"}
{"data":{"id":2043024878256128,"id_str":"2043024878256128","order_type":0,"order_subtype":5,"datetime":"1787620345","microtimestamp":"1787620345325000","amount":0.26349748,"amount_str":"0.26349748","amount_traded":"0","amount_at_create":"0.26349748","price":79582.22,"price_str":"79582.22","is_liquidation":false},"channel":"live_orders_btcusd","event":"order_created","event_id":"000659d4-cbad-25c8-0001-000103000020","pre_event_id":"000659d4-cbad-25c8-0000-000102000020","order_source":"orderbook"}
{"data":{"id":2043024878260233,"id_str":"2043024878260233","order_type":0,"order_subtype":5,"datetime":"1787620345","microtimestamp":"1787620345326000","amount":0.351464,"amount_str":"0.35146400","amount_traded":"0","amount_at_create":"0.35146400","price":79564.38,"price_str":"79564.38","is_liquidation":false},"channel":"live_orders_btcusd","event":"order_created","event_id":"000659d4-cbad-29b0-0000-000100000020","pre_event_id":"000659d4-cbad-25c8-0001-000103000020","order_source":"orderbook"}
{"data":{"id":2043024878211082,"id_str":"2043024878211082","order_type":0,"order_subtype":5,"datetime":"1787620345","microtimestamp":"1787620345327000","amount":0.18838361,"amount_str":"0.18838361","amount_traded":"0","amount_at_create":"0.18838361","price":79605.57,"price_str":"79605.57","is_liquidation":false},"channel":"live_orders_btcusd","event":"order_deleted","event_id":"000659d4-cbad-2d98-0000-000101000020","pre_event_id":"000659d4-cbad-29b0-0000-000100000020","order_source":"orderbook"}
{"data":{"id":2043024878219268,"id_str":"2043024878219268","order_type":0,"order_subtype":5,"datetime":"1787620345","microtimestamp":"1787620345328000","amount":0.62794536,"amount_str":"0.62794536","amount_traded":"0","amount_at_create":"0.62794536","price":79603.57,"price_str":"79603.57","is_liquidation":false},"channel":"live_orders_btcusd","event":"order_deleted","event_id":"000659d4-cbad-3180-0000-000102000020","pre_event_id":"000659d4-cbad-2d98-0000-000101000020","order_source":"orderbook"}
{"data":{"id":2043024878223360,"id_str":"2043024878223360","order_type":0,"order_subtype":5,"datetime":"1787620345","microtimestamp":"1787620345329000","amount":0.50235629,"amount_str":"0.50235629","amount_traded":"0","amount_at_create":"0.50235629","price":79601.58,"price_str":"79601.58","is_liquidation":false},"channel":"live_orders_btcusd","event":"order_deleted","event_id":"000659d4-cbad-3568-0000-000103000020","pre_event_id":"000659d4-cbad-3180-0000-000102000020","order_source":"orderbook"}
{"data":{"id":2043024878272516,"id_str":"2043024878272516","order_type":0,"order_subtype":5,"datetime":"1787620345","microtimestamp":"1787620345329000","amount":0.009037,"amount_str":"0.00903700","amount_traded":"0","amount_at_create":"0.00903700","price":79525.32,"price_str":"79525.32","is_liquidation":false},"channel":"live_orders_btcusd","event":"order_created","event_id":"000659d4-cbad-3568-0001-000100000020","pre_event_id":"000659d4-cbad-3568-0000-000103000020","order_source":"orderbook"}
{"data":{"id":2043024878288917,"id_str":"2043024878288917","order_type":1,"order_subtype":5,"datetime":"1787620345","microtimestamp":"1787620345334000","amount":1.25442582,"amount_str":"1.25442582","amount_traded":"0","amount_at_create":"1.25442582","price":79717.75,"price_str":"79717.75","is_liquidation":false},"channel":"live_orders_btcusd","event":"order_created","event_id":"000659d4-cbad-48f0-0000-000101000020","pre_event_id":"000659d4-cbad-3568-0001-000100000020","order_source":"orderbook"}
{"data":{"id":2043024850550788,"id_str":"2043024850550788","order_type":0,"order_subtype":5,"datetime":"1787620345","microtimestamp":"1787620345336000","amount":0.00163456,"amount_str":"0.00163456","amount_traded":"0","amount_at_create":"0.00163456","price":79589.73,"price_str":"79589.73","is_liquidation":false},"channel":"live_orders_btcusd","event":"order_deleted","event_id":"000659d4-cbad-50c0-0000-000102000020","pre_event_id":"000659d4-cbad-48f0-0000-000101000020","order_source":"orderbook"}
{"data":{"id":2043024863952899,"id_str":"2043024863952899","order_type":1,"order_subtype":5,"datetime":"1787620345","microtimestamp":"1787620345339000","amount":0.0217818,"amount_str":"0.02178180","amount_traded":"0","amount_at_create":"0.06278180","price":79640.91,"price_str":"79640.91","is_liquidation":false},"channel":"live_orders_btcusd","event":"order_deleted","event_id":"000659d4-cbad-5c78-0000-000103000020","pre_event_id":"000659d4-cbad-50c0-0000-000102000020","order_source":"orderbook"}
{"data":{"id":2043024878309392,"id_str":"2043024878309392","order_type":0,"order_subtype":5,"datetime":"1787620345","microtimestamp":"1787620345339000","amount":0.18838379,"amount_str":"0.18838379","amount_traded":"0","amount_at_create":"0.18838379","price":79604.71,"price_str":"79604.71","is_liquidation":false},"channel":"live_orders_btcusd","event":"order_created","event_id":"000659d4-cbad-5c78-0001-000100000020","pre_event_id":"000659d4-cbad-5c78-0000-000103000020","order_source":"orderbook"}
{"data":{"id":2043024850571271,"id_str":"2043024850571271","order_type":1,"order_subtype":5,"datetime":"1787620345","microtimestamp":"1787620345339000","amount":0.00163456,"amount_str":"0.00163456","amount_traded":"0","amount_at_create":"0.00163456","price":79717.18,"price_str":"79717.18","is_liquidation":false},"channel":"live_orders_btcusd","event":"order_deleted","event_id":"000659d4-cbad-5c78-0002-000101000020","pre_event_id":"000659d4-cbad-5c78-0001-000100000020","order_source":"orderbook"}
{"data":{"id":2043024864866308,"id_str":"2043024864866308","order_type":1,"order_subtype":5,"datetime":"1787620345","microtimestamp":"1787620345339000","amount":0.06277971,"amount_str":"0.06277971","amount_traded":"0","amount_at_create":"0.06277971","price":79643.57,"price_str":"79643.57","is_liquidation":false},"channel":"live_orders_btcusd","event":"order_deleted","event_id":"000659d4-cbad-5c78-0003-000102000020","pre_event_id":"000659d4-cbad-5c78-0002-000101000020","order_source":"orderbook"}
{"data":{"id":2043024868143106,"id_str":"2043024868143106","order_type":1,"order_subtype":5,"datetime":"1787620345","microtimestamp":"1787620345341000","amount":0.25109901,"amount_str":"0.25109901","amount_traded":"0","amount_at_create":"0.25109901","price":79649.86,"price_str":"79649.86","is_liquidation":false},"channel":"live_orders_btcusd","event":"order_deleted","event_id":"000659d4-cbad-6448-0000-000103000020","pre_event_id":"000659d4-cbad-5c78-0003-000102000020","order_source":"orderbook"}
{"data":{"id":2043024878317572,"id_str":"2043024878317572","order_type":0,"order_subtype":5,"datetime":"1787620345","microtimestamp":"1787620345341000","amount":0.62794599,"amount_str":"0.62794599","amount_traded":"0","amount_at_create":"0.62794599","price":79602.72,"price_str":"79602.72","is_liquidation":false},"channel":"live_orders_btcusd","event":"order_created","event_id":"000659d4-cbad-6448-0001-000100000020","pre_event_id":"000659d4-cbad-6448-0000-000103000020","order_source":"orderbook"}
{"data":{"id":2043024878321681,"id_str":"2043024878321681","order_type":0,"order_subtype":5,"datetime":"1787620345","microtimestamp":"1787620345342000","amount":0.50235679,"amount_str":"0.50235679","amount_traded":"0","amount_at_create":"0.50235679","price":79600.73,"price_str":"79600.73","is_liquidation":false},"channel":"live_orders_btcusd","event":"order_created","event_id":"000659d4-cbad-6830-0000-000101000020","pre_event_id":"000659d4-cbad-6448-0001-000100000020","order_source":"orderbook"}
{"data":{"id":2043024877940765,"id_str":"2043024877940765","order_type":1,"order_subtype":5,"datetime":"1787620345","microtimestamp":"1787620345342000","amount":0.25109124,"amount_str":"0.25109124","amount_traded":"0","amount_at_create":"0.25109124","price":79652.32,"price_str":"79652.32","is_liquidation":false},"channel":"live_orders_btcusd","event":"order_deleted","event_id":"000659d4-cbad-6830-0001-000102000020","pre_event_id":"000659d4-cbad-6830-0000-000101000020","order_source":"orderbook"}
{"data":{"id":2043024708149248,"id_str":"2043024708149248","order_type":0,"order_subtype":5,"datetime":"1787620345","microtimestamp":"1787620345346000","amount":0.007532,"amount_str":"0.00753200","amount_traded":"0","amount_at_create":"0.00753200","price":79513.99,"price_str":"79513.99","is_liquidation":false},"channel":"live_orders_btcusd","event":"order_deleted","event_id":"000659d4-cbad-77d0-0000-000103000020","pre_event_id":"000659d4-cbad-6830-0001-000102000020","order_source":"orderbook"}
{"data":{"id":2043024878358528,"id_str":"2043024878358528","order_type":0,"order_subtype":5,"datetime":"1787620345","microtimestamp":"1787620345350000","amount":0.00164224,"amount_str":"0.00164224","amount_traded":"0","amount_at_create":"0.00164224","price":79558.89,"price_str":"79558.89","is_liquidation":false},"channel":"live_orders_btcusd","event":"order_created","event_id":"000659d4-cbad-8770-0000-000100000020","pre_event_id":"000659d4-cbad-77d0-0000-000103000020","order_source":"orderbook"}
{"data":{"id":2043024878358555,"id_str":"2043024878358555","order_type":1,"order_subtype":5,"datetime":"1787620345","microtimestamp":"1787620345351000","amount":0.00164224,"amount_str":"0.00164224","amount_traded":"0","amount_at_create":"0.00164224","price":79686.3,"price_str":"79686.30","is_liquidation":false},"channel":"live_orders_btcusd","event":"order_created","event_id":"000659d4-cbad-8b58-0000-000101000020","pre_event_id":"000659d4-cbad-8770-0000-000100000020","order_source":"orderbook"}
{"data":{"id":2043024878239760,"id_str":"2043024878239760","order_type":0,"order_subtype":5,"datetime":"1787620345","microtimestamp":"1787620345354000","amount":0.00143636,"amount_str":"0.00143636","amount_traded":"0","amount_at_create":"0.00143636","price":71672.31,"price_str":"71672.31","is_liquidation":false},"channel":"live_orders_btcusd","event":"order_deleted","event_id":"000659d4-cbad-9710-0000-000102000020","pre_event_id":"000659d4-cbad-8b58-0000-000101000020","order_source":"orderbook"}
{"data":{"id":2043024878211073,"id_str":"2043024878211073","order_type":1,"order_subtype":5,"datetime":"1787620345","microtimestamp":"1787620345359000","amount":0.19,"amount_str":"0.19000000","amount_traded":"0","amount_at_create":"0.19000000","price":79640.88,"price_str":"79640.88","is_liquidation":false},"channel":"live_orders_btcusd","event":"order_deleted","event_id":"000659d4-cbad-aa98-0000-000103000020","pre_event_id":"000659d4-cbad-9710-0000-000102000020","order_source":"orderbook"}
{"data":{"id":2043024878403584,"id_str":"2043024878403584","order_type":1,"order_subtype":5,"datetime":"1787620345","microtimestamp":"1787620345361000","amount":0.1,"amount_str":"0.10000000","amount_traded":"0","amount_at_create":"0.10000000","price":79632.06,"price_str":"79632.06","is_liquidation":false},"channel":"live_orders_btcusd","event":"order_created","event_id":"000659d4-cbad-b268-0000-000100000020","pre_event_id":"000659d4-cbad-aa98-0000-000103000020","order_source":"orderbook"}
{"data":{"id":2043024878407685,"id_str":"2043024878407685","order_type":0,"order_subtype":5,"datetime":"1787620345","microtimestamp":"1787620345362000","amount":0.5,"amount_str":"0.50000000","amount_traded":"0","amount_at_create":"0.50000000","price":79621.96,"price_str":"79621.96","is_liquidation":false},"channel":"live_orders_btcusd","event":"order_created","event_id":"000659d4-cbad-b650-0000-000101000020","pre_event_id":"000659d4-cbad-b268-0000-000100000020","order_source":"orderbook"}
{"data":{"id":2043024878407686,"id_str":"2043024878407686","order_type":1,"order_subtype":5,"datetime":"1787620345","microtimestamp":"1787620345362000","amount":0.1,"amount_str":"0.10000000","amount_traded":"0","amount_at_create":"0.10000000","price":79634.1,"price_str":"79634.10","is_liquidation":false},"channel":"live_orders_btcusd","event":"order_created","event_id":"000659d4-cbad-b650-0001-000102000020","pre_event_id":"000659d4-cbad-b650-0000-000101000020","order_source":"orderbook"}
{"data":{"id":2043024878407693,"id_str":"2043024878407693","order_type":1,"order_subtype":5,"datetime":"1787620345","microtimestamp":"1787620345363000","amount":0.5,"amount_str":"0.50000000","amount_traded":"0","amount_at_create":"0.50000000","price":79630.92,"price_str":"79630.92","is_liquidation":false},"channel":"live_orders_btcusd","event":"order_created","event_id":"000659d4-cbad-ba38-0000-000103000020","pre_event_id":"000659d4-cbad-b650-0001-000102000020","order_source":"orderbook"}
{"data":{"id":2043024878407695,"id_str":"2043024878407695","order_type":0,"order_subtype":5,"datetime":"1787620345","microtimestamp":"1787620345363000","amount":0.25,"amount_str":"0.25000000","amount_traded":"0","amount_at_create":"0.25000000","price":79625.94,"price_str":"79625.94","is_liquidation":false},"channel":"live_orders_btcusd","event":"order_created","event_id":"000659d4-cbad-ba38-0001-000100000020","pre_event_id":"000659d4-cbad-ba38-0000-000103000020","order_source":"orderbook"}
{"data":{"id":2043024878407700,"id_str":"2043024878407700","order_type":1,"order_subtype":5,"datetime":"1787620345","microtimestamp":"1787620345363000","amount":0.1,"amount_str":"0.10000000","amount_traded":"0","amount_at_create":"0.10000000","price":79636.14,"price_str":"79636.14","is_liquidation":false},"channel":"live_orders_btcusd","event":"order_created","event_id":"000659d4-cbad-ba38-0002-000101000020","pre_event_id":"000659d4-cbad-ba38-0001-000100000020","order_source":"orderbook"}
{"data":{"id":2043024878411791,"id_str":"2043024878411791","order_type":1,"order_subtype":5,"datetime":"1787620345","microtimestamp":"1787620345364000","amount":0.1,"amount_str":"0.10000000","amount_traded":"0","amount_at_create":"0.10000000","price":79630.91,"price_str":"79630.91","is_liquidation":false},"channel":"live_orders_btcusd","event":"order_created","event_id":"000659d4-cbad-be20-0000-000102000020","pre_event_id":"000659d4-cbad-ba38-0002-000101000020","order_source":"orderbook"}
{"data":{"id":2043024878411794,"id_str":"2043024878411794","order_type":1,"order_subtype":5,"datetime":"1787620345","microtimestamp":"1787620345364000","amount":0.1,"amount_str":"0.10000000","amount_traded":"0","amount_at_create":"0.10000000","price":79630.9,"price_str":"79630.90","is_liquidation":false},"channel":"live_orders_btcusd","event":"order_created","event_id":"000659d4-cbad-be20-0001-000103000020","pre_event_id":"000659d4-cbad-be20-0000-000102000020","order_source":"orderbook"}
{"data":{"id":2043024878415877,"id_str":"2043024878415877","order_type":1,"order_subtype":5,"datetime":"1787620345","microtimestamp":"1787620345364000","amount":0.25,"amount_str":"0.25000000","amount_traded":"0","amount_at_create":"0.25000000","price":79630.92,"price_str":"79630.92","is_liquidation":false},"channel":"live_orders_btcusd","event":"order_created","event_id":"000659d4-cbad-be20-0002-000100000020","pre_event_id":"000659d4-cbad-be20-0001-000103000020","order_source":"orderbook"}
{"data":{"id":2043024878415881,"id_str":"2043024878415881","order_type":1,"order_subtype":5,"datetime":"1787620345","microtimestamp":"1787620345365000","amount":0.1,"amount_str":"0.10000000","amount_traded":"0","amount_at_create":"0.10000000","price":79638.18,"price_str":"79638.18","is_liquidation":false},"channel":"live_orders_btcusd","event":"order_created","event_id":"000659d4-cbad-c208-0000-000101000020","pre_event_id":"000659d4-cbad-be20-0002-000100000020","order_source":"orderbook"}
{"data":{"id":2043024878149633,"id_str":"2043024878149633","order_type":1,"order_subtype":5,"datetime":"1787620345","microtimestamp":"1787620345368000","amount":0.1,"amount_str":"0.10000000","amount_traded":"0","amount_at_create":"0.10000000","price":79640.87,"price_str":"79640.87","is_liquidation":false},"channel":"live_orders_btcusd","event":"order_deleted","event_id":"000659d4-cbad-cdc0-0000-000102000020","pre_event_id":"000659d4-cbad-c208-0000-000101000020","order_source":"orderbook"}
{"data":{"id":2043024878432261,"id_str":"2043024878432261","order_type":0,"order_subtype":0,"datetime":"1787620345","microtimestamp":"1787620345368000","amount":0.00049029,"amount_str":"0.00049029","amount_traded":"0","amount_at_create":"0.00049029","price":78775.17,"price_str":"78775.17","is_liquidation":false},"channel":"live_orders_btcusd","event":"order_created","event_id":"000659d4-cbad-cdc0-0001-000103000020","pre_event_id":"000659d4-cbad-cdc0-0000-000102000020","order_source":"orderbook"}
{"data":{"id":2043024878411791,"id_str":"2043024878411791","order_type":1,"order_subtype":5,"datetime":"1787620345","microtimestamp":"1787620345369000","amount":0.1,"amount_str":"0.10000000","amount_traded":"0","amount_at_create":"0.10000000","price":79630.91,"price_str":"79630.91","is_liquidation":false},"channel":"live_orders_btcusd","event":"order_deleted","event_id":"000659d4-cbad-d1a8-0000-000100000020","pre_event_id":"000659d4-cbad-cdc0-0001-000103000020","order_source":"orderbook"}
{"data":{"id":2043024878415877,"id_str":"2043024878415877","order_type":1,"order_subtype":5,"datetime":"1787620345","microtimestamp":"1787620345371000","amount":0.25,"amount_str":"0.25000000","amount_traded":"0","amount_at_create":"0.25000000","price":79630.92,"price_str":"79630.92","is_liquidation":false},"channel":"live_orders_btcusd","event":"order_deleted","event_id":"000659d4-cbad-d978-0000-000101000020","pre_event_id":"000659d4-cbad-d1a8-0000-000100000020","order_source":"orderbook"}
{"data":{"id":2043024862375939,"id_str":"2043024862375939","order_type":1,"order_subtype":5,"datetime":"1787620345","microtimestamp":"1787620345372000","amount":0.06275933,"amount_str":"0.06275933","amount_traded":"0","amount_at_create":"0.06275933","price":79649.38,"price_str":"79649.38","is_liquidation":false},"channel":"live_orders_btcusd","event":"order_deleted","event_id":"000659d4-cbad-dd60-0000-000102000020","pre_event_id":"000659d4-cbad-d978-0000-000101000020","order_source":"orderbook"}
{"data":{"id":2043024878407693,"id_str":"2043024878407693","order_type":1,"order_subtype":5,"datetime":"1787620345","microtimestamp":"1787620345372000","amount":0.5,"amount_str":"0.50000000","amount_traded":"0","amount_at_create":"0.50000000","price":79630.92,"price_str":"79630.92","is_liquidation":false},"channel":"live_orders_btcusd","event":"order_deleted","event_id":"000659d4-cbad-dd60-0001-000103000020","pre_event_id":"000659d4-cbad-dd60-0000-000102000020","order_source":"orderbook"}
{"data":{"id":2043024878452744,"id_str":"2043024878452744","order_type":1,"order_subtype":5,"datetime":"1787620345","microtimestamp":"1787620345373000","amount":0.25113082,"amount_str":"0.25113082","amount_traded":"0","amount_at_create":"0.25113082","price":79639.77,"price_str":"79639.77","is_liquidation":false},"channel":"live_orders_btcusd","event":"order_created","event_id":"000659d4-cbad-e148-0000-000100000020","pre_event_id":"000659d4-cbad-dd60-0001-000103000020","order_source":"orderbook"}
{"data":{"id":2043024878452746,"id_str":"2043024878452746","order_type":1,"order_subtype":5,"datetime":"1787620345","microtimestamp":"1787620345373000","amount":0.19,"amount_str":"0.19000000","amount_traded":"0","amount_at_create":"0.19000000","price":79630.92,"price_str":"79630.92","is_liquidation":false},"channel":"live_orders_btcusd","event":"order_created","event_id":"000659d4-cbad-e148-0001-000101000020","pre_event_id":"000659d4-cbad-e148-0000-000100000020","order_source":"orderbook"}
{"data":{"id":2043024878452753,"id_str":"2043024878452753","order_type":1,"order_subtype":5,"datetime":"1787620345","microtimestamp":"1787620345374000","amount":0.25115301,"amount_str":"0.25115301","amount_traded":"0","amount_at_create":"0.25115301","price":79632.73,"price_str":"79632.73","is_liquidation":false},"channel":"live_orders_btcusd","event":"order_created","event_id":"000659d4-cbad-e530-0000-000102000020","pre_event_id":"000659d4-cbad-e148-0001-000101000020","order_source":"orderbook"}
{"data":{"id":2043024878452756,"id_str":"2043024878452756","order_type":1,"order_subtype":5,"datetime":"1787620345","microtimestamp":"1787620345374000","amount":0.06279282,"amount_str":"0.06279282","amount_traded":"0","amount_at_create":"0.06279282","price":79626.93,"price_str":"79626.93","is_liquidation":false},"channel":"live_orders_btcusd","event":"order_created","event_id":"000659d4-cbad-e530-0001-000103000020","pre_event_id":"000659d4-cbad-e530-0000-000102000020","order_source":"orderbook"}
{"data":{"id":2043024877928448,"id_str":"2043024877928448","order_type":0,"order_subtype":0,"datetime":"1787620345","microtimestamp":"1787620345374000","amount":0.06275933,"amount_str":"0.06275933","amount_traded":"0","amount_at_create":"0.06275933","price":79567.87,"price_str":"79567.87","is_liquidation":false},"channel":"live_orders_btcusd","event":"order_deleted","event_id":"000659d4-cbad-e530-0002-000100000020","pre_event_id":"000659d4-cbad-e530-0001-000103000020","order_source":"orderbook"}
{"data":{"id":2043024878407695,"id_str":"2043024878407695","order_type":0,"order_subtype":5,"datetime":"1787620345","microtimestamp":"1787620345376000","amount":0.25,"amount_str":"0.25000000","amount_traded":"0","amount_at_create":"0.25000000","price":79625.94,"price_str":"79625.94","is_liquidation":false},"channel":"live_orders_btcusd","event":"order_deleted","event_id":"000659d4-cbad-ed00-0000-000101000020","pre_event_id":"000659d4-cbad-e530-0002-000100000020","order_source":"orderbook"}
{"data":{"id":2043024878465026,"id_str":"2043024878465026","order_type":0,"order_subtype":5,"datetime":"1787620345","microtimestamp":"1787620345376000","amount":0.64019425,"amount_str":"0.64019425","amount_traded":"0","amount_at_create":"0.64019425","price":79500,"price_str":"79500.00","is_liquidation":false},"channel":"live_orders_btcusd","event":"order_created","event_id":"000659d4-cbad-ed00-0001-000102000020","pre_event_id":"000659d4-cbad-ed00-0000-000101000020","order_source":"orderbook"}
{"data":{"id":2043024878407685,"id_str":"2043024878407685","order_type":0,"order_subtype":5,"datetime":"1787620345","microtimestamp":"1787620345377000","amount":0.5,"amount_str":"0.50000000","amount_traded":"0","amount_at_create":"0.50000000","price":79621.96,"price_str":"79621.96","is_liquidation":false},"channel":"live_orders_btcusd","event":"order_deleted","event_id":"000659d4-cbad-f0e8-0000-000103000020","pre_event_id":"000659d4-cbad-ed00-0001-000102000020","order_source":"orderbook"}
{"data":{"id":2043024878473219,"id_str":"2043024878473219","order_type":1,"order_subtype":5,"datetime":"1787620345","microtimestamp":"1787620345378000","amount":0.06278971,"amount_str":"0.06278971","amount_traded":"0","amount_at_create":"0.06278971","price":79630.88,"price_str":"79630.88","is_liquidation":false},"channel":"live_orders_btcusd","event":"order_created","event_id":"000659d4-cbad-f4d0-0000-000100000020","pre_event_id":"000659d4-cbad-f0e8-0000-000103000020","order_source":"orderbook"}
{"data":{"id":2043024878481415,"id_str":"2043024878481415","order_type":0,"order_subtype":5,"datetime":"1787620345","microtimestamp":"1787620345380000","amount":0.00251287,"amount_str":"0.00251287","amount_traded":"0","amount_at_create":"0.00251287","price":79590.31,"price_str":"79590.31","is_liquidation":false},"channel":"live_orders_btcusd","event":"order_created","event_id":"000659d4-cbad-fca0-0000-000101000020","pre_event_id":"000659d4-cbad-f4d0-0000-000100000020","order_source":"orderbook"}
{"data":{"id":2043024878493698,"id_str":"2043024878493698","order_type":1,"order_subtype":5,"datetime":"1787620345","microtimestamp":"1787620345383000","amount":0.06275933,"amount_str":"0.06275933","amount_traded":"0","amount_at_create":"0.06275933","price":79626.93,"price_str":"79626.93","is_liquidation":false},"channel":"live_orders_btcusd","event":"order_created","event_id":"000659d4-cbae-0858-0000-000102000020","pre_event_id":"000659d4-cbad-fca0-0000-000101000020","order_source":"orderbook"}
{"data":{"id":2043024878497800,"id_str":"2043024878497800","order_type":0,"order_subtype":0,"datetime":"1787620345","microtimestamp":"1787620345385000","amount":0.06275933,"amount_str":"0.06275933","amount_traded":"0","amount_at_create":"0.06275933","price":79601.59,"price_str":"79601.59","is_liquidation":false},"channel":"live_orders_btcusd","event":"order_created","event_id":"000659d4-cbae-1028-0000-000103000020","pre_event_id":"000659d4-cbae-0858-0000-000102000020","order_source":"orderbook"}
{"data":{"id":2043024878481415,"id_str":"2043024878481415","order_type":0,"order_subtype":5,"datetime":"1787620345","microtimestamp":"1787620345386000","amount":0.00251287,"amount_str":"0.00251287","amount_traded":"0","amount_at_create":"0.00251287","price":79590.31,"price_str":"79590.31","is_liquidation":false},"channel":"live_orders_btcusd","event":"order_deleted","event_id":"000659d4-cbae-1410-0000-000100000020","pre_event_id":"000659d4-cbae-1028-0000-000103000020","order_source":"orderbook"}
{"data":{"id":2043024878514186,"id_str":"2043024878514186","order_type":0,"order_subtype":5,"datetime":"1787620345","microtimestamp":"1787620345388000","amount":0.81593385,"amount_str":"0.81593385","amount_traded":"0","amount_at_create":"0.81593385","price":79581.58,"price_str":"79581.58","is_liquidation":false},"channel":"live_orders_btcusd","event":"order_created","event_id":"000659d4-cbae-1be0-0000-000101000020","pre_event_id":"000659d4-cbae-1410-0000-000100000020","order_source":"orderbook"}
{"data":{"id":2043024878309392,"id_str":"2043024878309392","order_type":0,"order_subtype":5,"datetime":"1787620345","microtimestamp":"1787620345389000","amount":0.18838379,"amount_str":"0.18838379","amount_traded":"0","amount_at_create":"0.18838379","price":79604.71,"price_str":"79604.71","is_liquidation":false},"channel":"live_orders_btcusd","event":"order_deleted","event_id":"000659d4-cbae-1fc8-0000-000102000020","pre_event_id":"000659d4-cbae-1be0-0000-000101000020","order_source":"orderbook"}
{"data":{"id":2043024878518281,"id_str":"2043024878518281","order_type":0,"order_subtype":5,"datetime":"1787620345","microtimestamp":"1787620345389000","amount":0.110039,"amount_str":"0.11003900","amount_traded":"0","amount_at_create":"0.11003900","price":79581.03,"price_str":"79581.03","is_liquidation":false},"channel":"live_orders_btcusd","event":"order_created","event_id":"000659d4-cbae-1fc8-0001-000103000020","pre_event_id":"000659d4-cbae-1fc8-0000-000102000020","order_source":"orderbook"}
{"data":{"id":2043024878415881,"id_str":"2043024878415881","order_type":1,"order_subtype":5,"datetime":"1787620345","microtimestamp":"1787620345394000","amount":0.1,"amount_str":"0.10000000","amount_traded":"0","amount_at_create":"0.10000000","price":79638.18,"price_str":"79638.18","is_liquidation":false},"channel":"live_orders_btcusd","event":"order_deleted","event_id":"000659d4-cbae-3350-0000-000100000020","pre_event_id":"000659d4-cbae-1fc8-0001-000103000020","order_source":"orderbook"}
{"data":{"id":2043024878559232,"id_str":"2043024878559232","order_type":0,"order_subtype":5,"datetime":"1787620345","microtimestamp":"1787620345399000","amount":0.18838816,"amount_str":"0.18838816","amount_traded":"0","amount_at_create":"0.18838816","price":79606.36,"price_str":"79606.36","is_liquidation":false},"channel":"live_orders_btcusd","event":"order_created","event_id":"000659d4-cbae-46d8-0000-000101000020","pre_event_id":"000659d4-cbae-3350-0000-000100000020","order_source":"orderbook"}
{"data":{"id":2043024878563329,"id_str":"2043024878563329","order_type":0,"order_subtype":5,"datetime":"1787620345","microtimestamp":"1787620345400000","amount":0.00143636,"amount_str":"0.00143636","amount_traded":"0","amount_at_create":"0.00143636","price":71666.03,"price_str":"71666.03","is_liquidation":false},"channel":"live_orders_btcusd","event":"order_created","event_id":"000659d4-cbae-4ac0-0000-000102000020","pre_event_id":"000659d4-cbae-46d8-0000-000101000020","order_source":"orderbook"}
{"data":{"id":2043024878567429,"id_str":"2043024878567429","order_type":1,"order_subtype":5,"datetime":"1787620345","microtimestamp":"1787620345401000","amount":0.1,"amount_str":"0.10000000","amount_traded":"0","amount_at_create":"0.10000000","price":79631.99,"price_str":"79631.99","is_liquidation":false},"channel":"live_orders_btcusd","event":"order_created","event_id":"000659d4-cbae-4ea8-0000-000103000020","pre_event_id":"000659d4-cbae-4ac0-0000-000102000020","order_source":"orderbook"}
{"data":{"id":2043024878559232,"id_str":"2043024878559232","order_type":0,"order_subtype":5,"datetime":"1787620345","microtimestamp":"1787620345402000","amount":0.18838816,"amount_str":"0.18838816","amount_traded":"0","amount_at_create":"0.18838816","price":79606.36,"price_str":"79606.36","is_liquidation":false},"channel":"live_orders_btcusd","event":"order_deleted","event_id":"000659d4-cbae-5290-0000-000100000020","pre_event_id":"000659d4-cbae-4ea8-0000-000103000020","order_source":"orderbook"}
{"data":{"id":2043024878571536,"id_str":"2043024878571536","order_type":0,"order_subtype":5,"datetime":"1787620345","microtimestamp":"1787620345403000","amount":0.19,"amount_str":"0.19000000","amount_traded":"0","amount_at_create":"0.19000000","price":79626.93,"price_str":"79626.93","is_liquidation":false},"channel":"live_orders_btcusd","event":"order_created","event_id":"000659d4-cbae-5678-0000-000101000020","pre_event_id":"000659d4-cbae-5290-0000-000100000020","order_source":"orderbook"}
{"data":{"id":2043024878571536,"id_str":"2043024878571536","order_type":0,"order_subtype":5,"datetime":"1787620345","microtimestamp":"1787620345403000","amount":0.19,"amount_str":"0.19000000","amount_traded":"0","amount_at_create":"0.19000000","price":79626.93,"price_str":"79626.93","is_liquidation":false},"channel":"live_orders_btcusd","event":"order_deleted","event_id":"000659d4-cbae-5678-0001-000102000020","pre_event_id":"000659d4-cbae-5678-0000-000101000020","order_source":"orderbook"}
{"data":{"id":2043024878575617,"id_str":"2043024878575617","order_type":0,"order_subtype":5,"datetime":"1787620345","microtimestamp":"1787620345403000","amount":0.18838819,"amount_str":"0.18838819","amount_traded":"0","amount_at_create":"0.18838819","price":79604.21,"price_str":"79604.21","is_liquidation":false},"channel":"live_orders_btcusd","event":"order_created","event_id":"000659d4-cbae-5678-0002-000103000020","pre_event_id":"000659d4-cbae-5678-0001-000102000020","order_source":"orderbook"}
{"data":{"id":2043024769773577,"id_str":"2043024769773577","order_type":1,"order_subtype":5,"datetime":"1787620345","microtimestamp":"1787620345404000","amount":0.00252108,"amount_str":"0.00252108","amount_traded":"0","amount_at_create":"0.00252108","price":79712.52,"price_str":"79712.52","is_liquidation":false},"channel":"live_orders_btcusd","event":"order_deleted","event_id":"000659d4-cbae-5a60-0000-000100000020","pre_event_id":"000659d4-cbae-5678-0002-000103000020","order_source":"orderbook"}
{"data":{"id":2043024878673922,"id_str":"2043024878673922","order_type":0,"order_subtype":5,"datetime":"1787620345","microtimestamp":"1787620345427000","amount":0.007531,"amount_str":"0.00753100","amount_traded":"0","amount_at_create":"0.00753100","price":79468.1,"price_str":"79468.10","is_liquidation":false},"channel":"live_orders_btcusd","event":"order_created","event_id":"000659d4-cbae-b438-0000-000101000020","pre_event_id":"000659d4-cbae-5a60-0000-000100000020","order_source":"orderbook"}
{"data":{"id":2043024878702600,"id_str":"2043024878702600","order_type":0,"order_subtype":5,"datetime":"1787620345","microtimestamp":"1787620345434000","amount":0.00251224,"amount_str":"0.00251224","amount_traded":"0","amount_at_create":"0.00251224","price":79610.27,"price_str":"79610.27","is_liquidation":false},"channel":"live_orders_btcusd","event":"order_created","event_id":"000659d4-cbae-cf90-0000-000102000020","pre_event_id":"000659d4-cbae-b438-0000-000101000020","order_source":"orderbook"}
{"data":{"id":2043024878407700,"id_str":"2043024878407700","order_type":1,"order_subtype":5,"datetime":"1787620345","microtimestamp":"1787620345435000","amount":0.1,"amount_str":"0.10000000","amount_traded":"0","amount_at_create":"0.10000000","price":79636.14,"price_str":"79636.14","is_liquidation":false},"channel":"live_orders_btcusd","event":"order_deleted","event_id":"000659d4-cbae-d378-0000-000103000020","pre_event_id":"000659d4-cbae-cf90-0000-000102000020","order_source":"orderbook"}
{"data":{"id":2043024878563329,"id_str":"2043024878563329","order_type":0,"order_subtype":5,"datetime":"1787620345","microtimestamp":"1787620345436000","amount":0.00143636,"amount_str":"0.00143636","amount_traded":"0","amount_at_create":"0.00143636","price":71666.03,"price_str":"71666.03","is_liquidation":false},"channel":"live_orders_btcusd","event":"order_deleted","event_id":"000659d4-cbae-d760-0000-000100000020","pre_event_id":"000659d4-cbae-d378-0000-000103000020","order_source":"orderbook"}
{"data":{"id":2043024878411794,"id_str":"2043024878411794","order_type":1,"order_subtype":5,"datetime":"1787620345","microtimestamp":"1787620345437000","amount":0.1,"amount_str":"0.10000000","amount_traded":"0","amount_at_create":"0.10000000","price":79630.9,"price_str":"79630.90","is_liquidation":false},"channel":"live_orders_btcusd","event":"order_deleted","event_id":"000659d4-cbae-db48-0000-000101000020","pre_event_id":"000659d4-cbae-d760-0000-000100000020","order_source":"orderbook"}
{"data":{"id":2043024863301639,"id_str":"2043024863301639","order_type":1,"order_subtype":5,"datetime":"1787620345","microtimestamp":"1787620345440000","amount":0.110049,"amount_str":"0.11004900","amount_traded":"0","amount_at_create":"0.11004900","price":79640.92,"price_str":"79640.92","is_liquidation":false},"channel":"live_orders_btcusd","event":"order_deleted","event_id":"000659d4-cbae-e700-0000-000102000020","pre_event_id":"000659d4-cbae-db48-0000-000101000020","order_source":"orderbook"}
{"data":{"id":2043024878731265,"id_str":"2043024878731265","order_type":1,"order_subtype":5,"datetime":"1787620345","microtimestamp":"1787620345441000","amount":0.1,"amount_str":"0.10000000","amount_traded":"0","amount_at_create":"0.10000000","price":79631.91,"price_str":"79631.91","is_liquidation":false},"channel":"live_orders_btcusd","event":"order_created","event_id":"000659d4-cbae-eae8-0000-000103000020","pre_event_id":"000659d4-cbae-e700-0000-000102000020","order_source":"orderbook"}
{"data":{"id":2043024878735363,"id_str":"2043024878735363","order_type":0,"order_subtype":5,"datetime":"1787620345","microtimestamp":"1787620345442000","amount":0.05,"amount_str":"0.05000000","amount_traded":"0","amount_at_create":"0.05000000","price":79616.93,"price_str":"79616.93","is_liquidation":false},"channel":"live_orders_btcusd","event":"order_created","event_id":"000659d4-cbae-eed0-0000-000100000020","pre_event_id":"000659d4-cbae-eae8-0000-000103000020","order_source":"orderbook"}
{"data":{"id":2043024878735361,"id_str":"2043024878735361","order_type":1,"order_subtype":5,"datetime":"1787620345","microtimestamp":"1787620345442000","amount":0.5,"amount_str":"0.50000000","amount_traded":"0","amount_at_create":"0.50000000","price":79628.89,"price_str":"79628.89","is_liquidation":false},"channel":"live_orders_btcusd","event":"order_created","event_id":"000659d4-cbae-eed0-0001-000101000020","pre_event_id":"000659d4-cbae-eed0-0000-000100000020","order_source":"orderbook"}
{"data":{"id":2043024878735368,"id_str":"2043024878735368","order_type":1,"order_subtype":5,"datetime":"1787620345","microtimestamp":"1787620345443000","amount":0.1,"amount_str":"0.10000000","amount_traded":"0","amount_at_create":"0.10000000","price":79630.91,"price_str":"79630.91","is_liquidation":false},"channel":"live_orders_btcusd","event":"order_created","event_id":"000659d4-cbae-f2b8-0000-000102000020","pre_event_id":"000659d4-cbae-eed0-0001-000101000020","order_source":"orderbook"}
{"data":{"id":2043024878739459,"id_str":"2043024878739459","order_type":1,"order_subtype":5,"datetime":"1787620345","microtimestamp":"1787620345443000","amount":0.25,"amount_str":"0.25000000","amount_traded":"0","amount_at_create":"0.25000000","price":79626.93,"price_str":"79626.93","is_liquidation":false},"channel":"live_orders_btcusd","event":"order_created","event_id":"000659d4-cbae-f2b8-0001-000103000020","pre_event_id":"000659d4-cbae-f2b8-0000-000102000020","order_source":"orderbook"}
{"data":{"id":2043024878739463,"id_str":"2043024878739463","order_type":0,"order_subtype":5,"datetime":"1787620345","microtimestamp":"1787620345444000","amount":0.5,"amount_str":"0.50000000","amount_traded":"0","amount_at_create":"0.50000000","price":79620.92,"price_str":"79620.92","is_liquidation":false},"channel":"live_orders_btcusd","event":"order_created","event_id":"000659d4-cbae-f6a0-0000-000100000020","pre_event_id":"000659d4-cbae-f2b8-0001-000103000020","order_source":"orderbook"}
{"data":{"id":2043024878739464,"id_str":"2043024878739464","order_type":0,"order_subtype":5,"datetime":"1787620345","microtimestamp":"1787620345444000","amount":0.25,"amount_str":"0.25000000","amount_traded":"0","amount_at_create":"0.25000000","price":79624.9,"price_str":"79624.90","is_liquidation":false},"channel":"live_orders_btcusd","event":"order_created","event_id":"000659d4-cbae-f6a0-0001-000101000020","pre_event_id":"000659d4-cbae-f6a0-0000-000100000020","order_source":"orderbook"}
{"data":{"id":2043024878743552,"id_str":"2043024878743552","order_type":1,"order_subtype":5,"datetime":"1787620345","microtimestamp":"1787620345444000","amount":0.1,"amount_str":"0.10000000","amount_traded":"0","amount_at_create":"0.10000000","price":79630.89,"price_str":"79630.89","is_liquidation":false},"channel":"live_orders_btcusd","event":"order_created","event_id":"000659d4-cbae-f6a0-0002-000102000020","pre_event_id":"000659d4-cbae-f6a0-0001-000101000020","order_source":"orderbook"}
{"data":{"id":2043024878743554,"id_str":"2043024878743554","order_type":1,"order_subtype":5,"datetime":"1787620345","microtimestamp":"1787620345445000","amount":0.1,"amount_str":"0.10000000","amount_traded":"0","amount_at_create":"0.10000000","price":79630.88,"price_str":"79630.88","is_liquidation":false},"channel":"live_orders_btcusd","event":"order_created","event_id":"000659d4-cbae-fa88-0000-000103000020","pre_event_id":"000659d4-cbae-f6a0-0002-000102000020","order_source":"orderbook"}
{"data":{"id":2043024878452746,"id_str":"2043024878452746","order_type":1,"order_subtype":5,"datetime":"1787620345","microtimestamp":"1787620345445000","amount":0.19,"amount_str":"0.19000000","amount_traded":"0","amount_at_create":"0.19000000","price":79630.92,"price_str":"79630.92","is_liquidation":false},"channel":"live_orders_btcusd","event":"order_deleted","event_id":"000659d4-cbae-fa88-0001-000100000020","pre_event_id":"000659d4-cbae-fa88-0000-000103000020","order_source":"orderbook"}
{"data":{"id":2043024878735368,"id_str":"2043024878735368","order_type":1,"order_subtype":5,"datetime":"1787620345","microtimestamp":"1787620345446000","amount":0.1,"amount_str":"0.10000000","amount_traded":"0","amount_at_create":"0.10000000","price":79630.91,"price_str":"79630.91","is_liquidation":false},"channel":"live_orders_btcusd","event":"order_deleted","event_id":"000659d4-cbae-fe70-0000-000101000020","pre_event_id":"000659d4-cbae-fa88-0001-000100000020","order_source":"orderbook"}
{"data":{"id":2043024878739464,"id_str":"2043024878739464","order_type":0,"order_subtype":5,"datetime":"1787620345","microtimestamp":"1787620345447000","amount":0.25,"amount_str":"0.25000000","amount_traded":"0","amount_at_create":"0.25000000","price":79624.9,"price_str":"79624.90","is_liquidation":false},"channel":"live_orders_btcusd","event":"order_deleted","event_id":"000659d4-cbaf-0258-0000-000102000020","pre_event_id":"000659d4-cbae-fe70-0000-000101000020","order_source":"orderbook"}
{"data":{"id":2043024878743552,"id_str":"2043024878743552","order_type":1,"order_subtype":5,"datetime":"1787620345","microtimestamp":"1787620345447000","amount":0.1,"amount_str":"0.10000000","amount_traded":"0","amount_at_create":"0.10000000","price":79630.89,"price_str":"79630.89","is_liquidation":false},"channel":"live_orders_btcusd","event":"order_deleted","event_id":"000659d4-cbaf-0258-0001-000103000020","pre_event_id":"000659d4-cbaf-0258-0000-000102000020","order_source":"orderbook"}
{"data":{"id":2043024878739463,"id_str":"2043024878739463","order_type":0,"order_subtype":5,"datetime":"1787620345","microtimestamp":"1787620345447000","amount":0.5,"amount_str":"0.50000000","amount_traded":"0","amount_at_create":"0.50000000","price":79620.92,"price_str":"79620.92","is_liquidation":false},"channel":"live_orders_btcusd","event":"order_deleted","event_id":"000659d4-cbaf-0258-0002-000100000020","pre_event_id":"000659d4-cbaf-0258-0001-000103000020","order_source":"orderbook"}
{"data":{"id":2043024878768133,"id_str":"2043024878768133","order_type":1,"order_subtype":5,"datetime":"1787620345","microtimestamp":"1787620345450000","amount":0.05,"amount_str":"0.05000000","amount_traded":"0","amount_at_create":"0.05000000","price":79636.92,"price_str":"79636.92","is_liquidation":false},"channel":"live_orders_btcusd","event":"order_created","event_id":"000659d4-cbaf-0e10-0000-000101000020","pre_event_id":"000659d4-cbaf-0258-0002-000100000020","order_source":"orderbook"}
{"data":{"id":2043024878800897,"id_str":"2043024878800897","order_type":1,"order_subtype":5,"datetime":"1787620345","microtimestamp":"1787620345466000","amount":0.19,"amount_str":"0.19000000","amount_traded":"0","amount_at_create":"0.19000000","price":79626.93,"price_str":"79626.93","is_liquidation":false},"channel":"live_orders_btcusd","event":"order_created","event_id":"000659d4-cbaf-4c90-0000-000102000020","pre_event_id":"000659d4-cbaf-0e10-0000-000101000020","order_source":"orderbook"}
{"data":{"id":2043024878813185,"id_str":"2043024878813185","order_type":0,"order_subtype":5,"datetime":"1787620345","microtimestamp":"1787620345467000","amount":0.19,"amount_str":"0.19000000","amount_traded":"0","amount_at_create":"0.19000000","price":79626.92,"price_str":"79626.92","is_liquidation":false},"channel":"live_orders_btcusd","event":"order_created","event_id":"000659d4-cbaf-5078-0000-000103000020","pre_event_id":"000659d4-cbaf-4c90-0000-000102000020","order_source":"orderbook"}
{"data":{"id":2043024878850056,"id_str":"2043024878850056","order_type":0,"order_subtype":4,"datetime":"1787620345","microtimestamp":"1787620345471000","amount":0.009,"amount_str":"0.00900000","amount_traded":"0","amount_at_create":"0.00900000","price":79644.33,"price_str":"79644.33","is_liquidation":false},"channel":"live_orders_btcusd","event":"order_created","event_id":"000659d4-cbaf-6018-0000-000100000020","pre_event_id":"000659d4-cbaf-5078-0000-000103000020","order_source":"orderbook"}
{"data":{"id":2043024878850056,"id_str":"2043024878850056","order_type":0,"order_subtype":4,"datetime":"1787620345","microtimestamp":"1787620345471000","amount":0,"amount_str":"0","amount_traded":"0.00900000","amount_at_create":"0.00900000","price":79626.93,"price_str":"79626.93","is_liquidation":false},"channel":"live_orders_btcusd","event":"order_deleted","event_id":"000659d4-cbaf-6018-0001-000101000020","pre_event_id":"000659d4-cbaf-6018-0000-000100000020","order_source":"orderbook"}
{"data":{"id":2043024878452756,"id_str":"2043024878452756","order_type":1,"order_subtype":5,"datetime":"1787620345","microtimestamp":"1787620345471000","amount":0.05379282,"amount_str":"0.05379282","amount_traded":"0.00900000","amount_at_create":"0.06279282","price":79626.93,"price_str":"79626.93","is_liquidation":false},"channel":"live_orders_btcusd","event":"order_changed","event_id":"000659d4-cbaf-6018-0002-000102000020","pre_event_id":"000659d4-cbaf-6018-0001-000101000020","order_source":"orderbook"}
{"data":{"id":2043024838209540,"id_str":"2043024838209540","order_type":1,"order_subtype":0,"datetime":"1787620345","microtimestamp":"1787620345471000","amount":0.00025,"amount_str":"0.00025000","amount_traded":"0","amount_at_create":"0.00025000","price":80068,"price_str":"80068.00","is_liquidation":false},"channel":"live_orders_btcusd","event":"order_deleted","event_id":"000659d4-cbaf-6018-0003-000103000020","pre_event_id":"000659d4-cbaf-6018-0002-000102000020","order_source":"orderbook"}
{"data":{"id":2043024864894979,"id_str":"2043024864894979","order_type":0,"order_subtype":5,"datetime":"1787620345","microtimestamp":"1787620345474000","amount":0.12640783,"amount_str":"0.12640783","amount_traded":"0","amount_at_create":"0.12640783","price":79592.85,"price_str":"79592.85","is_liquidation":false},"channel":"live_orders_btcusd","event":"order_deleted","event_id":"000659d4-cbaf-6bd0-0000-000100000020","pre_event_id":"000659d4-cbaf-6018-0003-000103000020","order_source":"orderbook"}
{"data":{"id":2043024878891017,"id_str":"2043024878891017","order_type":0,"order_subtype":5,"datetime":"1787620345","microtimestamp":"1787620345482000","amount":0.00143636,"amount_str":"0.00143636","amount_traded":"0","amount_at_create":"0.00143636","price":71664.23,"price_str":"71664.23","is_liquidation":false},"channel":"live_orders_btcusd","event":"order_created","event_id":"000659d4-cbaf-8b10-0000-000101000020","pre_event_id":"000659d4-cbaf-6bd0-0000-000100000020","order_source":"orderbook"}
{"data":{"id":2043024878899203,"id_str":"2043024878899203","order_type":1,"order_subtype":5,"datetime":"1787620345","microtimestamp":"1787620345483000","amount":0.1,"amount_str":"0.10000000","amount_traded":"0","amount_at_create":"0.10000000","price":79628.79,"price_str":"79628.79","is_liquidation":false},"channel":"live_orders_btcusd","event":"order_created","event_id":"000659d4-cbaf-8ef8-0000-000102000020","pre_event_id":"000659d4-cbaf-8b10-0000-000101000020","order_source":"orderbook"}
{"data":{"id":2043024878735361,"id_str":"2043024878735361","order_type":1,"order_subtype":5,"datetime":"1787620345","microtimestamp":"1787620345486000","amount":0.5,"amount_str":"0.50000000","amount_traded":"0","amount_at_create":"0.50000000","price":79628.89,"price_str":"79628.89","is_liquidation":false},"channel":"live_orders_btcusd","event":"order_deleted","event_id":"000659d4-cbaf-9ab0-0000-000103000020","pre_event_id":"000659d4-cbaf-8ef8-0000-000102000020","order_source":"orderbook"}
{"data":{"id":2043024878432261,"id_str":"2043024878432261","order_type":0,"order_subtype":0,"datetime":"1787620345","microtimestamp":"1787620345495000","amount":0.00049029,"amount_str":"0.00049029","amount_traded":"0","amount_at_create":"0.00049029","price":78775.17,"price_str":"78775.17","is_liquidation":false},"channel":"live_orders_btcusd","event":"order_deleted","event_id":"000659d4-cbaf-bdd8-0000-000100000020","pre_event_id":"000659d4-cbaf-9ab0-0000-000103000020","order_source":"orderbook"}
{"data":{"id":2043024878960643,"id_str":"2043024878960643","order_type":0,"order_subtype":5,"datetime":"1787620345","microtimestamp":"1787620345497000","amount":0.5,"amount_str":"0.50000000","amount_traded":"0","amount_at_create":"0.50000000","price":79619.82,"price_str":"79619.82","is_liquidation":false},"channel":"live_orders_btcusd","event":"order_created","event_id":"000659d4-cbaf-c5a8-0000-000101000020","pre_event_id":"000659d4-cbaf-bdd8-0000-000100000020","order_source":"orderbook"}
{"data":{"id":2043024878960650,"id_str":"2043024878960650","order_type":0,"order_subtype":5,"datetime":"1787620345","microtimestamp":"1787620345498000","amount":0.25,"amount_str":"0.25000000","amount_traded":"0","amount_at_create":"0.25000000","price":79623.8,"price_str":"79623.80","is_liquidation":false},"channel":"live_orders_btcusd","event":"order_created","event_id":"000659d4-cbaf-c990-0000-000102000020","pre_event_id":"000659d4-cbaf-c5a8-0000-000101000020","order_source":"orderbook"}
{"data":{"id":2043024878968833,"id_str":"2043024878968833","order_type":0,"order_subtype":5,"datetime":"1787620346","microtimestamp":"1787620345500000","amount":0.00251301,"amount_str":"0.00251301","amount_traded":"0","amount_at_create":"0.00251301","price":79585.91,"price_str":"79585.91","is_liquidation":false},"channel":"live_orders_btcusd","event":"order_created","event_id":"000659d4-cbaf-d160-0000-000103000020","pre_event_id":"000659d4-cbaf-c990-0000-000102000020","order_source":"orderbook"}
{"data":{"id":2043024879017986,"id_str":"2043024879017986","order_type":1,"order_subtype":5,"datetime":"1787620346","microtimestamp":"1787620345511000","amount":0.110062,"amount_str":"0.11006200","amount_traded":"0","amount_at_create":"0.11006200","price":79626.93,"price_str":"79626.93","is_liquidation":false},"channel":"live_orders_btcusd","event":"order_created","event_id":"000659d4-cbaf-fc58-0000-000100000020","pre_event_id":"000659d4-cbaf-d160-0000-000103000020","order_source":"orderbook"}
{"data":{"id":2043024878575617,"id_str":"2043024878575617","order_type":0,"order_subtype":5,"datetime":"1787620346","microtimestamp":"1787620345517000","amount":0.18838819,"amount_str":"0.18838819","amount_traded":"0","amount_at_create":"0.18838819","price":79604.21,"price_str":"79604.21","is_liquidation":false},"channel":"live_orders_btcusd","event":"order_deleted","event_id":"000659d4-cbb0-13c8-0000-000101000020","pre_event_id":"000659d4-cbaf-fc58-0000-000100000020","order_source":"orderbook"}
{"data":{"id":2043024878702600,"id_str":"2043024878702600","order_type":0,"order_subtype":5,"datetime":"1787620346","microtimestamp":"1787620345521000","amount":0.00251224,"amount_str":"0.00251224","amount_traded":"0","amount_at_create":"0.00251224","price":79610.27,"price_str":"79610.27","is_liquidation":false},"channel":"live_orders_btcusd","event":"order_deleted","event_id":"000659d4-cbb0-2368-0000-000102000020","pre_event_id":"000659d4-cbb0-13c8-0000-000101000020","order_source":"orderbook"}
{"data":{"id":2043024878813185,"id_str":"2043024878813185","order_type":0,"order_subtype":5,"datetime":"1787620346","microtimestamp":"1787620345524000","amount":0.19,"amount_str":"0.19000000","amount_traded":"0","amount_at_create":"0.19000000","price":79626.92,"price_str":"79626.92","is_liquidation":false},"channel":"live_orders_btcusd","event":"order_deleted","event_id":"000659d4-cbb0-2f20-0000-000103000020","pre_event_id":"000659d4-cbb0-2368-0000-000102000020","order_source":"orderbook"}
{"data":{"id":2043024879079440,"id_str":"2043024879079440","order_type":0,"order_subtype":5,"datetime":"1787620346","microtimestamp":"1787620345527000","amount":0.18839112,"amount_str":"0.18839112","amount_traded":"0","amount_at_create":"0.18839112","price":79606.12,"price_str":"79606.12","is_liquidation":false},"channel":"live_orders_btcusd","event":"order_created","event_id":"000659d4-cbb0-3ad8-0000-000100000020","pre_event_id":"000659d4-cbb0-2f20-0000-000103000020","order_source":"orderbook"}
{"data":{"id":2043024879099917,"id_str":"2043024879099917","order_type":1,"order_subtype":5,"datetime":"1787620346","microtimestamp":"1787620345532000","amount":0.5,"amount_str":"0.50000000","amount_traded":"0","amount_at_create":"0.50000000","price":79627.79,"price_str":"79627.79","is_liquidation":false},"channel":"live_orders_btcusd","event":"order_created","event_id":"000659d4-cbb0-4e60-0000-000101000020","pre_event_id":"000659d4-cbb0-3ad8-0000-000100000020","order_source":"orderbook"}
{"data":{"id":2043024879099917,"id_str":"2043024879099917","order_type":1,"order_subtype":5,"datetime":"1787620346","microtimestamp":"1787620345535000","amount":0.5,"amount_str":"0.50000000","amount_traded":"0","amount_at_create":"0.50000000","price":79627.79,"price_str":"79627.79","is_liquidation":false},"channel":"live_orders_btcusd","event":"order_deleted","event_id":"000659d4-cbb0-5a18-0000-000102000020","pre_event_id":"000659d4-cbb0-4e60-0000-000101000020","order_source":"orderbook"}
{"data":{"id":2043024879120387,"id_str":"2043024879120387","order_type":1,"order_subtype":0,"datetime":"1787620346","microtimestamp":"1787620345536000","amount":0.00025,"amount_str":"0.00025000","amount_traded":"0","amount_at_create":"0.00025000","price":80003,"price_str":"80003.00","is_liquidation":false},"channel":"live_orders_btcusd","event":"order_created","event_id":"000659d4-cbb0-5e00-0000-000103000020","pre_event_id":"000659d4-cbb0-5a18-0000-000102000020","order_source":"orderbook"}
{"data":{"id":2043024879222788,"id_str":"2043024879222788","order_type":0,"order_subtype":5,"datetime":"1787620346","microtimestamp":"1787620345562000","amount":0.00143636,"amount_str":"0.00143636","amount_traded":"0","amount_at_create":"0.00143636","price":71664.23,"price_str":"71664.23","is_liquidation":false},"channel":"live_orders_btcusd","event":"order_created","event_id":"000659d4-cbb0-c390-0000-000100000020","pre_event_id":"000659d4-cbb0-5e00-0000-000103000020","order_source":"orderbook"}
